**********************************************************************
*                     Grid Engine Batch System                       *
*              IN2P3 Computing Centre, Villeurbanne FR               *
**********************************************************************
* User:                           boutigny                           *
* Group:                          lsst                               *
* Jobname:                        dask-worker                        *
* JobID:                          15661247                           *
* Queue:                          mc_highmem                         *
* Worker:                         ccwsge0404.in2p3.fr                *
* Operating system:               Linux 3.10.0-1160.25.1.el7.x86_64  *
* Project:                        P_lsst                             *
**********************************************************************
* Submitted on:                   Tue Jul 20 19:45:37 CEST 2021      *
* Started on:                     Tue Jul 20 19:45:44 CEST 2021      *
**********************************************************************
coucou
distributed.nanny - INFO -         Start Nanny at: 'tcp://134.158.168.70:37793'
distributed.worker - INFO -       Start worker at: tcp://134.158.168.70:37680
distributed.worker - INFO -          Listening to: tcp://134.158.168.70:37680
distributed.worker - INFO -          dashboard at:       134.158.168.70:42165
distributed.worker - INFO - Waiting to connect to:  tcp://134.158.48.24:42415
distributed.worker - INFO - -------------------------------------------------
distributed.worker - INFO -               Threads:                          1
distributed.worker - INFO -                Memory:                   4.66 GiB
distributed.worker - INFO -       Local Directory: /pbs/throng/lsst/users/boutigny/LSST_notebooks/Dask/dask-worker-space/worker-a3vhh5hs
distributed.worker - INFO - -------------------------------------------------
distributed.worker - INFO -         Registered to:  tcp://134.158.48.24:42415
distributed.worker - INFO - -------------------------------------------------
distributed.core - INFO - Starting established connection
distributed.utils_perf - INFO - full garbage collection released 0.95 GiB from 48 reference cycles (threshold: 9.54 MiB)
distributed.core - INFO - Event loop was unresponsive in Worker for 3.86s.  This is often caused by long-running GIL-holding functions or moving large chunks of data. This can cause timeouts and instability.
distributed.worker - ERROR - failed during get data with tcp://134.158.168.70:37680 -> tcp://134.158.170.32:41455
Traceback (most recent call last):
  File "/sps/lsst/users/boutigny/conda_envs/desc_2/lib/python3.8/site-packages/tornado/iostream.py", line 867, in _read_to_buffer
    bytes_read = self.read_from_fd(buf)
  File "/sps/lsst/users/boutigny/conda_envs/desc_2/lib/python3.8/site-packages/tornado/iostream.py", line 1140, in read_from_fd
    return self.socket.recv_into(buf, len(buf))
ConnectionResetError: [Errno 104] Connection reset by peer

The above exception was the direct cause of the following exception:

Traceback (most recent call last):
  File "/sps/lsst/users/boutigny/conda_envs/desc_2/lib/python3.8/site-packages/distributed/worker.py", line 1366, in get_data
    response = await comm.read(deserializers=serializers)
  File "/sps/lsst/users/boutigny/conda_envs/desc_2/lib/python3.8/site-packages/distributed/comm/tcp.py", line 206, in read
    convert_stream_closed_error(self, e)
  File "/sps/lsst/users/boutigny/conda_envs/desc_2/lib/python3.8/site-packages/distributed/comm/tcp.py", line 124, in convert_stream_closed_error
    raise CommClosedError(
distributed.comm.core.CommClosedError: in <closed TCP>: ConnectionResetError: [Errno 104] Connection reset by peer
distributed.core - INFO - Lost connection to 'tcp://134.158.170.32:58596': in <closed TCP>: ConnectionResetError: [Errno 104] Connection reset by peer
distributed.worker - WARNING - Worker is at 81% memory usage. Pausing worker.  Process memory: 3.80 GiB -- Worker memory limit: 4.66 GiB
distributed.worker - WARNING - Worker is at 57% memory usage. Resuming worker. Process memory: 2.69 GiB -- Worker memory limit: 4.66 GiB
distributed.core - INFO - Event loop was unresponsive in Worker for 8.84s.  This is often caused by long-running GIL-holding functions or moving large chunks of data. This can cause timeouts and instability.
distributed.worker - ERROR - Worker stream died during communication: tcp://134.158.168.180:37111
Traceback (most recent call last):
  File "/sps/lsst/users/boutigny/conda_envs/desc_2/lib/python3.8/site-packages/distributed/comm/tcp.py", line 200, in read
    n = await stream.read_into(frames)
tornado.iostream.StreamClosedError: Stream is closed

The above exception was the direct cause of the following exception:

Traceback (most recent call last):
  File "/sps/lsst/users/boutigny/conda_envs/desc_2/lib/python3.8/site-packages/distributed/worker.py", line 2169, in gather_dep
    response = await get_data_from_worker(
  File "/sps/lsst/users/boutigny/conda_envs/desc_2/lib/python3.8/site-packages/distributed/worker.py", line 3442, in get_data_from_worker
    return await retry_operation(_get_data, operation="get_data_from_worker")
  File "/sps/lsst/users/boutigny/conda_envs/desc_2/lib/python3.8/site-packages/distributed/utils_comm.py", line 385, in retry_operation
    return await retry(
  File "/sps/lsst/users/boutigny/conda_envs/desc_2/lib/python3.8/site-packages/distributed/utils_comm.py", line 370, in retry
    return await coro()
  File "/sps/lsst/users/boutigny/conda_envs/desc_2/lib/python3.8/site-packages/distributed/worker.py", line 3422, in _get_data
    response = await send_recv(
  File "/sps/lsst/users/boutigny/conda_envs/desc_2/lib/python3.8/site-packages/distributed/core.py", line 645, in send_recv
    response = await comm.read(deserializers=deserializers)
  File "/sps/lsst/users/boutigny/conda_envs/desc_2/lib/python3.8/site-packages/distributed/comm/tcp.py", line 206, in read
    convert_stream_closed_error(self, e)
  File "/sps/lsst/users/boutigny/conda_envs/desc_2/lib/python3.8/site-packages/distributed/comm/tcp.py", line 128, in convert_stream_closed_error
    raise CommClosedError("in %s: %s" % (obj, exc)) from exc
distributed.comm.core.CommClosedError: in <closed TCP>: Stream is closed
distributed.worker - ERROR - Worker stream died during communication: tcp://134.158.168.65:35110
Traceback (most recent call last):
  File "/sps/lsst/users/boutigny/conda_envs/desc_2/lib/python3.8/site-packages/tornado/iostream.py", line 867, in _read_to_buffer
    bytes_read = self.read_from_fd(buf)
  File "/sps/lsst/users/boutigny/conda_envs/desc_2/lib/python3.8/site-packages/tornado/iostream.py", line 1140, in read_from_fd
    return self.socket.recv_into(buf, len(buf))
ConnectionResetError: [Errno 104] Connection reset by peer

The above exception was the direct cause of the following exception:

Traceback (most recent call last):
  File "/sps/lsst/users/boutigny/conda_envs/desc_2/lib/python3.8/site-packages/distributed/comm/core.py", line 318, in connect
    handshake = await asyncio.wait_for(comm.read(), time_left())
  File "/sps/lsst/users/boutigny/conda_envs/desc_2/lib/python3.8/asyncio/tasks.py", line 494, in wait_for
    return fut.result()
  File "/sps/lsst/users/boutigny/conda_envs/desc_2/lib/python3.8/site-packages/distributed/comm/tcp.py", line 206, in read
    convert_stream_closed_error(self, e)
  File "/sps/lsst/users/boutigny/conda_envs/desc_2/lib/python3.8/site-packages/distributed/comm/tcp.py", line 124, in convert_stream_closed_error
    raise CommClosedError(
distributed.comm.core.CommClosedError: in <closed TCP>: ConnectionResetError: [Errno 104] Connection reset by peer

The above exception was the direct cause of the following exception:

Traceback (most recent call last):
  File "/sps/lsst/users/boutigny/conda_envs/desc_2/lib/python3.8/site-packages/distributed/worker.py", line 2169, in gather_dep
    response = await get_data_from_worker(
  File "/sps/lsst/users/boutigny/conda_envs/desc_2/lib/python3.8/site-packages/distributed/worker.py", line 3442, in get_data_from_worker
    return await retry_operation(_get_data, operation="get_data_from_worker")
  File "/sps/lsst/users/boutigny/conda_envs/desc_2/lib/python3.8/site-packages/distributed/utils_comm.py", line 385, in retry_operation
    return await retry(
  File "/sps/lsst/users/boutigny/conda_envs/desc_2/lib/python3.8/site-packages/distributed/utils_comm.py", line 370, in retry
    return await coro()
  File "/sps/lsst/users/boutigny/conda_envs/desc_2/lib/python3.8/site-packages/distributed/worker.py", line 3419, in _get_data
    comm = await rpc.connect(worker)
  File "/sps/lsst/users/boutigny/conda_envs/desc_2/lib/python3.8/site-packages/distributed/core.py", line 1010, in connect
    comm = await connect(
  File "/sps/lsst/users/boutigny/conda_envs/desc_2/lib/python3.8/site-packages/distributed/comm/core.py", line 323, in connect
    raise IOError(
OSError: Timed out during handshake while connecting to tcp://134.158.168.65:35110 after 10 s
distributed.core - INFO - Event loop was unresponsive in Worker for 8.53s.  This is often caused by long-running GIL-holding functions or moving large chunks of data. This can cause timeouts and instability.
distributed.nanny - WARNING - Worker exceeded 95% memory budget. Restarting
distributed.nanny - WARNING - Worker exceeded 95% memory budget. Restarting
distributed.nanny - WARNING - Worker exceeded 95% memory budget. Restarting
distributed.nanny - WARNING - Worker exceeded 95% memory budget. Restarting
distributed.nanny - WARNING - Worker exceeded 95% memory budget. Restarting
distributed.nanny - WARNING - Worker exceeded 95% memory budget. Restarting
distributed.nanny - INFO - Worker process 50391 was killed by signal 15
distributed.nanny - WARNING - Restarting worker
/sps/lsst/users/boutigny/conda_envs/desc_2/lib/python3.8/contextlib.py:120: UserWarning: Creating scratch directories is taking a surprisingly long time. This is often due to running workers on a network file system. Consider specifying a local-directory to point workers to write scratch data to a local disk.
  next(self.gen)
distributed.worker - INFO -       Start worker at: tcp://134.158.168.70:45862
distributed.worker - INFO -          Listening to: tcp://134.158.168.70:45862
distributed.worker - INFO -          dashboard at:       134.158.168.70:34972
distributed.worker - INFO - Waiting to connect to:  tcp://134.158.48.24:42415
distributed.worker - INFO - -------------------------------------------------
distributed.worker - INFO -               Threads:                          1
distributed.worker - INFO -                Memory:                   4.66 GiB
distributed.worker - INFO -       Local Directory: /pbs/throng/lsst/users/boutigny/LSST_notebooks/Dask/dask-worker-space/worker-eldl440x
distributed.worker - INFO - -------------------------------------------------
distributed.worker - INFO -         Registered to:  tcp://134.158.48.24:42415
distributed.worker - INFO - -------------------------------------------------
distributed.core - INFO - Starting established connection
distributed.worker - ERROR - Worker stream died during communication: tcp://134.158.170.29:39482
Traceback (most recent call last):
  File "/sps/lsst/users/boutigny/conda_envs/desc_2/lib/python3.8/site-packages/tornado/iostream.py", line 867, in _read_to_buffer
    bytes_read = self.read_from_fd(buf)
  File "/sps/lsst/users/boutigny/conda_envs/desc_2/lib/python3.8/site-packages/tornado/iostream.py", line 1140, in read_from_fd
    return self.socket.recv_into(buf, len(buf))
ConnectionResetError: [Errno 104] Connection reset by peer

The above exception was the direct cause of the following exception:

Traceback (most recent call last):
  File "/sps/lsst/users/boutigny/conda_envs/desc_2/lib/python3.8/site-packages/distributed/comm/core.py", line 318, in connect
    handshake = await asyncio.wait_for(comm.read(), time_left())
  File "/sps/lsst/users/boutigny/conda_envs/desc_2/lib/python3.8/asyncio/tasks.py", line 494, in wait_for
    return fut.result()
  File "/sps/lsst/users/boutigny/conda_envs/desc_2/lib/python3.8/site-packages/distributed/comm/tcp.py", line 206, in read
    convert_stream_closed_error(self, e)
  File "/sps/lsst/users/boutigny/conda_envs/desc_2/lib/python3.8/site-packages/distributed/comm/tcp.py", line 124, in convert_stream_closed_error
    raise CommClosedError(
distributed.comm.core.CommClosedError: in <closed TCP>: ConnectionResetError: [Errno 104] Connection reset by peer

The above exception was the direct cause of the following exception:

Traceback (most recent call last):
  File "/sps/lsst/users/boutigny/conda_envs/desc_2/lib/python3.8/site-packages/distributed/worker.py", line 2169, in gather_dep
    response = await get_data_from_worker(
  File "/sps/lsst/users/boutigny/conda_envs/desc_2/lib/python3.8/site-packages/distributed/worker.py", line 3442, in get_data_from_worker
    return await retry_operation(_get_data, operation="get_data_from_worker")
  File "/sps/lsst/users/boutigny/conda_envs/desc_2/lib/python3.8/site-packages/distributed/utils_comm.py", line 385, in retry_operation
    return await retry(
  File "/sps/lsst/users/boutigny/conda_envs/desc_2/lib/python3.8/site-packages/distributed/utils_comm.py", line 370, in retry
    return await coro()
  File "/sps/lsst/users/boutigny/conda_envs/desc_2/lib/python3.8/site-packages/distributed/worker.py", line 3419, in _get_data
    comm = await rpc.connect(worker)
  File "/sps/lsst/users/boutigny/conda_envs/desc_2/lib/python3.8/site-packages/distributed/core.py", line 1010, in connect
    comm = await connect(
  File "/sps/lsst/users/boutigny/conda_envs/desc_2/lib/python3.8/site-packages/distributed/comm/core.py", line 323, in connect
    raise IOError(
OSError: Timed out during handshake while connecting to tcp://134.158.170.29:39482 after 10 s
distributed.core - INFO - Event loop was unresponsive in Worker for 3.16s.  This is often caused by long-running GIL-holding functions or moving large chunks of data. This can cause timeouts and instability.
distributed.worker - ERROR - failed during get data with tcp://134.158.168.70:45862 -> tcp://134.158.170.37:34353
Traceback (most recent call last):
  File "/sps/lsst/users/boutigny/conda_envs/desc_2/lib/python3.8/site-packages/distributed/comm/tcp.py", line 196, in read
    frames_nbytes = await stream.read_bytes(fmt_size)
tornado.iostream.StreamClosedError: Stream is closed

The above exception was the direct cause of the following exception:

Traceback (most recent call last):
  File "/sps/lsst/users/boutigny/conda_envs/desc_2/lib/python3.8/site-packages/distributed/worker.py", line 1366, in get_data
    response = await comm.read(deserializers=serializers)
  File "/sps/lsst/users/boutigny/conda_envs/desc_2/lib/python3.8/site-packages/distributed/comm/tcp.py", line 206, in read
    convert_stream_closed_error(self, e)
  File "/sps/lsst/users/boutigny/conda_envs/desc_2/lib/python3.8/site-packages/distributed/comm/tcp.py", line 128, in convert_stream_closed_error
    raise CommClosedError("in %s: %s" % (obj, exc)) from exc
distributed.comm.core.CommClosedError: in <closed TCP>: Stream is closed
distributed.core - INFO - Lost connection to 'tcp://134.158.170.37:43190': in <closed TCP>: Stream is closed
distributed.worker - ERROR - failed during get data with tcp://134.158.168.70:45862 -> tcp://134.158.170.21:44434
Traceback (most recent call last):
  File "/sps/lsst/users/boutigny/conda_envs/desc_2/lib/python3.8/site-packages/tornado/iostream.py", line 867, in _read_to_buffer
    bytes_read = self.read_from_fd(buf)
  File "/sps/lsst/users/boutigny/conda_envs/desc_2/lib/python3.8/site-packages/tornado/iostream.py", line 1140, in read_from_fd
    return self.socket.recv_into(buf, len(buf))
ConnectionResetError: [Errno 104] Connection reset by peer

The above exception was the direct cause of the following exception:

Traceback (most recent call last):
  File "/sps/lsst/users/boutigny/conda_envs/desc_2/lib/python3.8/site-packages/distributed/worker.py", line 1366, in get_data
    response = await comm.read(deserializers=serializers)
  File "/sps/lsst/users/boutigny/conda_envs/desc_2/lib/python3.8/site-packages/distributed/comm/tcp.py", line 206, in read
    convert_stream_closed_error(self, e)
  File "/sps/lsst/users/boutigny/conda_envs/desc_2/lib/python3.8/site-packages/distributed/comm/tcp.py", line 124, in convert_stream_closed_error
    raise CommClosedError(
distributed.comm.core.CommClosedError: in <closed TCP>: ConnectionResetError: [Errno 104] Connection reset by peer
distributed.core - INFO - Lost connection to 'tcp://134.158.170.21:38446': in <closed TCP>: ConnectionResetError: [Errno 104] Connection reset by peer
distributed.worker - ERROR - failed during get data with tcp://134.158.168.70:45862 -> tcp://134.158.170.52:44053
Traceback (most recent call last):
  File "/sps/lsst/users/boutigny/conda_envs/desc_2/lib/python3.8/site-packages/tornado/iostream.py", line 867, in _read_to_buffer
    bytes_read = self.read_from_fd(buf)
  File "/sps/lsst/users/boutigny/conda_envs/desc_2/lib/python3.8/site-packages/tornado/iostream.py", line 1140, in read_from_fd
    return self.socket.recv_into(buf, len(buf))
ConnectionResetError: [Errno 104] Connection reset by peer

The above exception was the direct cause of the following exception:

Traceback (most recent call last):
  File "/sps/lsst/users/boutigny/conda_envs/desc_2/lib/python3.8/site-packages/distributed/worker.py", line 1366, in get_data
    response = await comm.read(deserializers=serializers)
  File "/sps/lsst/users/boutigny/conda_envs/desc_2/lib/python3.8/site-packages/distributed/comm/tcp.py", line 206, in read
    convert_stream_closed_error(self, e)
  File "/sps/lsst/users/boutigny/conda_envs/desc_2/lib/python3.8/site-packages/distributed/comm/tcp.py", line 124, in convert_stream_closed_error
    raise CommClosedError(
distributed.comm.core.CommClosedError: in <closed TCP>: ConnectionResetError: [Errno 104] Connection reset by peer
distributed.core - INFO - Lost connection to 'tcp://134.158.170.52:57042': in <closed TCP>: ConnectionResetError: [Errno 104] Connection reset by peer
distributed.worker - ERROR - failed during get data with tcp://134.158.168.70:45862 -> tcp://134.158.168.225:44012
Traceback (most recent call last):
  File "/sps/lsst/users/boutigny/conda_envs/desc_2/lib/python3.8/site-packages/distributed/comm/tcp.py", line 196, in read
    frames_nbytes = await stream.read_bytes(fmt_size)
tornado.iostream.StreamClosedError: Stream is closed

The above exception was the direct cause of the following exception:

Traceback (most recent call last):
  File "/sps/lsst/users/boutigny/conda_envs/desc_2/lib/python3.8/site-packages/distributed/worker.py", line 1366, in get_data
    response = await comm.read(deserializers=serializers)
  File "/sps/lsst/users/boutigny/conda_envs/desc_2/lib/python3.8/site-packages/distributed/comm/tcp.py", line 206, in read
    convert_stream_closed_error(self, e)
  File "/sps/lsst/users/boutigny/conda_envs/desc_2/lib/python3.8/site-packages/distributed/comm/tcp.py", line 128, in convert_stream_closed_error
    raise CommClosedError("in %s: %s" % (obj, exc)) from exc
distributed.comm.core.CommClosedError: in <closed TCP>: Stream is closed
distributed.core - INFO - Lost connection to 'tcp://134.158.168.225:53958': in <closed TCP>: Stream is closed
distributed.nanny - WARNING - Worker exceeded 95% memory budget. Restarting
distributed.nanny - WARNING - Worker exceeded 95% memory budget. Restarting
distributed.nanny - WARNING - Worker exceeded 95% memory budget. Restarting
distributed.nanny - WARNING - Worker exceeded 95% memory budget. Restarting
distributed.nanny - WARNING - Worker exceeded 95% memory budget. Restarting
distributed.nanny - WARNING - Worker exceeded 95% memory budget. Restarting
distributed.nanny - WARNING - Worker exceeded 95% memory budget. Restarting
distributed.nanny - WARNING - Worker exceeded 95% memory budget. Restarting
distributed.nanny - WARNING - Worker exceeded 95% memory budget. Restarting
distributed.nanny - INFO - Worker process 62976 was killed by signal 15
distributed.nanny - WARNING - Restarting worker
distributed.worker - INFO -       Start worker at: tcp://134.158.168.70:37143
distributed.worker - INFO -          Listening to: tcp://134.158.168.70:37143
distributed.worker - INFO -          dashboard at:       134.158.168.70:35949
distributed.worker - INFO - Waiting to connect to:  tcp://134.158.48.24:42415
distributed.worker - INFO - -------------------------------------------------
distributed.worker - INFO -               Threads:                          1
distributed.worker - INFO -                Memory:                   4.66 GiB
distributed.worker - INFO -       Local Directory: /pbs/throng/lsst/users/boutigny/LSST_notebooks/Dask/dask-worker-space/worker-q5ear3b6
distributed.worker - INFO - -------------------------------------------------
distributed.worker - INFO -         Registered to:  tcp://134.158.48.24:42415
distributed.worker - INFO - -------------------------------------------------
distributed.core - INFO - Starting established connection
distributed.worker - ERROR - Worker stream died during communication: tcp://134.158.168.63:34054
Traceback (most recent call last):
  File "/sps/lsst/users/boutigny/conda_envs/desc_2/lib/python3.8/site-packages/tornado/iostream.py", line 867, in _read_to_buffer
    bytes_read = self.read_from_fd(buf)
  File "/sps/lsst/users/boutigny/conda_envs/desc_2/lib/python3.8/site-packages/tornado/iostream.py", line 1140, in read_from_fd
    return self.socket.recv_into(buf, len(buf))
ConnectionResetError: [Errno 104] Connection reset by peer

The above exception was the direct cause of the following exception:

Traceback (most recent call last):
  File "/sps/lsst/users/boutigny/conda_envs/desc_2/lib/python3.8/site-packages/distributed/comm/core.py", line 318, in connect
    handshake = await asyncio.wait_for(comm.read(), time_left())
  File "/sps/lsst/users/boutigny/conda_envs/desc_2/lib/python3.8/asyncio/tasks.py", line 494, in wait_for
    return fut.result()
  File "/sps/lsst/users/boutigny/conda_envs/desc_2/lib/python3.8/site-packages/distributed/comm/tcp.py", line 206, in read
    convert_stream_closed_error(self, e)
  File "/sps/lsst/users/boutigny/conda_envs/desc_2/lib/python3.8/site-packages/distributed/comm/tcp.py", line 124, in convert_stream_closed_error
    raise CommClosedError(
distributed.comm.core.CommClosedError: in <closed TCP>: ConnectionResetError: [Errno 104] Connection reset by peer

The above exception was the direct cause of the following exception:

Traceback (most recent call last):
  File "/sps/lsst/users/boutigny/conda_envs/desc_2/lib/python3.8/site-packages/distributed/worker.py", line 2169, in gather_dep
    response = await get_data_from_worker(
  File "/sps/lsst/users/boutigny/conda_envs/desc_2/lib/python3.8/site-packages/distributed/worker.py", line 3442, in get_data_from_worker
    return await retry_operation(_get_data, operation="get_data_from_worker")
  File "/sps/lsst/users/boutigny/conda_envs/desc_2/lib/python3.8/site-packages/distributed/utils_comm.py", line 385, in retry_operation
    return await retry(
  File "/sps/lsst/users/boutigny/conda_envs/desc_2/lib/python3.8/site-packages/distributed/utils_comm.py", line 370, in retry
    return await coro()
  File "/sps/lsst/users/boutigny/conda_envs/desc_2/lib/python3.8/site-packages/distributed/worker.py", line 3419, in _get_data
    comm = await rpc.connect(worker)
  File "/sps/lsst/users/boutigny/conda_envs/desc_2/lib/python3.8/site-packages/distributed/core.py", line 1010, in connect
    comm = await connect(
  File "/sps/lsst/users/boutigny/conda_envs/desc_2/lib/python3.8/site-packages/distributed/comm/core.py", line 323, in connect
    raise IOError(
OSError: Timed out during handshake while connecting to tcp://134.158.168.63:34054 after 10 s
distributed.worker - ERROR - Worker stream died during communication: tcp://134.158.170.28:45868
Traceback (most recent call last):
  File "/sps/lsst/users/boutigny/conda_envs/desc_2/lib/python3.8/site-packages/distributed/comm/tcp.py", line 200, in read
    n = await stream.read_into(frames)
tornado.iostream.StreamClosedError: Stream is closed

The above exception was the direct cause of the following exception:

Traceback (most recent call last):
  File "/sps/lsst/users/boutigny/conda_envs/desc_2/lib/python3.8/site-packages/distributed/worker.py", line 2169, in gather_dep
    response = await get_data_from_worker(
  File "/sps/lsst/users/boutigny/conda_envs/desc_2/lib/python3.8/site-packages/distributed/worker.py", line 3442, in get_data_from_worker
    return await retry_operation(_get_data, operation="get_data_from_worker")
  File "/sps/lsst/users/boutigny/conda_envs/desc_2/lib/python3.8/site-packages/distributed/utils_comm.py", line 385, in retry_operation
    return await retry(
  File "/sps/lsst/users/boutigny/conda_envs/desc_2/lib/python3.8/site-packages/distributed/utils_comm.py", line 370, in retry
    return await coro()
  File "/sps/lsst/users/boutigny/conda_envs/desc_2/lib/python3.8/site-packages/distributed/worker.py", line 3422, in _get_data
    response = await send_recv(
  File "/sps/lsst/users/boutigny/conda_envs/desc_2/lib/python3.8/site-packages/distributed/core.py", line 645, in send_recv
    response = await comm.read(deserializers=deserializers)
  File "/sps/lsst/users/boutigny/conda_envs/desc_2/lib/python3.8/site-packages/distributed/comm/tcp.py", line 206, in read
    convert_stream_closed_error(self, e)
  File "/sps/lsst/users/boutigny/conda_envs/desc_2/lib/python3.8/site-packages/distributed/comm/tcp.py", line 128, in convert_stream_closed_error
    raise CommClosedError("in %s: %s" % (obj, exc)) from exc
distributed.comm.core.CommClosedError: in <closed TCP>: Stream is closed
distributed.worker - ERROR - Worker stream died during communication: tcp://134.158.170.49:39237
Traceback (most recent call last):
  File "/sps/lsst/users/boutigny/conda_envs/desc_2/lib/python3.8/site-packages/distributed/comm/tcp.py", line 200, in read
    n = await stream.read_into(frames)
tornado.iostream.StreamClosedError: Stream is closed

The above exception was the direct cause of the following exception:

Traceback (most recent call last):
  File "/sps/lsst/users/boutigny/conda_envs/desc_2/lib/python3.8/site-packages/distributed/worker.py", line 2169, in gather_dep
    response = await get_data_from_worker(
  File "/sps/lsst/users/boutigny/conda_envs/desc_2/lib/python3.8/site-packages/distributed/worker.py", line 3442, in get_data_from_worker
    return await retry_operation(_get_data, operation="get_data_from_worker")
  File "/sps/lsst/users/boutigny/conda_envs/desc_2/lib/python3.8/site-packages/distributed/utils_comm.py", line 385, in retry_operation
    return await retry(
  File "/sps/lsst/users/boutigny/conda_envs/desc_2/lib/python3.8/site-packages/distributed/utils_comm.py", line 370, in retry
    return await coro()
  File "/sps/lsst/users/boutigny/conda_envs/desc_2/lib/python3.8/site-packages/distributed/worker.py", line 3422, in _get_data
    response = await send_recv(
  File "/sps/lsst/users/boutigny/conda_envs/desc_2/lib/python3.8/site-packages/distributed/core.py", line 645, in send_recv
    response = await comm.read(deserializers=deserializers)
  File "/sps/lsst/users/boutigny/conda_envs/desc_2/lib/python3.8/site-packages/distributed/comm/tcp.py", line 206, in read
    convert_stream_closed_error(self, e)
  File "/sps/lsst/users/boutigny/conda_envs/desc_2/lib/python3.8/site-packages/distributed/comm/tcp.py", line 128, in convert_stream_closed_error
    raise CommClosedError("in %s: %s" % (obj, exc)) from exc
distributed.comm.core.CommClosedError: in <closed TCP>: Stream is closed
distributed.core - INFO - Event loop was unresponsive in Worker for 11.71s.  This is often caused by long-running GIL-holding functions or moving large chunks of data. This can cause timeouts and instability.
distributed.core - INFO - Event loop was unresponsive in Worker for 7.09s.  This is often caused by long-running GIL-holding functions or moving large chunks of data. This can cause timeouts and instability.
distributed.comm.tcp - INFO - Connection closed before handshake completed
distributed.worker - ERROR - failed during get data with tcp://134.158.168.70:37143 -> tcp://134.158.170.41:42307
Traceback (most recent call last):
  File "/sps/lsst/users/boutigny/conda_envs/desc_2/lib/python3.8/site-packages/tornado/iostream.py", line 867, in _read_to_buffer
    bytes_read = self.read_from_fd(buf)
  File "/sps/lsst/users/boutigny/conda_envs/desc_2/lib/python3.8/site-packages/tornado/iostream.py", line 1140, in read_from_fd
    return self.socket.recv_into(buf, len(buf))
ConnectionResetError: [Errno 104] Connection reset by peer

The above exception was the direct cause of the following exception:

Traceback (most recent call last):
  File "/sps/lsst/users/boutigny/conda_envs/desc_2/lib/python3.8/site-packages/distributed/worker.py", line 1366, in get_data
    response = await comm.read(deserializers=serializers)
  File "/sps/lsst/users/boutigny/conda_envs/desc_2/lib/python3.8/site-packages/distributed/comm/tcp.py", line 206, in read
    convert_stream_closed_error(self, e)
  File "/sps/lsst/users/boutigny/conda_envs/desc_2/lib/python3.8/site-packages/distributed/comm/tcp.py", line 124, in convert_stream_closed_error
    raise CommClosedError(
distributed.comm.core.CommClosedError: in <closed TCP>: ConnectionResetError: [Errno 104] Connection reset by peer
distributed.core - INFO - Lost connection to 'tcp://134.158.170.41:35382': in <closed TCP>: ConnectionResetError: [Errno 104] Connection reset by peer
distributed.core - INFO - Event loop was unresponsive in Worker for 16.25s.  This is often caused by long-running GIL-holding functions or moving large chunks of data. This can cause timeouts and instability.
distributed.utils_perf - INFO - full garbage collection released 21.07 MiB from 76 reference cycles (threshold: 9.54 MiB)
distributed.worker - ERROR - failed during get data with tcp://134.158.168.70:37143 -> tcp://134.158.170.60:36565
Traceback (most recent call last):
  File "/sps/lsst/users/boutigny/conda_envs/desc_2/lib/python3.8/site-packages/distributed/comm/tcp.py", line 196, in read
    frames_nbytes = await stream.read_bytes(fmt_size)
tornado.iostream.StreamClosedError: Stream is closed

The above exception was the direct cause of the following exception:

Traceback (most recent call last):
  File "/sps/lsst/users/boutigny/conda_envs/desc_2/lib/python3.8/site-packages/distributed/worker.py", line 1366, in get_data
    response = await comm.read(deserializers=serializers)
  File "/sps/lsst/users/boutigny/conda_envs/desc_2/lib/python3.8/site-packages/distributed/comm/tcp.py", line 206, in read
    convert_stream_closed_error(self, e)
  File "/sps/lsst/users/boutigny/conda_envs/desc_2/lib/python3.8/site-packages/distributed/comm/tcp.py", line 128, in convert_stream_closed_error
    raise CommClosedError("in %s: %s" % (obj, exc)) from exc
distributed.comm.core.CommClosedError: in <closed TCP>: Stream is closed
distributed.core - INFO - Event loop was unresponsive in Worker for 9.26s.  This is often caused by long-running GIL-holding functions or moving large chunks of data. This can cause timeouts and instability.
distributed.core - INFO - Lost connection to 'tcp://134.158.170.60:38992': in <closed TCP>: Stream is closed
distributed.worker - ERROR - Worker stream died during communication: tcp://134.158.170.22:36589
Traceback (most recent call last):
  File "/sps/lsst/users/boutigny/conda_envs/desc_2/lib/python3.8/site-packages/distributed/comm/tcp.py", line 200, in read
    n = await stream.read_into(frames)
tornado.iostream.StreamClosedError: Stream is closed

The above exception was the direct cause of the following exception:

Traceback (most recent call last):
  File "/sps/lsst/users/boutigny/conda_envs/desc_2/lib/python3.8/site-packages/distributed/worker.py", line 2169, in gather_dep
    response = await get_data_from_worker(
  File "/sps/lsst/users/boutigny/conda_envs/desc_2/lib/python3.8/site-packages/distributed/worker.py", line 3442, in get_data_from_worker
    return await retry_operation(_get_data, operation="get_data_from_worker")
  File "/sps/lsst/users/boutigny/conda_envs/desc_2/lib/python3.8/site-packages/distributed/utils_comm.py", line 385, in retry_operation
    return await retry(
  File "/sps/lsst/users/boutigny/conda_envs/desc_2/lib/python3.8/site-packages/distributed/utils_comm.py", line 370, in retry
    return await coro()
  File "/sps/lsst/users/boutigny/conda_envs/desc_2/lib/python3.8/site-packages/distributed/worker.py", line 3422, in _get_data
    response = await send_recv(
  File "/sps/lsst/users/boutigny/conda_envs/desc_2/lib/python3.8/site-packages/distributed/core.py", line 645, in send_recv
    response = await comm.read(deserializers=deserializers)
  File "/sps/lsst/users/boutigny/conda_envs/desc_2/lib/python3.8/site-packages/distributed/comm/tcp.py", line 206, in read
    convert_stream_closed_error(self, e)
  File "/sps/lsst/users/boutigny/conda_envs/desc_2/lib/python3.8/site-packages/distributed/comm/tcp.py", line 128, in convert_stream_closed_error
    raise CommClosedError("in %s: %s" % (obj, exc)) from exc
distributed.comm.core.CommClosedError: in <closed TCP>: Stream is closed
distributed.worker - INFO - Can't find dependencies for key ('fix-overlap-and_-a2c92d0a7b4404ef4989bfc49cea49a2', 151)
distributed.utils_perf - INFO - full garbage collection released 21.11 MiB from 24 reference cycles (threshold: 9.54 MiB)
distributed.worker - WARNING - Memory use is high but worker has no data to store to disk.  Perhaps some other process is leaking memory?  Process memory: 3.38 GiB -- Worker memory limit: 4.66 GiB
distributed.comm.tcp - INFO - Connection closed before handshake completed
distributed.worker - ERROR - Worker stream died during communication: tcp://134.158.168.226:45460
Traceback (most recent call last):
  File "/sps/lsst/users/boutigny/conda_envs/desc_2/lib/python3.8/site-packages/distributed/comm/tcp.py", line 200, in read
    n = await stream.read_into(frames)
tornado.iostream.StreamClosedError: Stream is closed

The above exception was the direct cause of the following exception:

Traceback (most recent call last):
  File "/sps/lsst/users/boutigny/conda_envs/desc_2/lib/python3.8/site-packages/distributed/worker.py", line 2169, in gather_dep
    response = await get_data_from_worker(
  File "/sps/lsst/users/boutigny/conda_envs/desc_2/lib/python3.8/site-packages/distributed/worker.py", line 3442, in get_data_from_worker
    return await retry_operation(_get_data, operation="get_data_from_worker")
  File "/sps/lsst/users/boutigny/conda_envs/desc_2/lib/python3.8/site-packages/distributed/utils_comm.py", line 385, in retry_operation
    return await retry(
  File "/sps/lsst/users/boutigny/conda_envs/desc_2/lib/python3.8/site-packages/distributed/utils_comm.py", line 370, in retry
    return await coro()
  File "/sps/lsst/users/boutigny/conda_envs/desc_2/lib/python3.8/site-packages/distributed/worker.py", line 3422, in _get_data
    response = await send_recv(
  File "/sps/lsst/users/boutigny/conda_envs/desc_2/lib/python3.8/site-packages/distributed/core.py", line 645, in send_recv
    response = await comm.read(deserializers=deserializers)
  File "/sps/lsst/users/boutigny/conda_envs/desc_2/lib/python3.8/site-packages/distributed/comm/tcp.py", line 206, in read
    convert_stream_closed_error(self, e)
  File "/sps/lsst/users/boutigny/conda_envs/desc_2/lib/python3.8/site-packages/distributed/comm/tcp.py", line 128, in convert_stream_closed_error
    raise CommClosedError("in %s: %s" % (obj, exc)) from exc
distributed.comm.core.CommClosedError: in <closed TCP>: Stream is closed
distributed.worker - WARNING - Memory use is high but worker has no data to store to disk.  Perhaps some other process is leaking memory?  Process memory: 3.38 GiB -- Worker memory limit: 4.66 GiB
distributed.utils - ERROR - Timed out trying to connect to tcp://134.158.48.24:42415 after 10 s
Traceback (most recent call last):
  File "/sps/lsst/users/boutigny/conda_envs/desc_2/lib/python3.8/site-packages/distributed/comm/core.py", line 285, in connect
    comm = await asyncio.wait_for(
  File "/sps/lsst/users/boutigny/conda_envs/desc_2/lib/python3.8/asyncio/tasks.py", line 501, in wait_for
    raise exceptions.TimeoutError()
asyncio.exceptions.TimeoutError

The above exception was the direct cause of the following exception:

Traceback (most recent call last):
  File "/sps/lsst/users/boutigny/conda_envs/desc_2/lib/python3.8/site-packages/distributed/utils.py", line 668, in log_errors
    yield
  File "/sps/lsst/users/boutigny/conda_envs/desc_2/lib/python3.8/site-packages/distributed/worker.py", line 2353, in query_who_has
    response = await retry_operation(self.scheduler.who_has, keys=deps)
  File "/sps/lsst/users/boutigny/conda_envs/desc_2/lib/python3.8/site-packages/distributed/utils_comm.py", line 385, in retry_operation
    return await retry(
  File "/sps/lsst/users/boutigny/conda_envs/desc_2/lib/python3.8/site-packages/distributed/utils_comm.py", line 370, in retry
    return await coro()
  File "/sps/lsst/users/boutigny/conda_envs/desc_2/lib/python3.8/site-packages/distributed/core.py", line 859, in send_recv_from_rpc
    comm = await self.pool.connect(self.addr)
  File "/sps/lsst/users/boutigny/conda_envs/desc_2/lib/python3.8/site-packages/distributed/core.py", line 1010, in connect
    comm = await connect(
  File "/sps/lsst/users/boutigny/conda_envs/desc_2/lib/python3.8/site-packages/distributed/comm/core.py", line 307, in connect
    raise IOError(
OSError: Timed out trying to connect to tcp://134.158.48.24:42415 after 10 s
distributed.utils - ERROR - Timed out trying to connect to tcp://134.158.48.24:42415 after 10 s
Traceback (most recent call last):
  File "/sps/lsst/users/boutigny/conda_envs/desc_2/lib/python3.8/site-packages/distributed/comm/core.py", line 285, in connect
    comm = await asyncio.wait_for(
  File "/sps/lsst/users/boutigny/conda_envs/desc_2/lib/python3.8/asyncio/tasks.py", line 501, in wait_for
    raise exceptions.TimeoutError()
asyncio.exceptions.TimeoutError

The above exception was the direct cause of the following exception:

Traceback (most recent call last):
  File "/sps/lsst/users/boutigny/conda_envs/desc_2/lib/python3.8/site-packages/distributed/utils.py", line 668, in log_errors
    yield
  File "/sps/lsst/users/boutigny/conda_envs/desc_2/lib/python3.8/site-packages/distributed/worker.py", line 2282, in gather_dep
    await self.query_who_has(dep.key)
  File "/sps/lsst/users/boutigny/conda_envs/desc_2/lib/python3.8/site-packages/distributed/worker.py", line 2353, in query_who_has
    response = await retry_operation(self.scheduler.who_has, keys=deps)
  File "/sps/lsst/users/boutigny/conda_envs/desc_2/lib/python3.8/site-packages/distributed/utils_comm.py", line 385, in retry_operation
    return await retry(
  File "/sps/lsst/users/boutigny/conda_envs/desc_2/lib/python3.8/site-packages/distributed/utils_comm.py", line 370, in retry
    return await coro()
  File "/sps/lsst/users/boutigny/conda_envs/desc_2/lib/python3.8/site-packages/distributed/core.py", line 859, in send_recv_from_rpc
    comm = await self.pool.connect(self.addr)
  File "/sps/lsst/users/boutigny/conda_envs/desc_2/lib/python3.8/site-packages/distributed/core.py", line 1010, in connect
    comm = await connect(
  File "/sps/lsst/users/boutigny/conda_envs/desc_2/lib/python3.8/site-packages/distributed/comm/core.py", line 307, in connect
    raise IOError(
OSError: Timed out trying to connect to tcp://134.158.48.24:42415 after 10 s
distributed.comm.tcp - INFO - Connection closed before handshake completed
distributed.comm.tcp - INFO - Connection closed before handshake completed
tornado.application - ERROR - Exception in callback functools.partial(<bound method IOLoop._discard_future_result of <tornado.platform.asyncio.AsyncIOLoop object at 0x2ab92bcae520>>, <Task finished name='Task-205' coro=<Worker.gather_dep() done, defined at /sps/lsst/users/boutigny/conda_envs/desc_2/lib/python3.8/site-packages/distributed/worker.py:2137> exception=OSError('Timed out trying to connect to tcp://134.158.48.24:42415 after 10 s')>)
Traceback (most recent call last):
  File "/sps/lsst/users/boutigny/conda_envs/desc_2/lib/python3.8/site-packages/distributed/comm/core.py", line 285, in connect
    comm = await asyncio.wait_for(
  File "/sps/lsst/users/boutigny/conda_envs/desc_2/lib/python3.8/asyncio/tasks.py", line 501, in wait_for
    raise exceptions.TimeoutError()
asyncio.exceptions.TimeoutError

The above exception was the direct cause of the following exception:

Traceback (most recent call last):
  File "/sps/lsst/users/boutigny/conda_envs/desc_2/lib/python3.8/site-packages/tornado/ioloop.py", line 741, in _run_callback
    ret = callback()
  File "/sps/lsst/users/boutigny/conda_envs/desc_2/lib/python3.8/site-packages/tornado/ioloop.py", line 765, in _discard_future_result
    future.result()
  File "/sps/lsst/users/boutigny/conda_envs/desc_2/lib/python3.8/site-packages/distributed/worker.py", line 2282, in gather_dep
    await self.query_who_has(dep.key)
  File "/sps/lsst/users/boutigny/conda_envs/desc_2/lib/python3.8/site-packages/distributed/worker.py", line 2353, in query_who_has
    response = await retry_operation(self.scheduler.who_has, keys=deps)
  File "/sps/lsst/users/boutigny/conda_envs/desc_2/lib/python3.8/site-packages/distributed/utils_comm.py", line 385, in retry_operation
    return await retry(
  File "/sps/lsst/users/boutigny/conda_envs/desc_2/lib/python3.8/site-packages/distributed/utils_comm.py", line 370, in retry
    return await coro()
  File "/sps/lsst/users/boutigny/conda_envs/desc_2/lib/python3.8/site-packages/distributed/core.py", line 859, in send_recv_from_rpc
    comm = await self.pool.connect(self.addr)
  File "/sps/lsst/users/boutigny/conda_envs/desc_2/lib/python3.8/site-packages/distributed/core.py", line 1010, in connect
    comm = await connect(
  File "/sps/lsst/users/boutigny/conda_envs/desc_2/lib/python3.8/site-packages/distributed/comm/core.py", line 307, in connect
    raise IOError(
OSError: Timed out trying to connect to tcp://134.158.48.24:42415 after 10 s
distributed.worker - WARNING - Worker is at 88% memory usage. Pausing worker.  Process memory: 4.13 GiB -- Worker memory limit: 4.66 GiB
distributed.worker - WARNING - Memory use is high but worker has no data to store to disk.  Perhaps some other process is leaking memory?  Process memory: 4.20 GiB -- Worker memory limit: 4.66 GiB
distributed.worker - WARNING - Memory use is high but worker has no data to store to disk.  Perhaps some other process is leaking memory?  Process memory: 4.20 GiB -- Worker memory limit: 4.66 GiB
distributed.worker - WARNING - Memory use is high but worker has no data to store to disk.  Perhaps some other process is leaking memory?  Process memory: 4.21 GiB -- Worker memory limit: 4.66 GiB
distributed.worker - WARNING - Memory use is high but worker has no data to store to disk.  Perhaps some other process is leaking memory?  Process memory: 4.18 GiB -- Worker memory limit: 4.66 GiB
distributed.worker - WARNING - Memory use is high but worker has no data to store to disk.  Perhaps some other process is leaking memory?  Process memory: 4.20 GiB -- Worker memory limit: 4.66 GiB
distributed.worker - WARNING - Memory use is high but worker has no data to store to disk.  Perhaps some other process is leaking memory?  Process memory: 4.20 GiB -- Worker memory limit: 4.66 GiB
distributed.worker - WARNING - Memory use is high but worker has no data to store to disk.  Perhaps some other process is leaking memory?  Process memory: 4.21 GiB -- Worker memory limit: 4.66 GiB
distributed.worker - WARNING - Memory use is high but worker has no data to store to disk.  Perhaps some other process is leaking memory?  Process memory: 4.21 GiB -- Worker memory limit: 4.66 GiB
distributed.worker - WARNING - Worker is at 79% memory usage. Resuming worker. Process memory: 3.69 GiB -- Worker memory limit: 4.66 GiB
distributed.worker - WARNING - Memory use is high but worker has no data to store to disk.  Perhaps some other process is leaking memory?  Process memory: 3.69 GiB -- Worker memory limit: 4.66 GiB
distributed.nanny - WARNING - Worker exceeded 95% memory budget. Restarting
distributed.nanny - INFO - Worker process 1929 was killed by signal 15
distributed.nanny - WARNING - Restarting worker
/sps/lsst/users/boutigny/conda_envs/desc_2/lib/python3.8/contextlib.py:120: UserWarning: Creating scratch directories is taking a surprisingly long time. This is often due to running workers on a network file system. Consider specifying a local-directory to point workers to write scratch data to a local disk.
  next(self.gen)
distributed.worker - INFO -       Start worker at: tcp://134.158.168.70:36962
distributed.worker - INFO -          Listening to: tcp://134.158.168.70:36962
distributed.worker - INFO -          dashboard at:       134.158.168.70:43882
distributed.worker - INFO - Waiting to connect to:  tcp://134.158.48.24:42415
distributed.worker - INFO - -------------------------------------------------
distributed.worker - INFO -               Threads:                          1
distributed.worker - INFO -                Memory:                   4.66 GiB
distributed.worker - INFO -       Local Directory: /pbs/throng/lsst/users/boutigny/LSST_notebooks/Dask/dask-worker-space/worker-7fdv_d2j
distributed.worker - INFO - -------------------------------------------------
distributed.worker - INFO -         Registered to:  tcp://134.158.48.24:42415
distributed.worker - INFO - -------------------------------------------------
distributed.core - INFO - Starting established connection
distributed.worker - ERROR - Worker stream died during communication: tcp://134.158.168.170:43451
Traceback (most recent call last):
  File "/sps/lsst/users/boutigny/conda_envs/desc_2/lib/python3.8/site-packages/tornado/iostream.py", line 867, in _read_to_buffer
    bytes_read = self.read_from_fd(buf)
  File "/sps/lsst/users/boutigny/conda_envs/desc_2/lib/python3.8/site-packages/tornado/iostream.py", line 1140, in read_from_fd
    return self.socket.recv_into(buf, len(buf))
ConnectionResetError: [Errno 104] Connection reset by peer

The above exception was the direct cause of the following exception:

Traceback (most recent call last):
  File "/sps/lsst/users/boutigny/conda_envs/desc_2/lib/python3.8/site-packages/distributed/comm/core.py", line 318, in connect
    handshake = await asyncio.wait_for(comm.read(), time_left())
  File "/sps/lsst/users/boutigny/conda_envs/desc_2/lib/python3.8/asyncio/tasks.py", line 494, in wait_for
    return fut.result()
  File "/sps/lsst/users/boutigny/conda_envs/desc_2/lib/python3.8/site-packages/distributed/comm/tcp.py", line 206, in read
    convert_stream_closed_error(self, e)
  File "/sps/lsst/users/boutigny/conda_envs/desc_2/lib/python3.8/site-packages/distributed/comm/tcp.py", line 124, in convert_stream_closed_error
    raise CommClosedError(
distributed.comm.core.CommClosedError: in <closed TCP>: ConnectionResetError: [Errno 104] Connection reset by peer

The above exception was the direct cause of the following exception:

Traceback (most recent call last):
  File "/sps/lsst/users/boutigny/conda_envs/desc_2/lib/python3.8/site-packages/distributed/worker.py", line 2169, in gather_dep
    response = await get_data_from_worker(
  File "/sps/lsst/users/boutigny/conda_envs/desc_2/lib/python3.8/site-packages/distributed/worker.py", line 3442, in get_data_from_worker
    return await retry_operation(_get_data, operation="get_data_from_worker")
  File "/sps/lsst/users/boutigny/conda_envs/desc_2/lib/python3.8/site-packages/distributed/utils_comm.py", line 385, in retry_operation
    return await retry(
  File "/sps/lsst/users/boutigny/conda_envs/desc_2/lib/python3.8/site-packages/distributed/utils_comm.py", line 370, in retry
    return await coro()
  File "/sps/lsst/users/boutigny/conda_envs/desc_2/lib/python3.8/site-packages/distributed/worker.py", line 3419, in _get_data
    comm = await rpc.connect(worker)
  File "/sps/lsst/users/boutigny/conda_envs/desc_2/lib/python3.8/site-packages/distributed/core.py", line 1010, in connect
    comm = await connect(
  File "/sps/lsst/users/boutigny/conda_envs/desc_2/lib/python3.8/site-packages/distributed/comm/core.py", line 323, in connect
    raise IOError(
OSError: Timed out during handshake while connecting to tcp://134.158.168.170:43451 after 10 s
distributed.worker - INFO - Can't find dependencies for key ('fix-overlap-and_-a2c92d0a7b4404ef4989bfc49cea49a2', 44)
distributed.worker - INFO - Dependent not found: ('set_index-de5055cf7981b50e2b876d80000d7d25', 44) 0 .  Asking scheduler
distributed.worker - ERROR - Worker stream died during communication: tcp://134.158.168.198:42939
Traceback (most recent call last):
  File "/sps/lsst/users/boutigny/conda_envs/desc_2/lib/python3.8/site-packages/tornado/iostream.py", line 867, in _read_to_buffer
    bytes_read = self.read_from_fd(buf)
  File "/sps/lsst/users/boutigny/conda_envs/desc_2/lib/python3.8/site-packages/tornado/iostream.py", line 1140, in read_from_fd
    return self.socket.recv_into(buf, len(buf))
ConnectionResetError: [Errno 104] Connection reset by peer

The above exception was the direct cause of the following exception:

Traceback (most recent call last):
  File "/sps/lsst/users/boutigny/conda_envs/desc_2/lib/python3.8/site-packages/distributed/worker.py", line 2169, in gather_dep
    response = await get_data_from_worker(
  File "/sps/lsst/users/boutigny/conda_envs/desc_2/lib/python3.8/site-packages/distributed/worker.py", line 3442, in get_data_from_worker
    return await retry_operation(_get_data, operation="get_data_from_worker")
  File "/sps/lsst/users/boutigny/conda_envs/desc_2/lib/python3.8/site-packages/distributed/utils_comm.py", line 385, in retry_operation
    return await retry(
  File "/sps/lsst/users/boutigny/conda_envs/desc_2/lib/python3.8/site-packages/distributed/utils_comm.py", line 370, in retry
    return await coro()
  File "/sps/lsst/users/boutigny/conda_envs/desc_2/lib/python3.8/site-packages/distributed/worker.py", line 3422, in _get_data
    response = await send_recv(
  File "/sps/lsst/users/boutigny/conda_envs/desc_2/lib/python3.8/site-packages/distributed/core.py", line 645, in send_recv
    response = await comm.read(deserializers=deserializers)
  File "/sps/lsst/users/boutigny/conda_envs/desc_2/lib/python3.8/site-packages/distributed/comm/tcp.py", line 206, in read
    convert_stream_closed_error(self, e)
  File "/sps/lsst/users/boutigny/conda_envs/desc_2/lib/python3.8/site-packages/distributed/comm/tcp.py", line 124, in convert_stream_closed_error
    raise CommClosedError(
distributed.comm.core.CommClosedError: in <closed TCP>: ConnectionResetError: [Errno 104] Connection reset by peer
distributed.worker - INFO - Can't find dependencies for key ('fix-overlap-and_-a2c92d0a7b4404ef4989bfc49cea49a2', 143)
distributed.worker - INFO - Dependent not found: ('set_index-de5055cf7981b50e2b876d80000d7d25', 142) 0 .  Asking scheduler
distributed.core - INFO - Event loop was unresponsive in Worker for 3.20s.  This is often caused by long-running GIL-holding functions or moving large chunks of data. This can cause timeouts and instability.
distributed.worker - ERROR - Worker stream died during communication: tcp://134.158.170.60:35065
Traceback (most recent call last):
  File "/sps/lsst/users/boutigny/conda_envs/desc_2/lib/python3.8/site-packages/distributed/comm/core.py", line 318, in connect
    handshake = await asyncio.wait_for(comm.read(), time_left())
  File "/sps/lsst/users/boutigny/conda_envs/desc_2/lib/python3.8/asyncio/tasks.py", line 501, in wait_for
    raise exceptions.TimeoutError()
asyncio.exceptions.TimeoutError

The above exception was the direct cause of the following exception:

Traceback (most recent call last):
  File "/sps/lsst/users/boutigny/conda_envs/desc_2/lib/python3.8/site-packages/distributed/worker.py", line 2169, in gather_dep
    response = await get_data_from_worker(
  File "/sps/lsst/users/boutigny/conda_envs/desc_2/lib/python3.8/site-packages/distributed/worker.py", line 3442, in get_data_from_worker
    return await retry_operation(_get_data, operation="get_data_from_worker")
  File "/sps/lsst/users/boutigny/conda_envs/desc_2/lib/python3.8/site-packages/distributed/utils_comm.py", line 385, in retry_operation
    return await retry(
  File "/sps/lsst/users/boutigny/conda_envs/desc_2/lib/python3.8/site-packages/distributed/utils_comm.py", line 370, in retry
    return await coro()
  File "/sps/lsst/users/boutigny/conda_envs/desc_2/lib/python3.8/site-packages/distributed/worker.py", line 3419, in _get_data
    comm = await rpc.connect(worker)
  File "/sps/lsst/users/boutigny/conda_envs/desc_2/lib/python3.8/site-packages/distributed/core.py", line 1010, in connect
    comm = await connect(
  File "/sps/lsst/users/boutigny/conda_envs/desc_2/lib/python3.8/site-packages/distributed/comm/core.py", line 323, in connect
    raise IOError(
OSError: Timed out during handshake while connecting to tcp://134.158.170.60:35065 after 10 s
distributed.worker - ERROR - Worker stream died during communication: tcp://134.158.170.46:37397
Traceback (most recent call last):
  File "/sps/lsst/users/boutigny/conda_envs/desc_2/lib/python3.8/site-packages/distributed/comm/core.py", line 318, in connect
    handshake = await asyncio.wait_for(comm.read(), time_left())
  File "/sps/lsst/users/boutigny/conda_envs/desc_2/lib/python3.8/asyncio/tasks.py", line 501, in wait_for
    raise exceptions.TimeoutError()
asyncio.exceptions.TimeoutError

The above exception was the direct cause of the following exception:

Traceback (most recent call last):
  File "/sps/lsst/users/boutigny/conda_envs/desc_2/lib/python3.8/site-packages/distributed/worker.py", line 2169, in gather_dep
    response = await get_data_from_worker(
  File "/sps/lsst/users/boutigny/conda_envs/desc_2/lib/python3.8/site-packages/distributed/worker.py", line 3442, in get_data_from_worker
    return await retry_operation(_get_data, operation="get_data_from_worker")
  File "/sps/lsst/users/boutigny/conda_envs/desc_2/lib/python3.8/site-packages/distributed/utils_comm.py", line 385, in retry_operation
    return await retry(
  File "/sps/lsst/users/boutigny/conda_envs/desc_2/lib/python3.8/site-packages/distributed/utils_comm.py", line 370, in retry
    return await coro()
  File "/sps/lsst/users/boutigny/conda_envs/desc_2/lib/python3.8/site-packages/distributed/worker.py", line 3419, in _get_data
    comm = await rpc.connect(worker)
  File "/sps/lsst/users/boutigny/conda_envs/desc_2/lib/python3.8/site-packages/distributed/core.py", line 1010, in connect
    comm = await connect(
  File "/sps/lsst/users/boutigny/conda_envs/desc_2/lib/python3.8/site-packages/distributed/comm/core.py", line 323, in connect
    raise IOError(
OSError: Timed out during handshake while connecting to tcp://134.158.170.46:37397 after 10 s
distributed.utils_perf - INFO - full garbage collection released 0.95 GiB from 19 reference cycles (threshold: 9.54 MiB)
distributed.worker - ERROR - Worker stream died during communication: tcp://134.158.168.237:39462
Traceback (most recent call last):
  File "/sps/lsst/users/boutigny/conda_envs/desc_2/lib/python3.8/site-packages/distributed/comm/tcp.py", line 200, in read
    n = await stream.read_into(frames)
tornado.iostream.StreamClosedError: Stream is closed

The above exception was the direct cause of the following exception:

Traceback (most recent call last):
  File "/sps/lsst/users/boutigny/conda_envs/desc_2/lib/python3.8/site-packages/distributed/worker.py", line 2169, in gather_dep
    response = await get_data_from_worker(
  File "/sps/lsst/users/boutigny/conda_envs/desc_2/lib/python3.8/site-packages/distributed/worker.py", line 3442, in get_data_from_worker
    return await retry_operation(_get_data, operation="get_data_from_worker")
  File "/sps/lsst/users/boutigny/conda_envs/desc_2/lib/python3.8/site-packages/distributed/utils_comm.py", line 385, in retry_operation
    return await retry(
  File "/sps/lsst/users/boutigny/conda_envs/desc_2/lib/python3.8/site-packages/distributed/utils_comm.py", line 370, in retry
    return await coro()
  File "/sps/lsst/users/boutigny/conda_envs/desc_2/lib/python3.8/site-packages/distributed/worker.py", line 3422, in _get_data
    response = await send_recv(
  File "/sps/lsst/users/boutigny/conda_envs/desc_2/lib/python3.8/site-packages/distributed/core.py", line 645, in send_recv
    response = await comm.read(deserializers=deserializers)
  File "/sps/lsst/users/boutigny/conda_envs/desc_2/lib/python3.8/site-packages/distributed/comm/tcp.py", line 206, in read
    convert_stream_closed_error(self, e)
  File "/sps/lsst/users/boutigny/conda_envs/desc_2/lib/python3.8/site-packages/distributed/comm/tcp.py", line 128, in convert_stream_closed_error
    raise CommClosedError("in %s: %s" % (obj, exc)) from exc
distributed.comm.core.CommClosedError: in <closed TCP>: Stream is closed
distributed.worker - ERROR - failed during get data with tcp://134.158.168.70:36962 -> tcp://134.158.168.64:37041
Traceback (most recent call last):
  File "/sps/lsst/users/boutigny/conda_envs/desc_2/lib/python3.8/site-packages/tornado/iostream.py", line 867, in _read_to_buffer
    bytes_read = self.read_from_fd(buf)
  File "/sps/lsst/users/boutigny/conda_envs/desc_2/lib/python3.8/site-packages/tornado/iostream.py", line 1140, in read_from_fd
    return self.socket.recv_into(buf, len(buf))
ConnectionResetError: [Errno 104] Connection reset by peer

The above exception was the direct cause of the following exception:

Traceback (most recent call last):
  File "/sps/lsst/users/boutigny/conda_envs/desc_2/lib/python3.8/site-packages/distributed/worker.py", line 1366, in get_data
    response = await comm.read(deserializers=serializers)
  File "/sps/lsst/users/boutigny/conda_envs/desc_2/lib/python3.8/site-packages/distributed/comm/tcp.py", line 206, in read
    convert_stream_closed_error(self, e)
  File "/sps/lsst/users/boutigny/conda_envs/desc_2/lib/python3.8/site-packages/distributed/comm/tcp.py", line 124, in convert_stream_closed_error
    raise CommClosedError(
distributed.comm.core.CommClosedError: in <closed TCP>: ConnectionResetError: [Errno 104] Connection reset by peer
distributed.core - INFO - Lost connection to 'tcp://134.158.168.64:37558': in <closed TCP>: ConnectionResetError: [Errno 104] Connection reset by peer
distributed.worker - ERROR - Worker stream died during communication: tcp://134.158.170.59:33682
Traceback (most recent call last):
  File "/sps/lsst/users/boutigny/conda_envs/desc_2/lib/python3.8/site-packages/distributed/comm/tcp.py", line 200, in read
    n = await stream.read_into(frames)
tornado.iostream.StreamClosedError: Stream is closed

The above exception was the direct cause of the following exception:

Traceback (most recent call last):
  File "/sps/lsst/users/boutigny/conda_envs/desc_2/lib/python3.8/site-packages/distributed/worker.py", line 2169, in gather_dep
    response = await get_data_from_worker(
  File "/sps/lsst/users/boutigny/conda_envs/desc_2/lib/python3.8/site-packages/distributed/worker.py", line 3442, in get_data_from_worker
    return await retry_operation(_get_data, operation="get_data_from_worker")
  File "/sps/lsst/users/boutigny/conda_envs/desc_2/lib/python3.8/site-packages/distributed/utils_comm.py", line 385, in retry_operation
    return await retry(
  File "/sps/lsst/users/boutigny/conda_envs/desc_2/lib/python3.8/site-packages/distributed/utils_comm.py", line 370, in retry
    return await coro()
  File "/sps/lsst/users/boutigny/conda_envs/desc_2/lib/python3.8/site-packages/distributed/worker.py", line 3422, in _get_data
    response = await send_recv(
  File "/sps/lsst/users/boutigny/conda_envs/desc_2/lib/python3.8/site-packages/distributed/core.py", line 645, in send_recv
    response = await comm.read(deserializers=deserializers)
  File "/sps/lsst/users/boutigny/conda_envs/desc_2/lib/python3.8/site-packages/distributed/comm/tcp.py", line 206, in read
    convert_stream_closed_error(self, e)
  File "/sps/lsst/users/boutigny/conda_envs/desc_2/lib/python3.8/site-packages/distributed/comm/tcp.py", line 128, in convert_stream_closed_error
    raise CommClosedError("in %s: %s" % (obj, exc)) from exc
distributed.comm.core.CommClosedError: in <closed TCP>: Stream is closed
distributed.nanny - WARNING - Worker exceeded 95% memory budget. Restarting
distributed.nanny - WARNING - Worker exceeded 95% memory budget. Restarting
distributed.nanny - WARNING - Worker exceeded 95% memory budget. Restarting
distributed.nanny - WARNING - Worker exceeded 95% memory budget. Restarting
distributed.nanny - WARNING - Worker exceeded 95% memory budget. Restarting
distributed.nanny - WARNING - Worker exceeded 95% memory budget. Restarting
distributed.nanny - WARNING - Worker exceeded 95% memory budget. Restarting
distributed.nanny - WARNING - Worker exceeded 95% memory budget. Restarting
distributed.nanny - WARNING - Worker exceeded 95% memory budget. Restarting
distributed.nanny - WARNING - Worker exceeded 95% memory budget. Restarting
distributed.nanny - WARNING - Worker exceeded 95% memory budget. Restarting
distributed.nanny - WARNING - Worker exceeded 95% memory budget. Restarting
distributed.nanny - INFO - Worker process 2263 was killed by signal 15
distributed.nanny - WARNING - Restarting worker
distributed.worker - INFO -       Start worker at: tcp://134.158.168.70:45241
distributed.worker - INFO -          Listening to: tcp://134.158.168.70:45241
distributed.worker - INFO -          dashboard at:       134.158.168.70:36481
distributed.worker - INFO - Waiting to connect to:  tcp://134.158.48.24:42415
distributed.worker - INFO - -------------------------------------------------
distributed.worker - INFO -               Threads:                          1
distributed.worker - INFO -                Memory:                   4.66 GiB
distributed.worker - INFO -       Local Directory: /pbs/throng/lsst/users/boutigny/LSST_notebooks/Dask/dask-worker-space/worker-20m29daj
distributed.worker - INFO - -------------------------------------------------
distributed.worker - INFO -         Registered to:  tcp://134.158.48.24:42415
distributed.worker - INFO - -------------------------------------------------
distributed.core - INFO - Starting established connection
distributed.worker - ERROR - Worker stream died during communication: tcp://134.158.168.221:43551
Traceback (most recent call last):
  File "/sps/lsst/users/boutigny/conda_envs/desc_2/lib/python3.8/site-packages/distributed/comm/tcp.py", line 200, in read
    n = await stream.read_into(frames)
tornado.iostream.StreamClosedError: Stream is closed

The above exception was the direct cause of the following exception:

Traceback (most recent call last):
  File "/sps/lsst/users/boutigny/conda_envs/desc_2/lib/python3.8/site-packages/distributed/worker.py", line 2169, in gather_dep
    response = await get_data_from_worker(
  File "/sps/lsst/users/boutigny/conda_envs/desc_2/lib/python3.8/site-packages/distributed/worker.py", line 3442, in get_data_from_worker
    return await retry_operation(_get_data, operation="get_data_from_worker")
  File "/sps/lsst/users/boutigny/conda_envs/desc_2/lib/python3.8/site-packages/distributed/utils_comm.py", line 385, in retry_operation
    return await retry(
  File "/sps/lsst/users/boutigny/conda_envs/desc_2/lib/python3.8/site-packages/distributed/utils_comm.py", line 370, in retry
    return await coro()
  File "/sps/lsst/users/boutigny/conda_envs/desc_2/lib/python3.8/site-packages/distributed/worker.py", line 3422, in _get_data
    response = await send_recv(
  File "/sps/lsst/users/boutigny/conda_envs/desc_2/lib/python3.8/site-packages/distributed/core.py", line 645, in send_recv
    response = await comm.read(deserializers=deserializers)
  File "/sps/lsst/users/boutigny/conda_envs/desc_2/lib/python3.8/site-packages/distributed/comm/tcp.py", line 206, in read
    convert_stream_closed_error(self, e)
  File "/sps/lsst/users/boutigny/conda_envs/desc_2/lib/python3.8/site-packages/distributed/comm/tcp.py", line 128, in convert_stream_closed_error
    raise CommClosedError("in %s: %s" % (obj, exc)) from exc
distributed.comm.core.CommClosedError: in <closed TCP>: Stream is closed
distributed.worker - WARNING - Worker is at 80% memory usage. Pausing worker.  Process memory: 3.77 GiB -- Worker memory limit: 4.66 GiB
distributed.worker - WARNING - Worker is at 24% memory usage. Resuming worker. Process memory: 1.14 GiB -- Worker memory limit: 4.66 GiB
