**********************************************************************
*                     Grid Engine Batch System                       *
*              IN2P3 Computing Centre, Villeurbanne FR               *
**********************************************************************
* User:                           boutigny                           *
* Group:                          lsst                               *
* Jobname:                        dask-worker                        *
* JobID:                          15661293                           *
* Queue:                          mc_highmem                         *
* Worker:                         ccwsge0362.in2p3.fr                *
* Operating system:               Linux 3.10.0-1160.25.1.el7.x86_64  *
* Project:                        P_lsst                             *
**********************************************************************
* Submitted on:                   Tue Jul 20 19:45:38 CEST 2021      *
* Started on:                     Tue Jul 20 19:45:44 CEST 2021      *
**********************************************************************
coucou
distributed.nanny - INFO -         Start Nanny at: 'tcp://134.158.168.220:46323'
distributed.worker - INFO -       Start worker at: tcp://134.158.168.220:43729
distributed.worker - INFO -          Listening to: tcp://134.158.168.220:43729
distributed.worker - INFO -          dashboard at:      134.158.168.220:37583
distributed.worker - INFO - Waiting to connect to:  tcp://134.158.48.24:42415
distributed.worker - INFO - -------------------------------------------------
distributed.worker - INFO -               Threads:                          1
distributed.worker - INFO -                Memory:                   4.66 GiB
distributed.worker - INFO -       Local Directory: /pbs/throng/lsst/users/boutigny/LSST_notebooks/Dask/dask-worker-space/worker-ew9mt2p8
distributed.worker - INFO - -------------------------------------------------
distributed.worker - INFO -         Registered to:  tcp://134.158.48.24:42415
distributed.worker - INFO - -------------------------------------------------
distributed.core - INFO - Starting established connection
distributed.core - INFO - Event loop was unresponsive in Worker for 4.84s.  This is often caused by long-running GIL-holding functions or moving large chunks of data. This can cause timeouts and instability.
distributed.comm.tcp - INFO - Connection closed before handshake completed
distributed.worker - ERROR - failed during get data with tcp://134.158.168.220:43729 -> tcp://134.158.170.32:41455
Traceback (most recent call last):
  File "/sps/lsst/users/boutigny/conda_envs/desc_2/lib/python3.8/site-packages/tornado/iostream.py", line 867, in _read_to_buffer
    bytes_read = self.read_from_fd(buf)
  File "/sps/lsst/users/boutigny/conda_envs/desc_2/lib/python3.8/site-packages/tornado/iostream.py", line 1140, in read_from_fd
    return self.socket.recv_into(buf, len(buf))
ConnectionResetError: [Errno 104] Connection reset by peer

The above exception was the direct cause of the following exception:

Traceback (most recent call last):
  File "/sps/lsst/users/boutigny/conda_envs/desc_2/lib/python3.8/site-packages/distributed/worker.py", line 1366, in get_data
    response = await comm.read(deserializers=serializers)
  File "/sps/lsst/users/boutigny/conda_envs/desc_2/lib/python3.8/site-packages/distributed/comm/tcp.py", line 206, in read
    convert_stream_closed_error(self, e)
  File "/sps/lsst/users/boutigny/conda_envs/desc_2/lib/python3.8/site-packages/distributed/comm/tcp.py", line 124, in convert_stream_closed_error
    raise CommClosedError(
distributed.comm.core.CommClosedError: in <closed TCP>: ConnectionResetError: [Errno 104] Connection reset by peer
distributed.core - INFO - Lost connection to 'tcp://134.158.170.32:59458': in <closed TCP>: ConnectionResetError: [Errno 104] Connection reset by peer
distributed.worker - ERROR - failed during get data with tcp://134.158.168.220:43729 -> tcp://134.158.170.3:36309
Traceback (most recent call last):
  File "/sps/lsst/users/boutigny/conda_envs/desc_2/lib/python3.8/site-packages/tornado/iostream.py", line 867, in _read_to_buffer
    bytes_read = self.read_from_fd(buf)
  File "/sps/lsst/users/boutigny/conda_envs/desc_2/lib/python3.8/site-packages/tornado/iostream.py", line 1140, in read_from_fd
    return self.socket.recv_into(buf, len(buf))
ConnectionResetError: [Errno 104] Connection reset by peer

The above exception was the direct cause of the following exception:

Traceback (most recent call last):
  File "/sps/lsst/users/boutigny/conda_envs/desc_2/lib/python3.8/site-packages/distributed/worker.py", line 1366, in get_data
    response = await comm.read(deserializers=serializers)
  File "/sps/lsst/users/boutigny/conda_envs/desc_2/lib/python3.8/site-packages/distributed/comm/tcp.py", line 206, in read
    convert_stream_closed_error(self, e)
  File "/sps/lsst/users/boutigny/conda_envs/desc_2/lib/python3.8/site-packages/distributed/comm/tcp.py", line 124, in convert_stream_closed_error
    raise CommClosedError(
distributed.comm.core.CommClosedError: in <closed TCP>: ConnectionResetError: [Errno 104] Connection reset by peer
distributed.core - INFO - Lost connection to 'tcp://134.158.170.3:44888': in <closed TCP>: ConnectionResetError: [Errno 104] Connection reset by peer
distributed.worker - ERROR - failed during get data with tcp://134.158.168.220:43729 -> tcp://134.158.170.42:42146
Traceback (most recent call last):
  File "/sps/lsst/users/boutigny/conda_envs/desc_2/lib/python3.8/site-packages/tornado/iostream.py", line 867, in _read_to_buffer
    bytes_read = self.read_from_fd(buf)
  File "/sps/lsst/users/boutigny/conda_envs/desc_2/lib/python3.8/site-packages/tornado/iostream.py", line 1140, in read_from_fd
    return self.socket.recv_into(buf, len(buf))
ConnectionResetError: [Errno 104] Connection reset by peer

The above exception was the direct cause of the following exception:

Traceback (most recent call last):
  File "/sps/lsst/users/boutigny/conda_envs/desc_2/lib/python3.8/site-packages/distributed/worker.py", line 1366, in get_data
    response = await comm.read(deserializers=serializers)
  File "/sps/lsst/users/boutigny/conda_envs/desc_2/lib/python3.8/site-packages/distributed/comm/tcp.py", line 206, in read
    convert_stream_closed_error(self, e)
  File "/sps/lsst/users/boutigny/conda_envs/desc_2/lib/python3.8/site-packages/distributed/comm/tcp.py", line 124, in convert_stream_closed_error
    raise CommClosedError(
distributed.comm.core.CommClosedError: in <closed TCP>: ConnectionResetError: [Errno 104] Connection reset by peer
distributed.core - INFO - Lost connection to 'tcp://134.158.170.42:40364': in <closed TCP>: ConnectionResetError: [Errno 104] Connection reset by peer
distributed.nanny - WARNING - Worker exceeded 95% memory budget. Restarting
distributed.nanny - WARNING - Worker exceeded 95% memory budget. Restarting
distributed.nanny - WARNING - Worker exceeded 95% memory budget. Restarting
distributed.nanny - WARNING - Worker exceeded 95% memory budget. Restarting
distributed.nanny - WARNING - Worker exceeded 95% memory budget. Restarting
distributed.nanny - WARNING - Worker exceeded 95% memory budget. Restarting
distributed.nanny - WARNING - Worker exceeded 95% memory budget. Restarting
distributed.nanny - WARNING - Worker exceeded 95% memory budget. Restarting
distributed.nanny - WARNING - Worker exceeded 95% memory budget. Restarting
distributed.nanny - WARNING - Worker exceeded 95% memory budget. Restarting
distributed.nanny - WARNING - Worker exceeded 95% memory budget. Restarting
distributed.nanny - WARNING - Worker exceeded 95% memory budget. Restarting
distributed.nanny - WARNING - Worker exceeded 95% memory budget. Restarting
distributed.nanny - WARNING - Worker exceeded 95% memory budget. Restarting
distributed.nanny - WARNING - Worker exceeded 95% memory budget. Restarting
distributed.nanny - WARNING - Worker exceeded 95% memory budget. Restarting
distributed.nanny - WARNING - Worker exceeded 95% memory budget. Restarting
distributed.nanny - WARNING - Worker exceeded 95% memory budget. Restarting
distributed.nanny - INFO - Worker process 30699 was killed by signal 15
distributed.nanny - WARNING - Restarting worker
/sps/lsst/users/boutigny/conda_envs/desc_2/lib/python3.8/contextlib.py:120: UserWarning: Creating scratch directories is taking a surprisingly long time. This is often due to running workers on a network file system. Consider specifying a local-directory to point workers to write scratch data to a local disk.
  next(self.gen)
distributed.worker - INFO -       Start worker at: tcp://134.158.168.220:35443
distributed.worker - INFO -          Listening to: tcp://134.158.168.220:35443
distributed.worker - INFO -          dashboard at:      134.158.168.220:46205
distributed.worker - INFO - Waiting to connect to:  tcp://134.158.48.24:42415
distributed.worker - INFO - -------------------------------------------------
distributed.worker - INFO -               Threads:                          1
distributed.worker - INFO -                Memory:                   4.66 GiB
distributed.worker - INFO -       Local Directory: /pbs/throng/lsst/users/boutigny/LSST_notebooks/Dask/dask-worker-space/worker-qu451fy3
distributed.worker - INFO - -------------------------------------------------
distributed.worker - INFO -         Registered to:  tcp://134.158.48.24:42415
distributed.worker - INFO - -------------------------------------------------
distributed.core - INFO - Starting established connection
distributed.worker - ERROR - Worker stream died during communication: tcp://134.158.170.3:43478
Traceback (most recent call last):
  File "/sps/lsst/users/boutigny/conda_envs/desc_2/lib/python3.8/site-packages/tornado/iostream.py", line 867, in _read_to_buffer
    bytes_read = self.read_from_fd(buf)
  File "/sps/lsst/users/boutigny/conda_envs/desc_2/lib/python3.8/site-packages/tornado/iostream.py", line 1140, in read_from_fd
    return self.socket.recv_into(buf, len(buf))
ConnectionResetError: [Errno 104] Connection reset by peer

The above exception was the direct cause of the following exception:

Traceback (most recent call last):
  File "/sps/lsst/users/boutigny/conda_envs/desc_2/lib/python3.8/site-packages/distributed/comm/core.py", line 318, in connect
    handshake = await asyncio.wait_for(comm.read(), time_left())
  File "/sps/lsst/users/boutigny/conda_envs/desc_2/lib/python3.8/asyncio/tasks.py", line 494, in wait_for
    return fut.result()
  File "/sps/lsst/users/boutigny/conda_envs/desc_2/lib/python3.8/site-packages/distributed/comm/tcp.py", line 206, in read
    convert_stream_closed_error(self, e)
  File "/sps/lsst/users/boutigny/conda_envs/desc_2/lib/python3.8/site-packages/distributed/comm/tcp.py", line 124, in convert_stream_closed_error
    raise CommClosedError(
distributed.comm.core.CommClosedError: in <closed TCP>: ConnectionResetError: [Errno 104] Connection reset by peer

The above exception was the direct cause of the following exception:

Traceback (most recent call last):
  File "/sps/lsst/users/boutigny/conda_envs/desc_2/lib/python3.8/site-packages/distributed/worker.py", line 2169, in gather_dep
    response = await get_data_from_worker(
  File "/sps/lsst/users/boutigny/conda_envs/desc_2/lib/python3.8/site-packages/distributed/worker.py", line 3442, in get_data_from_worker
    return await retry_operation(_get_data, operation="get_data_from_worker")
  File "/sps/lsst/users/boutigny/conda_envs/desc_2/lib/python3.8/site-packages/distributed/utils_comm.py", line 385, in retry_operation
    return await retry(
  File "/sps/lsst/users/boutigny/conda_envs/desc_2/lib/python3.8/site-packages/distributed/utils_comm.py", line 370, in retry
    return await coro()
  File "/sps/lsst/users/boutigny/conda_envs/desc_2/lib/python3.8/site-packages/distributed/worker.py", line 3419, in _get_data
    comm = await rpc.connect(worker)
  File "/sps/lsst/users/boutigny/conda_envs/desc_2/lib/python3.8/site-packages/distributed/core.py", line 1010, in connect
    comm = await connect(
  File "/sps/lsst/users/boutigny/conda_envs/desc_2/lib/python3.8/site-packages/distributed/comm/core.py", line 323, in connect
    raise IOError(
OSError: Timed out during handshake while connecting to tcp://134.158.170.3:43478 after 10 s
distributed.core - INFO - Event loop was unresponsive in Worker for 16.25s.  This is often caused by long-running GIL-holding functions or moving large chunks of data. This can cause timeouts and instability.
distributed.worker - ERROR - failed during get data with tcp://134.158.168.220:35443 -> tcp://134.158.170.52:40902
Traceback (most recent call last):
  File "/sps/lsst/users/boutigny/conda_envs/desc_2/lib/python3.8/site-packages/distributed/comm/tcp.py", line 196, in read
    frames_nbytes = await stream.read_bytes(fmt_size)
tornado.iostream.StreamClosedError: Stream is closed

The above exception was the direct cause of the following exception:

Traceback (most recent call last):
  File "/sps/lsst/users/boutigny/conda_envs/desc_2/lib/python3.8/site-packages/distributed/worker.py", line 1366, in get_data
    response = await comm.read(deserializers=serializers)
  File "/sps/lsst/users/boutigny/conda_envs/desc_2/lib/python3.8/site-packages/distributed/comm/tcp.py", line 206, in read
    convert_stream_closed_error(self, e)
  File "/sps/lsst/users/boutigny/conda_envs/desc_2/lib/python3.8/site-packages/distributed/comm/tcp.py", line 128, in convert_stream_closed_error
    raise CommClosedError("in %s: %s" % (obj, exc)) from exc
distributed.comm.core.CommClosedError: in <closed TCP>: Stream is closed
distributed.core - INFO - Lost connection to 'tcp://134.158.170.52:47578': in <closed TCP>: Stream is closed
distributed.core - INFO - Event loop was unresponsive in Worker for 4.94s.  This is often caused by long-running GIL-holding functions or moving large chunks of data. This can cause timeouts and instability.
distributed.comm.tcp - INFO - Connection closed before handshake completed
distributed.worker - ERROR - failed during get data with tcp://134.158.168.220:35443 -> tcp://134.158.170.53:34679
Traceback (most recent call last):
  File "/sps/lsst/users/boutigny/conda_envs/desc_2/lib/python3.8/site-packages/tornado/iostream.py", line 867, in _read_to_buffer
    bytes_read = self.read_from_fd(buf)
  File "/sps/lsst/users/boutigny/conda_envs/desc_2/lib/python3.8/site-packages/tornado/iostream.py", line 1140, in read_from_fd
    return self.socket.recv_into(buf, len(buf))
ConnectionResetError: [Errno 104] Connection reset by peer

The above exception was the direct cause of the following exception:

Traceback (most recent call last):
  File "/sps/lsst/users/boutigny/conda_envs/desc_2/lib/python3.8/site-packages/distributed/worker.py", line 1366, in get_data
    response = await comm.read(deserializers=serializers)
  File "/sps/lsst/users/boutigny/conda_envs/desc_2/lib/python3.8/site-packages/distributed/comm/tcp.py", line 206, in read
    convert_stream_closed_error(self, e)
  File "/sps/lsst/users/boutigny/conda_envs/desc_2/lib/python3.8/site-packages/distributed/comm/tcp.py", line 124, in convert_stream_closed_error
    raise CommClosedError(
distributed.comm.core.CommClosedError: in <closed TCP>: ConnectionResetError: [Errno 104] Connection reset by peer
distributed.core - INFO - Lost connection to 'tcp://134.158.170.53:34672': in <closed TCP>: ConnectionResetError: [Errno 104] Connection reset by peer
distributed.worker - ERROR - failed during get data with tcp://134.158.168.220:35443 -> tcp://134.158.168.67:36046
Traceback (most recent call last):
  File "/sps/lsst/users/boutigny/conda_envs/desc_2/lib/python3.8/site-packages/tornado/iostream.py", line 867, in _read_to_buffer
    bytes_read = self.read_from_fd(buf)
  File "/sps/lsst/users/boutigny/conda_envs/desc_2/lib/python3.8/site-packages/tornado/iostream.py", line 1140, in read_from_fd
    return self.socket.recv_into(buf, len(buf))
ConnectionResetError: [Errno 104] Connection reset by peer

The above exception was the direct cause of the following exception:

Traceback (most recent call last):
  File "/sps/lsst/users/boutigny/conda_envs/desc_2/lib/python3.8/site-packages/distributed/worker.py", line 1366, in get_data
    response = await comm.read(deserializers=serializers)
  File "/sps/lsst/users/boutigny/conda_envs/desc_2/lib/python3.8/site-packages/distributed/comm/tcp.py", line 206, in read
    convert_stream_closed_error(self, e)
  File "/sps/lsst/users/boutigny/conda_envs/desc_2/lib/python3.8/site-packages/distributed/comm/tcp.py", line 124, in convert_stream_closed_error
    raise CommClosedError(
distributed.comm.core.CommClosedError: in <closed TCP>: ConnectionResetError: [Errno 104] Connection reset by peer
distributed.nanny - WARNING - Worker exceeded 95% memory budget. Restarting
distributed.nanny - WARNING - Worker exceeded 95% memory budget. Restarting
distributed.nanny - WARNING - Worker exceeded 95% memory budget. Restarting
distributed.nanny - WARNING - Worker exceeded 95% memory budget. Restarting
distributed.nanny - WARNING - Worker exceeded 95% memory budget. Restarting
distributed.nanny - WARNING - Worker exceeded 95% memory budget. Restarting
distributed.nanny - WARNING - Worker exceeded 95% memory budget. Restarting
distributed.nanny - WARNING - Worker exceeded 95% memory budget. Restarting
distributed.nanny - WARNING - Worker exceeded 95% memory budget. Restarting
distributed.nanny - WARNING - Worker exceeded 95% memory budget. Restarting
distributed.nanny - WARNING - Worker exceeded 95% memory budget. Restarting
distributed.nanny - WARNING - Worker exceeded 95% memory budget. Restarting
distributed.nanny - WARNING - Worker exceeded 95% memory budget. Restarting
distributed.nanny - WARNING - Worker exceeded 95% memory budget. Restarting
distributed.nanny - WARNING - Worker exceeded 95% memory budget. Restarting
distributed.nanny - WARNING - Worker exceeded 95% memory budget. Restarting
distributed.nanny - WARNING - Worker exceeded 95% memory budget. Restarting
distributed.nanny - INFO - Worker process 31424 was killed by signal 15
distributed.nanny - WARNING - Restarting worker
distributed.worker - INFO -       Start worker at: tcp://134.158.168.220:33335
distributed.worker - INFO -          Listening to: tcp://134.158.168.220:33335
distributed.worker - INFO -          dashboard at:      134.158.168.220:36586
distributed.worker - INFO - Waiting to connect to:  tcp://134.158.48.24:42415
distributed.worker - INFO - -------------------------------------------------
distributed.worker - INFO -               Threads:                          1
distributed.worker - INFO -                Memory:                   4.66 GiB
distributed.worker - INFO -       Local Directory: /pbs/throng/lsst/users/boutigny/LSST_notebooks/Dask/dask-worker-space/worker-k6l_lrs5
distributed.worker - INFO - -------------------------------------------------
distributed.worker - INFO -         Registered to:  tcp://134.158.48.24:42415
distributed.worker - INFO - -------------------------------------------------
distributed.core - INFO - Starting established connection
distributed.worker - ERROR - Worker stream died during communication: tcp://134.158.168.189:36388
Traceback (most recent call last):
  File "/sps/lsst/users/boutigny/conda_envs/desc_2/lib/python3.8/site-packages/distributed/comm/tcp.py", line 200, in read
    n = await stream.read_into(frames)
tornado.iostream.StreamClosedError: Stream is closed

The above exception was the direct cause of the following exception:

Traceback (most recent call last):
  File "/sps/lsst/users/boutigny/conda_envs/desc_2/lib/python3.8/site-packages/distributed/worker.py", line 2169, in gather_dep
    response = await get_data_from_worker(
  File "/sps/lsst/users/boutigny/conda_envs/desc_2/lib/python3.8/site-packages/distributed/worker.py", line 3442, in get_data_from_worker
    return await retry_operation(_get_data, operation="get_data_from_worker")
  File "/sps/lsst/users/boutigny/conda_envs/desc_2/lib/python3.8/site-packages/distributed/utils_comm.py", line 385, in retry_operation
    return await retry(
  File "/sps/lsst/users/boutigny/conda_envs/desc_2/lib/python3.8/site-packages/distributed/utils_comm.py", line 370, in retry
    return await coro()
  File "/sps/lsst/users/boutigny/conda_envs/desc_2/lib/python3.8/site-packages/distributed/worker.py", line 3422, in _get_data
    response = await send_recv(
  File "/sps/lsst/users/boutigny/conda_envs/desc_2/lib/python3.8/site-packages/distributed/core.py", line 645, in send_recv
    response = await comm.read(deserializers=deserializers)
  File "/sps/lsst/users/boutigny/conda_envs/desc_2/lib/python3.8/site-packages/distributed/comm/tcp.py", line 206, in read
    convert_stream_closed_error(self, e)
  File "/sps/lsst/users/boutigny/conda_envs/desc_2/lib/python3.8/site-packages/distributed/comm/tcp.py", line 128, in convert_stream_closed_error
    raise CommClosedError("in %s: %s" % (obj, exc)) from exc
distributed.comm.core.CommClosedError: in <closed TCP>: Stream is closed
distributed.worker - ERROR - Worker stream died during communication: tcp://134.158.168.195:36407
Traceback (most recent call last):
  File "/sps/lsst/users/boutigny/conda_envs/desc_2/lib/python3.8/site-packages/distributed/comm/core.py", line 318, in connect
    handshake = await asyncio.wait_for(comm.read(), time_left())
  File "/sps/lsst/users/boutigny/conda_envs/desc_2/lib/python3.8/asyncio/tasks.py", line 501, in wait_for
    raise exceptions.TimeoutError()
asyncio.exceptions.TimeoutError

The above exception was the direct cause of the following exception:

Traceback (most recent call last):
  File "/sps/lsst/users/boutigny/conda_envs/desc_2/lib/python3.8/site-packages/distributed/worker.py", line 2169, in gather_dep
    response = await get_data_from_worker(
  File "/sps/lsst/users/boutigny/conda_envs/desc_2/lib/python3.8/site-packages/distributed/worker.py", line 3442, in get_data_from_worker
    return await retry_operation(_get_data, operation="get_data_from_worker")
  File "/sps/lsst/users/boutigny/conda_envs/desc_2/lib/python3.8/site-packages/distributed/utils_comm.py", line 385, in retry_operation
    return await retry(
  File "/sps/lsst/users/boutigny/conda_envs/desc_2/lib/python3.8/site-packages/distributed/utils_comm.py", line 370, in retry
    return await coro()
  File "/sps/lsst/users/boutigny/conda_envs/desc_2/lib/python3.8/site-packages/distributed/worker.py", line 3419, in _get_data
    comm = await rpc.connect(worker)
  File "/sps/lsst/users/boutigny/conda_envs/desc_2/lib/python3.8/site-packages/distributed/core.py", line 1010, in connect
    comm = await connect(
  File "/sps/lsst/users/boutigny/conda_envs/desc_2/lib/python3.8/site-packages/distributed/comm/core.py", line 323, in connect
    raise IOError(
OSError: Timed out during handshake while connecting to tcp://134.158.168.195:36407 after 10 s
distributed.core - INFO - Event loop was unresponsive in Worker for 7.46s.  This is often caused by long-running GIL-holding functions or moving large chunks of data. This can cause timeouts and instability.
distributed.worker - ERROR - Worker stream died during communication: tcp://134.158.170.48:35212
Traceback (most recent call last):
  File "/sps/lsst/users/boutigny/conda_envs/desc_2/lib/python3.8/site-packages/distributed/comm/tcp.py", line 196, in read
    frames_nbytes = await stream.read_bytes(fmt_size)
tornado.iostream.StreamClosedError: Stream is closed

The above exception was the direct cause of the following exception:

Traceback (most recent call last):
  File "/sps/lsst/users/boutigny/conda_envs/desc_2/lib/python3.8/site-packages/distributed/worker.py", line 2169, in gather_dep
    response = await get_data_from_worker(
  File "/sps/lsst/users/boutigny/conda_envs/desc_2/lib/python3.8/site-packages/distributed/worker.py", line 3442, in get_data_from_worker
    return await retry_operation(_get_data, operation="get_data_from_worker")
  File "/sps/lsst/users/boutigny/conda_envs/desc_2/lib/python3.8/site-packages/distributed/utils_comm.py", line 385, in retry_operation
    return await retry(
  File "/sps/lsst/users/boutigny/conda_envs/desc_2/lib/python3.8/site-packages/distributed/utils_comm.py", line 370, in retry
    return await coro()
  File "/sps/lsst/users/boutigny/conda_envs/desc_2/lib/python3.8/site-packages/distributed/worker.py", line 3422, in _get_data
    response = await send_recv(
  File "/sps/lsst/users/boutigny/conda_envs/desc_2/lib/python3.8/site-packages/distributed/core.py", line 645, in send_recv
    response = await comm.read(deserializers=deserializers)
  File "/sps/lsst/users/boutigny/conda_envs/desc_2/lib/python3.8/site-packages/distributed/comm/tcp.py", line 206, in read
    convert_stream_closed_error(self, e)
  File "/sps/lsst/users/boutigny/conda_envs/desc_2/lib/python3.8/site-packages/distributed/comm/tcp.py", line 128, in convert_stream_closed_error
    raise CommClosedError("in %s: %s" % (obj, exc)) from exc
distributed.comm.core.CommClosedError: in <closed TCP>: Stream is closed
distributed.worker - ERROR - failed during get data with tcp://134.158.168.220:33335 -> tcp://134.158.168.170:33715
Traceback (most recent call last):
  File "/sps/lsst/users/boutigny/conda_envs/desc_2/lib/python3.8/site-packages/distributed/comm/tcp.py", line 196, in read
    frames_nbytes = await stream.read_bytes(fmt_size)
tornado.iostream.StreamClosedError: Stream is closed

The above exception was the direct cause of the following exception:

Traceback (most recent call last):
  File "/sps/lsst/users/boutigny/conda_envs/desc_2/lib/python3.8/site-packages/distributed/worker.py", line 1366, in get_data
    response = await comm.read(deserializers=serializers)
  File "/sps/lsst/users/boutigny/conda_envs/desc_2/lib/python3.8/site-packages/distributed/comm/tcp.py", line 206, in read
    convert_stream_closed_error(self, e)
  File "/sps/lsst/users/boutigny/conda_envs/desc_2/lib/python3.8/site-packages/distributed/comm/tcp.py", line 128, in convert_stream_closed_error
    raise CommClosedError("in %s: %s" % (obj, exc)) from exc
distributed.comm.core.CommClosedError: in <closed TCP>: Stream is closed
distributed.worker - ERROR - Worker stream died during communication: tcp://134.158.170.3:41869
Traceback (most recent call last):
  File "/sps/lsst/users/boutigny/conda_envs/desc_2/lib/python3.8/site-packages/distributed/comm/tcp.py", line 200, in read
    n = await stream.read_into(frames)
tornado.iostream.StreamClosedError: Stream is closed

The above exception was the direct cause of the following exception:

Traceback (most recent call last):
  File "/sps/lsst/users/boutigny/conda_envs/desc_2/lib/python3.8/site-packages/distributed/worker.py", line 2169, in gather_dep
    response = await get_data_from_worker(
  File "/sps/lsst/users/boutigny/conda_envs/desc_2/lib/python3.8/site-packages/distributed/worker.py", line 3442, in get_data_from_worker
    return await retry_operation(_get_data, operation="get_data_from_worker")
  File "/sps/lsst/users/boutigny/conda_envs/desc_2/lib/python3.8/site-packages/distributed/utils_comm.py", line 385, in retry_operation
    return await retry(
  File "/sps/lsst/users/boutigny/conda_envs/desc_2/lib/python3.8/site-packages/distributed/utils_comm.py", line 370, in retry
    return await coro()
  File "/sps/lsst/users/boutigny/conda_envs/desc_2/lib/python3.8/site-packages/distributed/worker.py", line 3422, in _get_data
    response = await send_recv(
  File "/sps/lsst/users/boutigny/conda_envs/desc_2/lib/python3.8/site-packages/distributed/core.py", line 645, in send_recv
    response = await comm.read(deserializers=deserializers)
  File "/sps/lsst/users/boutigny/conda_envs/desc_2/lib/python3.8/site-packages/distributed/comm/tcp.py", line 206, in read
    convert_stream_closed_error(self, e)
  File "/sps/lsst/users/boutigny/conda_envs/desc_2/lib/python3.8/site-packages/distributed/comm/tcp.py", line 128, in convert_stream_closed_error
    raise CommClosedError("in %s: %s" % (obj, exc)) from exc
distributed.comm.core.CommClosedError: in <closed TCP>: Stream is closed
distributed.core - INFO - Event loop was unresponsive in Worker for 5.06s.  This is often caused by long-running GIL-holding functions or moving large chunks of data. This can cause timeouts and instability.
distributed.core - INFO - Lost connection to 'tcp://134.158.168.170:52722': in <closed TCP>: Stream is closed
distributed.core - INFO - Event loop was unresponsive in Worker for 5.33s.  This is often caused by long-running GIL-holding functions or moving large chunks of data. This can cause timeouts and instability.
distributed.utils_perf - INFO - full garbage collection released 42.09 MiB from 27 reference cycles (threshold: 9.54 MiB)
distributed.worker - WARNING - Worker is at 81% memory usage. Pausing worker.  Process memory: 3.79 GiB -- Worker memory limit: 4.66 GiB
distributed.nanny - WARNING - Worker exceeded 95% memory budget. Restarting
distributed.nanny - WARNING - Worker exceeded 95% memory budget. Restarting
distributed.nanny - WARNING - Worker exceeded 95% memory budget. Restarting
distributed.nanny - WARNING - Worker exceeded 95% memory budget. Restarting
distributed.nanny - WARNING - Worker exceeded 95% memory budget. Restarting
distributed.nanny - WARNING - Worker exceeded 95% memory budget. Restarting
distributed.nanny - WARNING - Worker exceeded 95% memory budget. Restarting
distributed.nanny - WARNING - Worker exceeded 95% memory budget. Restarting
distributed.nanny - WARNING - Worker exceeded 95% memory budget. Restarting
distributed.nanny - WARNING - Worker exceeded 95% memory budget. Restarting
distributed.nanny - WARNING - Worker exceeded 95% memory budget. Restarting
distributed.nanny - INFO - Worker process 31815 was killed by signal 15
distributed.nanny - WARNING - Restarting worker
distributed.diskutils - INFO - Found stale lock file and directory '/pbs/throng/lsst/users/boutigny/LSST_notebooks/Dask/dask-worker-space/worker-m0acln97', purging
distributed.diskutils - ERROR - Failed to remove '/pbs/throng/lsst/users/boutigny/LSST_notebooks/Dask/dask-worker-space/worker-m0acln97' (failed in <built-in function open>): [Errno 2] No such file or directory: '/pbs/throng/lsst/users/boutigny/LSST_notebooks/Dask/dask-worker-space/worker-m0acln97'
distributed.diskutils - INFO - Found stale lock file and directory '/pbs/throng/lsst/users/boutigny/LSST_notebooks/Dask/dask-worker-space/worker-8sj8viln', purging
/sps/lsst/users/boutigny/conda_envs/desc_2/lib/python3.8/contextlib.py:120: UserWarning: Creating scratch directories is taking a surprisingly long time. This is often due to running workers on a network file system. Consider specifying a local-directory to point workers to write scratch data to a local disk.
  next(self.gen)
distributed.worker - INFO -       Start worker at: tcp://134.158.168.220:45091
distributed.worker - INFO -          Listening to: tcp://134.158.168.220:45091
distributed.worker - INFO -          dashboard at:      134.158.168.220:41353
distributed.worker - INFO - Waiting to connect to:  tcp://134.158.48.24:42415
distributed.worker - INFO - -------------------------------------------------
distributed.worker - INFO -               Threads:                          1
distributed.worker - INFO -                Memory:                   4.66 GiB
distributed.worker - INFO -       Local Directory: /pbs/throng/lsst/users/boutigny/LSST_notebooks/Dask/dask-worker-space/worker-860soiqz
distributed.worker - INFO - -------------------------------------------------
distributed.worker - INFO -         Registered to:  tcp://134.158.48.24:42415
distributed.worker - INFO - -------------------------------------------------
distributed.core - INFO - Starting established connection
distributed.worker - ERROR - Worker stream died during communication: tcp://134.158.168.63:44844
Traceback (most recent call last):
  File "/sps/lsst/users/boutigny/conda_envs/desc_2/lib/python3.8/site-packages/distributed/comm/tcp.py", line 196, in read
    frames_nbytes = await stream.read_bytes(fmt_size)
tornado.iostream.StreamClosedError: Stream is closed

The above exception was the direct cause of the following exception:

Traceback (most recent call last):
  File "/sps/lsst/users/boutigny/conda_envs/desc_2/lib/python3.8/site-packages/distributed/worker.py", line 2169, in gather_dep
    response = await get_data_from_worker(
  File "/sps/lsst/users/boutigny/conda_envs/desc_2/lib/python3.8/site-packages/distributed/worker.py", line 3442, in get_data_from_worker
    return await retry_operation(_get_data, operation="get_data_from_worker")
  File "/sps/lsst/users/boutigny/conda_envs/desc_2/lib/python3.8/site-packages/distributed/utils_comm.py", line 385, in retry_operation
    return await retry(
  File "/sps/lsst/users/boutigny/conda_envs/desc_2/lib/python3.8/site-packages/distributed/utils_comm.py", line 370, in retry
    return await coro()
  File "/sps/lsst/users/boutigny/conda_envs/desc_2/lib/python3.8/site-packages/distributed/worker.py", line 3422, in _get_data
    response = await send_recv(
  File "/sps/lsst/users/boutigny/conda_envs/desc_2/lib/python3.8/site-packages/distributed/core.py", line 645, in send_recv
    response = await comm.read(deserializers=deserializers)
  File "/sps/lsst/users/boutigny/conda_envs/desc_2/lib/python3.8/site-packages/distributed/comm/tcp.py", line 206, in read
    convert_stream_closed_error(self, e)
  File "/sps/lsst/users/boutigny/conda_envs/desc_2/lib/python3.8/site-packages/distributed/comm/tcp.py", line 128, in convert_stream_closed_error
    raise CommClosedError("in %s: %s" % (obj, exc)) from exc
distributed.comm.core.CommClosedError: in <closed TCP>: Stream is closed
distributed.worker - INFO - Can't find dependencies for key ('fix-overlap-and_-a2c92d0a7b4404ef4989bfc49cea49a2', 129)
distributed.worker - INFO - Dependent not found: ('set_index-de5055cf7981b50e2b876d80000d7d25', 128) 0 .  Asking scheduler
distributed.worker - ERROR - Worker stream died during communication: tcp://134.158.170.53:33709
Traceback (most recent call last):
  File "/sps/lsst/users/boutigny/conda_envs/desc_2/lib/python3.8/site-packages/distributed/comm/tcp.py", line 196, in read
    frames_nbytes = await stream.read_bytes(fmt_size)
tornado.iostream.StreamClosedError: Stream is closed

The above exception was the direct cause of the following exception:

Traceback (most recent call last):
  File "/sps/lsst/users/boutigny/conda_envs/desc_2/lib/python3.8/site-packages/distributed/worker.py", line 2169, in gather_dep
    response = await get_data_from_worker(
  File "/sps/lsst/users/boutigny/conda_envs/desc_2/lib/python3.8/site-packages/distributed/worker.py", line 3442, in get_data_from_worker
    return await retry_operation(_get_data, operation="get_data_from_worker")
  File "/sps/lsst/users/boutigny/conda_envs/desc_2/lib/python3.8/site-packages/distributed/utils_comm.py", line 385, in retry_operation
    return await retry(
  File "/sps/lsst/users/boutigny/conda_envs/desc_2/lib/python3.8/site-packages/distributed/utils_comm.py", line 370, in retry
    return await coro()
  File "/sps/lsst/users/boutigny/conda_envs/desc_2/lib/python3.8/site-packages/distributed/worker.py", line 3422, in _get_data
    response = await send_recv(
  File "/sps/lsst/users/boutigny/conda_envs/desc_2/lib/python3.8/site-packages/distributed/core.py", line 645, in send_recv
    response = await comm.read(deserializers=deserializers)
  File "/sps/lsst/users/boutigny/conda_envs/desc_2/lib/python3.8/site-packages/distributed/comm/tcp.py", line 206, in read
    convert_stream_closed_error(self, e)
  File "/sps/lsst/users/boutigny/conda_envs/desc_2/lib/python3.8/site-packages/distributed/comm/tcp.py", line 128, in convert_stream_closed_error
    raise CommClosedError("in %s: %s" % (obj, exc)) from exc
distributed.comm.core.CommClosedError: in <closed TCP>: Stream is closed
distributed.utils_perf - INFO - full garbage collection released 343.37 MiB from 21 reference cycles (threshold: 9.54 MiB)
distributed.worker - WARNING - Worker is at 89% memory usage. Pausing worker.  Process memory: 4.17 GiB -- Worker memory limit: 4.66 GiB
distributed.worker - WARNING - Worker is at 54% memory usage. Resuming worker. Process memory: 2.56 GiB -- Worker memory limit: 4.66 GiB
distributed.core - INFO - Event loop was unresponsive in Worker for 7.36s.  This is often caused by long-running GIL-holding functions or moving large chunks of data. This can cause timeouts and instability.
distributed.worker - ERROR - Worker stream died during communication: tcp://134.158.168.198:40954
Traceback (most recent call last):
  File "/sps/lsst/users/boutigny/conda_envs/desc_2/lib/python3.8/site-packages/tornado/iostream.py", line 867, in _read_to_buffer
    bytes_read = self.read_from_fd(buf)
  File "/sps/lsst/users/boutigny/conda_envs/desc_2/lib/python3.8/site-packages/tornado/iostream.py", line 1140, in read_from_fd
    return self.socket.recv_into(buf, len(buf))
ConnectionResetError: [Errno 104] Connection reset by peer

The above exception was the direct cause of the following exception:

Traceback (most recent call last):
  File "/sps/lsst/users/boutigny/conda_envs/desc_2/lib/python3.8/site-packages/distributed/comm/core.py", line 318, in connect
    handshake = await asyncio.wait_for(comm.read(), time_left())
  File "/sps/lsst/users/boutigny/conda_envs/desc_2/lib/python3.8/asyncio/tasks.py", line 494, in wait_for
    return fut.result()
  File "/sps/lsst/users/boutigny/conda_envs/desc_2/lib/python3.8/site-packages/distributed/comm/tcp.py", line 206, in read
    convert_stream_closed_error(self, e)
  File "/sps/lsst/users/boutigny/conda_envs/desc_2/lib/python3.8/site-packages/distributed/comm/tcp.py", line 124, in convert_stream_closed_error
    raise CommClosedError(
distributed.comm.core.CommClosedError: in <closed TCP>: ConnectionResetError: [Errno 104] Connection reset by peer

The above exception was the direct cause of the following exception:

Traceback (most recent call last):
  File "/sps/lsst/users/boutigny/conda_envs/desc_2/lib/python3.8/site-packages/distributed/worker.py", line 2169, in gather_dep
    response = await get_data_from_worker(
  File "/sps/lsst/users/boutigny/conda_envs/desc_2/lib/python3.8/site-packages/distributed/worker.py", line 3442, in get_data_from_worker
    return await retry_operation(_get_data, operation="get_data_from_worker")
  File "/sps/lsst/users/boutigny/conda_envs/desc_2/lib/python3.8/site-packages/distributed/utils_comm.py", line 385, in retry_operation
    return await retry(
  File "/sps/lsst/users/boutigny/conda_envs/desc_2/lib/python3.8/site-packages/distributed/utils_comm.py", line 370, in retry
    return await coro()
  File "/sps/lsst/users/boutigny/conda_envs/desc_2/lib/python3.8/site-packages/distributed/worker.py", line 3419, in _get_data
    comm = await rpc.connect(worker)
  File "/sps/lsst/users/boutigny/conda_envs/desc_2/lib/python3.8/site-packages/distributed/core.py", line 1010, in connect
    comm = await connect(
  File "/sps/lsst/users/boutigny/conda_envs/desc_2/lib/python3.8/site-packages/distributed/comm/core.py", line 323, in connect
    raise IOError(
OSError: Timed out during handshake while connecting to tcp://134.158.168.198:40954 after 10 s
distributed.worker - INFO - Can't find dependencies for key ('fix-overlap-and_-a2c92d0a7b4404ef4989bfc49cea49a2', 205)
distributed.worker - INFO - Dependent not found: ('set_index-de5055cf7981b50e2b876d80000d7d25', 204) 0 .  Asking scheduler
distributed.core - INFO - Event loop was unresponsive in Worker for 14.41s.  This is often caused by long-running GIL-holding functions or moving large chunks of data. This can cause timeouts and instability.
distributed.utils_perf - INFO - full garbage collection released 547.96 MiB from 54 reference cycles (threshold: 9.54 MiB)
distributed.worker - ERROR - Worker stream died during communication: tcp://134.158.170.3:42017
Traceback (most recent call last):
  File "/sps/lsst/users/boutigny/conda_envs/desc_2/lib/python3.8/site-packages/distributed/comm/tcp.py", line 200, in read
    n = await stream.read_into(frames)
tornado.iostream.StreamClosedError: Stream is closed

The above exception was the direct cause of the following exception:

Traceback (most recent call last):
  File "/sps/lsst/users/boutigny/conda_envs/desc_2/lib/python3.8/site-packages/distributed/worker.py", line 2169, in gather_dep
    response = await get_data_from_worker(
  File "/sps/lsst/users/boutigny/conda_envs/desc_2/lib/python3.8/site-packages/distributed/worker.py", line 3442, in get_data_from_worker
    return await retry_operation(_get_data, operation="get_data_from_worker")
  File "/sps/lsst/users/boutigny/conda_envs/desc_2/lib/python3.8/site-packages/distributed/utils_comm.py", line 385, in retry_operation
    return await retry(
  File "/sps/lsst/users/boutigny/conda_envs/desc_2/lib/python3.8/site-packages/distributed/utils_comm.py", line 370, in retry
    return await coro()
  File "/sps/lsst/users/boutigny/conda_envs/desc_2/lib/python3.8/site-packages/distributed/worker.py", line 3422, in _get_data
    response = await send_recv(
  File "/sps/lsst/users/boutigny/conda_envs/desc_2/lib/python3.8/site-packages/distributed/core.py", line 645, in send_recv
    response = await comm.read(deserializers=deserializers)
  File "/sps/lsst/users/boutigny/conda_envs/desc_2/lib/python3.8/site-packages/distributed/comm/tcp.py", line 206, in read
    convert_stream_closed_error(self, e)
  File "/sps/lsst/users/boutigny/conda_envs/desc_2/lib/python3.8/site-packages/distributed/comm/tcp.py", line 128, in convert_stream_closed_error
    raise CommClosedError("in %s: %s" % (obj, exc)) from exc
distributed.comm.core.CommClosedError: in <closed TCP>: Stream is closed
distributed.core - INFO - Event loop was unresponsive in Worker for 3.81s.  This is often caused by long-running GIL-holding functions or moving large chunks of data. This can cause timeouts and instability.
distributed.worker - ERROR - Worker stream died during communication: tcp://134.158.170.23:41572
Traceback (most recent call last):
  File "/sps/lsst/users/boutigny/conda_envs/desc_2/lib/python3.8/site-packages/distributed/comm/tcp.py", line 200, in read
    n = await stream.read_into(frames)
tornado.iostream.StreamClosedError: Stream is closed

The above exception was the direct cause of the following exception:

Traceback (most recent call last):
  File "/sps/lsst/users/boutigny/conda_envs/desc_2/lib/python3.8/site-packages/distributed/worker.py", line 2169, in gather_dep
    response = await get_data_from_worker(
  File "/sps/lsst/users/boutigny/conda_envs/desc_2/lib/python3.8/site-packages/distributed/worker.py", line 3442, in get_data_from_worker
    return await retry_operation(_get_data, operation="get_data_from_worker")
  File "/sps/lsst/users/boutigny/conda_envs/desc_2/lib/python3.8/site-packages/distributed/utils_comm.py", line 385, in retry_operation
    return await retry(
  File "/sps/lsst/users/boutigny/conda_envs/desc_2/lib/python3.8/site-packages/distributed/utils_comm.py", line 370, in retry
    return await coro()
  File "/sps/lsst/users/boutigny/conda_envs/desc_2/lib/python3.8/site-packages/distributed/worker.py", line 3422, in _get_data
    response = await send_recv(
  File "/sps/lsst/users/boutigny/conda_envs/desc_2/lib/python3.8/site-packages/distributed/core.py", line 645, in send_recv
    response = await comm.read(deserializers=deserializers)
  File "/sps/lsst/users/boutigny/conda_envs/desc_2/lib/python3.8/site-packages/distributed/comm/tcp.py", line 206, in read
    convert_stream_closed_error(self, e)
  File "/sps/lsst/users/boutigny/conda_envs/desc_2/lib/python3.8/site-packages/distributed/comm/tcp.py", line 128, in convert_stream_closed_error
    raise CommClosedError("in %s: %s" % (obj, exc)) from exc
distributed.comm.core.CommClosedError: in <closed TCP>: Stream is closed
distributed.worker - ERROR - Worker stream died during communication: tcp://134.158.168.64:37041
ConnectionRefusedError: [Errno 111] Connection refused

The above exception was the direct cause of the following exception:

Traceback (most recent call last):
  File "/sps/lsst/users/boutigny/conda_envs/desc_2/lib/python3.8/site-packages/distributed/comm/core.py", line 285, in connect
    comm = await asyncio.wait_for(
  File "/sps/lsst/users/boutigny/conda_envs/desc_2/lib/python3.8/asyncio/tasks.py", line 494, in wait_for
    return fut.result()
  File "/sps/lsst/users/boutigny/conda_envs/desc_2/lib/python3.8/site-packages/distributed/comm/tcp.py", line 391, in connect
    convert_stream_closed_error(self, e)
  File "/sps/lsst/users/boutigny/conda_envs/desc_2/lib/python3.8/site-packages/distributed/comm/tcp.py", line 124, in convert_stream_closed_error
    raise CommClosedError(
distributed.comm.core.CommClosedError: in <distributed.comm.tcp.TCPConnector object at 0x2b86f7802220>: ConnectionRefusedError: [Errno 111] Connection refused

The above exception was the direct cause of the following exception:

Traceback (most recent call last):
  File "/sps/lsst/users/boutigny/conda_envs/desc_2/lib/python3.8/site-packages/distributed/worker.py", line 2169, in gather_dep
    response = await get_data_from_worker(
  File "/sps/lsst/users/boutigny/conda_envs/desc_2/lib/python3.8/site-packages/distributed/worker.py", line 3442, in get_data_from_worker
    return await retry_operation(_get_data, operation="get_data_from_worker")
  File "/sps/lsst/users/boutigny/conda_envs/desc_2/lib/python3.8/site-packages/distributed/utils_comm.py", line 385, in retry_operation
    return await retry(
  File "/sps/lsst/users/boutigny/conda_envs/desc_2/lib/python3.8/site-packages/distributed/utils_comm.py", line 370, in retry
    return await coro()
  File "/sps/lsst/users/boutigny/conda_envs/desc_2/lib/python3.8/site-packages/distributed/worker.py", line 3419, in _get_data
    comm = await rpc.connect(worker)
  File "/sps/lsst/users/boutigny/conda_envs/desc_2/lib/python3.8/site-packages/distributed/core.py", line 1010, in connect
    comm = await connect(
  File "/sps/lsst/users/boutigny/conda_envs/desc_2/lib/python3.8/site-packages/distributed/comm/core.py", line 307, in connect
    raise IOError(
OSError: Timed out trying to connect to tcp://134.158.168.64:37041 after 10 s
distributed.core - INFO - Event loop was unresponsive in Worker for 11.76s.  This is often caused by long-running GIL-holding functions or moving large chunks of data. This can cause timeouts and instability.
distributed.worker - ERROR - Worker stream died during communication: tcp://134.158.170.28:41804
Traceback (most recent call last):
  File "/sps/lsst/users/boutigny/conda_envs/desc_2/lib/python3.8/site-packages/distributed/comm/tcp.py", line 200, in read
    n = await stream.read_into(frames)
tornado.iostream.StreamClosedError: Stream is closed

The above exception was the direct cause of the following exception:

Traceback (most recent call last):
  File "/sps/lsst/users/boutigny/conda_envs/desc_2/lib/python3.8/site-packages/distributed/worker.py", line 2169, in gather_dep
    response = await get_data_from_worker(
  File "/sps/lsst/users/boutigny/conda_envs/desc_2/lib/python3.8/site-packages/distributed/worker.py", line 3442, in get_data_from_worker
    return await retry_operation(_get_data, operation="get_data_from_worker")
  File "/sps/lsst/users/boutigny/conda_envs/desc_2/lib/python3.8/site-packages/distributed/utils_comm.py", line 385, in retry_operation
    return await retry(
  File "/sps/lsst/users/boutigny/conda_envs/desc_2/lib/python3.8/site-packages/distributed/utils_comm.py", line 370, in retry
    return await coro()
  File "/sps/lsst/users/boutigny/conda_envs/desc_2/lib/python3.8/site-packages/distributed/worker.py", line 3422, in _get_data
    response = await send_recv(
  File "/sps/lsst/users/boutigny/conda_envs/desc_2/lib/python3.8/site-packages/distributed/core.py", line 645, in send_recv
    response = await comm.read(deserializers=deserializers)
  File "/sps/lsst/users/boutigny/conda_envs/desc_2/lib/python3.8/site-packages/distributed/comm/tcp.py", line 206, in read
    convert_stream_closed_error(self, e)
  File "/sps/lsst/users/boutigny/conda_envs/desc_2/lib/python3.8/site-packages/distributed/comm/tcp.py", line 128, in convert_stream_closed_error
    raise CommClosedError("in %s: %s" % (obj, exc)) from exc
distributed.comm.core.CommClosedError: in <closed TCP>: Stream is closed
distributed.worker - INFO - Can't find dependencies for key ('fix-overlap-and_-a2c92d0a7b4404ef4989bfc49cea49a2', 107)
distributed.nanny - WARNING - Worker exceeded 95% memory budget. Restarting
distributed.nanny - WARNING - Worker exceeded 95% memory budget. Restarting
distributed.nanny - WARNING - Worker exceeded 95% memory budget. Restarting
distributed.nanny - WARNING - Worker exceeded 95% memory budget. Restarting
distributed.nanny - WARNING - Worker exceeded 95% memory budget. Restarting
distributed.nanny - WARNING - Worker exceeded 95% memory budget. Restarting
distributed.nanny - WARNING - Worker exceeded 95% memory budget. Restarting
distributed.nanny - WARNING - Worker exceeded 95% memory budget. Restarting
distributed.nanny - WARNING - Worker exceeded 95% memory budget. Restarting
distributed.nanny - WARNING - Worker exceeded 95% memory budget. Restarting
distributed.nanny - WARNING - Worker exceeded 95% memory budget. Restarting
distributed.nanny - WARNING - Worker exceeded 95% memory budget. Restarting
distributed.nanny - WARNING - Worker exceeded 95% memory budget. Restarting
distributed.nanny - WARNING - Worker exceeded 95% memory budget. Restarting
distributed.nanny - WARNING - Worker exceeded 95% memory budget. Restarting
distributed.nanny - WARNING - Worker exceeded 95% memory budget. Restarting
distributed.nanny - WARNING - Worker exceeded 95% memory budget. Restarting
distributed.nanny - WARNING - Worker exceeded 95% memory budget. Restarting
distributed.nanny - WARNING - Worker exceeded 95% memory budget. Restarting
distributed.nanny - WARNING - Worker exceeded 95% memory budget. Restarting
distributed.nanny - WARNING - Worker exceeded 95% memory budget. Restarting
distributed.nanny - WARNING - Worker exceeded 95% memory budget. Restarting
distributed.nanny - WARNING - Worker exceeded 95% memory budget. Restarting
distributed.nanny - WARNING - Worker exceeded 95% memory budget. Restarting
distributed.nanny - WARNING - Worker exceeded 95% memory budget. Restarting
distributed.nanny - WARNING - Worker exceeded 95% memory budget. Restarting
distributed.nanny - WARNING - Worker exceeded 95% memory budget. Restarting
distributed.nanny - WARNING - Worker exceeded 95% memory budget. Restarting
distributed.nanny - WARNING - Worker exceeded 95% memory budget. Restarting
distributed.nanny - WARNING - Worker exceeded 95% memory budget. Restarting
distributed.nanny - WARNING - Worker exceeded 95% memory budget. Restarting
distributed.nanny - WARNING - Worker exceeded 95% memory budget. Restarting
distributed.nanny - WARNING - Worker exceeded 95% memory budget. Restarting
distributed.nanny - WARNING - Worker exceeded 95% memory budget. Restarting
distributed.nanny - WARNING - Worker exceeded 95% memory budget. Restarting
distributed.nanny - WARNING - Worker exceeded 95% memory budget. Restarting
distributed.nanny - WARNING - Worker exceeded 95% memory budget. Restarting
distributed.nanny - WARNING - Worker exceeded 95% memory budget. Restarting
distributed.nanny - WARNING - Worker exceeded 95% memory budget. Restarting
distributed.nanny - WARNING - Worker exceeded 95% memory budget. Restarting
distributed.nanny - WARNING - Worker exceeded 95% memory budget. Restarting
distributed.nanny - WARNING - Worker exceeded 95% memory budget. Restarting
distributed.nanny - WARNING - Worker exceeded 95% memory budget. Restarting
distributed.nanny - WARNING - Worker exceeded 95% memory budget. Restarting
distributed.nanny - WARNING - Worker exceeded 95% memory budget. Restarting
distributed.nanny - WARNING - Worker exceeded 95% memory budget. Restarting
distributed.nanny - WARNING - Worker exceeded 95% memory budget. Restarting
distributed.nanny - WARNING - Worker exceeded 95% memory budget. Restarting
distributed.nanny - WARNING - Worker exceeded 95% memory budget. Restarting
distributed.nanny - WARNING - Worker exceeded 95% memory budget. Restarting
distributed.nanny - WARNING - Worker exceeded 95% memory budget. Restarting
distributed.nanny - WARNING - Worker exceeded 95% memory budget. Restarting
distributed.nanny - WARNING - Worker exceeded 95% memory budget. Restarting
distributed.nanny - WARNING - Worker exceeded 95% memory budget. Restarting
distributed.nanny - WARNING - Worker exceeded 95% memory budget. Restarting
distributed.nanny - WARNING - Worker exceeded 95% memory budget. Restarting
distributed.nanny - WARNING - Worker exceeded 95% memory budget. Restarting
distributed.nanny - WARNING - Worker exceeded 95% memory budget. Restarting
distributed.nanny - WARNING - Worker exceeded 95% memory budget. Restarting
distributed.nanny - WARNING - Worker exceeded 95% memory budget. Restarting
distributed.nanny - WARNING - Worker exceeded 95% memory budget. Restarting
distributed.nanny - WARNING - Worker exceeded 95% memory budget. Restarting
distributed.nanny - WARNING - Worker exceeded 95% memory budget. Restarting
distributed.nanny - WARNING - Worker exceeded 95% memory budget. Restarting
distributed.nanny - WARNING - Worker exceeded 95% memory budget. Restarting
distributed.nanny - WARNING - Worker exceeded 95% memory budget. Restarting
distributed.nanny - WARNING - Worker exceeded 95% memory budget. Restarting
distributed.nanny - WARNING - Worker exceeded 95% memory budget. Restarting
distributed.nanny - WARNING - Worker exceeded 95% memory budget. Restarting
distributed.nanny - WARNING - Worker exceeded 95% memory budget. Restarting
distributed.nanny - WARNING - Worker exceeded 95% memory budget. Restarting
distributed.nanny - WARNING - Worker exceeded 95% memory budget. Restarting
distributed.nanny - WARNING - Worker exceeded 95% memory budget. Restarting
distributed.nanny - WARNING - Worker exceeded 95% memory budget. Restarting
distributed.nanny - WARNING - Worker exceeded 95% memory budget. Restarting
distributed.nanny - WARNING - Worker exceeded 95% memory budget. Restarting
distributed.nanny - WARNING - Worker exceeded 95% memory budget. Restarting
distributed.nanny - WARNING - Worker exceeded 95% memory budget. Restarting
distributed.nanny - WARNING - Worker exceeded 95% memory budget. Restarting
distributed.nanny - WARNING - Worker exceeded 95% memory budget. Restarting
distributed.nanny - WARNING - Worker exceeded 95% memory budget. Restarting
distributed.nanny - WARNING - Worker exceeded 95% memory budget. Restarting
distributed.nanny - INFO - Worker process 32414 was killed by signal 15
distributed.nanny - WARNING - Restarting worker
/sps/lsst/users/boutigny/conda_envs/desc_2/lib/python3.8/contextlib.py:120: UserWarning: Creating scratch directories is taking a surprisingly long time. This is often due to running workers on a network file system. Consider specifying a local-directory to point workers to write scratch data to a local disk.
  next(self.gen)
distributed.worker - INFO -       Start worker at: tcp://134.158.168.220:45165
distributed.worker - INFO -          Listening to: tcp://134.158.168.220:45165
distributed.worker - INFO -          dashboard at:      134.158.168.220:46114
distributed.worker - INFO - Waiting to connect to:  tcp://134.158.48.24:42415
distributed.worker - INFO - -------------------------------------------------
distributed.worker - INFO -               Threads:                          1
distributed.worker - INFO -                Memory:                   4.66 GiB
distributed.worker - INFO -       Local Directory: /pbs/throng/lsst/users/boutigny/LSST_notebooks/Dask/dask-worker-space/worker-6y1basw0
distributed.worker - INFO - -------------------------------------------------
distributed.worker - INFO -         Registered to:  tcp://134.158.48.24:42415
distributed.worker - INFO - -------------------------------------------------
distributed.core - INFO - Starting established connection
