**********************************************************************
*                     Grid Engine Batch System                       *
*              IN2P3 Computing Centre, Villeurbanne FR               *
**********************************************************************
* User:                           boutigny                           *
* Group:                          lsst                               *
* Jobname:                        dask-worker                        *
* JobID:                          15661206                           *
* Queue:                          mc_highmem                         *
* Worker:                         ccwsge0335.in2p3.fr                *
* Operating system:               Linux 3.10.0-1160.25.1.el7.x86_64  *
* Project:                        P_lsst                             *
**********************************************************************
* Submitted on:                   Tue Jul 20 19:45:35 CEST 2021      *
* Started on:                     Tue Jul 20 19:45:44 CEST 2021      *
**********************************************************************
coucou
distributed.nanny - INFO -         Start Nanny at: 'tcp://134.158.168.193:38876'
distributed.worker - INFO -       Start worker at: tcp://134.158.168.193:36363
distributed.worker - INFO -          Listening to: tcp://134.158.168.193:36363
distributed.worker - INFO -          dashboard at:      134.158.168.193:35964
distributed.worker - INFO - Waiting to connect to:  tcp://134.158.48.24:42415
distributed.worker - INFO - -------------------------------------------------
distributed.worker - INFO -               Threads:                          1
distributed.worker - INFO -                Memory:                   4.66 GiB
distributed.worker - INFO -       Local Directory: /pbs/throng/lsst/users/boutigny/LSST_notebooks/Dask/dask-worker-space/worker-e8gviw1r
distributed.worker - INFO - -------------------------------------------------
distributed.worker - INFO -         Registered to:  tcp://134.158.48.24:42415
distributed.worker - INFO - -------------------------------------------------
distributed.core - INFO - Starting established connection
distributed.worker - ERROR - failed during get data with tcp://134.158.168.193:36363 -> tcp://134.158.170.59:33549
Traceback (most recent call last):
  File "/sps/lsst/users/boutigny/conda_envs/desc_2/lib/python3.8/site-packages/tornado/iostream.py", line 867, in _read_to_buffer
    bytes_read = self.read_from_fd(buf)
  File "/sps/lsst/users/boutigny/conda_envs/desc_2/lib/python3.8/site-packages/tornado/iostream.py", line 1140, in read_from_fd
    return self.socket.recv_into(buf, len(buf))
ConnectionResetError: [Errno 104] Connection reset by peer

The above exception was the direct cause of the following exception:

Traceback (most recent call last):
  File "/sps/lsst/users/boutigny/conda_envs/desc_2/lib/python3.8/site-packages/distributed/worker.py", line 1366, in get_data
    response = await comm.read(deserializers=serializers)
  File "/sps/lsst/users/boutigny/conda_envs/desc_2/lib/python3.8/site-packages/distributed/comm/tcp.py", line 206, in read
    convert_stream_closed_error(self, e)
  File "/sps/lsst/users/boutigny/conda_envs/desc_2/lib/python3.8/site-packages/distributed/comm/tcp.py", line 124, in convert_stream_closed_error
    raise CommClosedError(
distributed.comm.core.CommClosedError: in <closed TCP>: ConnectionResetError: [Errno 104] Connection reset by peer
distributed.core - INFO - Lost connection to 'tcp://134.158.170.59:36310': in <closed TCP>: ConnectionResetError: [Errno 104] Connection reset by peer
distributed.core - INFO - Event loop was unresponsive in Worker for 6.80s.  This is often caused by long-running GIL-holding functions or moving large chunks of data. This can cause timeouts and instability.
distributed.core - INFO - Event loop was unresponsive in Worker for 15.09s.  This is often caused by long-running GIL-holding functions or moving large chunks of data. This can cause timeouts and instability.
distributed.comm.tcp - INFO - Connection closed before handshake completed
distributed.core - INFO - Event loop was unresponsive in Worker for 6.38s.  This is often caused by long-running GIL-holding functions or moving large chunks of data. This can cause timeouts and instability.
distributed.utils_perf - INFO - full garbage collection released 20.77 MiB from 127 reference cycles (threshold: 9.54 MiB)
distributed.core - INFO - Event loop was unresponsive in Worker for 15.50s.  This is often caused by long-running GIL-holding functions or moving large chunks of data. This can cause timeouts and instability.
distributed.worker - ERROR - Worker stream died during communication: tcp://134.158.168.236:45221
Traceback (most recent call last):
  File "/sps/lsst/users/boutigny/conda_envs/desc_2/lib/python3.8/site-packages/tornado/iostream.py", line 867, in _read_to_buffer
    bytes_read = self.read_from_fd(buf)
  File "/sps/lsst/users/boutigny/conda_envs/desc_2/lib/python3.8/site-packages/tornado/iostream.py", line 1140, in read_from_fd
    return self.socket.recv_into(buf, len(buf))
ConnectionResetError: [Errno 104] Connection reset by peer

The above exception was the direct cause of the following exception:

Traceback (most recent call last):
  File "/sps/lsst/users/boutigny/conda_envs/desc_2/lib/python3.8/site-packages/distributed/comm/core.py", line 318, in connect
    handshake = await asyncio.wait_for(comm.read(), time_left())
  File "/sps/lsst/users/boutigny/conda_envs/desc_2/lib/python3.8/asyncio/tasks.py", line 494, in wait_for
    return fut.result()
  File "/sps/lsst/users/boutigny/conda_envs/desc_2/lib/python3.8/site-packages/distributed/comm/tcp.py", line 206, in read
    convert_stream_closed_error(self, e)
  File "/sps/lsst/users/boutigny/conda_envs/desc_2/lib/python3.8/site-packages/distributed/comm/tcp.py", line 124, in convert_stream_closed_error
    raise CommClosedError(
distributed.comm.core.CommClosedError: in <closed TCP>: ConnectionResetError: [Errno 104] Connection reset by peer

The above exception was the direct cause of the following exception:

Traceback (most recent call last):
  File "/sps/lsst/users/boutigny/conda_envs/desc_2/lib/python3.8/site-packages/distributed/worker.py", line 2169, in gather_dep
    response = await get_data_from_worker(
  File "/sps/lsst/users/boutigny/conda_envs/desc_2/lib/python3.8/site-packages/distributed/worker.py", line 3442, in get_data_from_worker
    return await retry_operation(_get_data, operation="get_data_from_worker")
  File "/sps/lsst/users/boutigny/conda_envs/desc_2/lib/python3.8/site-packages/distributed/utils_comm.py", line 385, in retry_operation
    return await retry(
  File "/sps/lsst/users/boutigny/conda_envs/desc_2/lib/python3.8/site-packages/distributed/utils_comm.py", line 370, in retry
    return await coro()
  File "/sps/lsst/users/boutigny/conda_envs/desc_2/lib/python3.8/site-packages/distributed/worker.py", line 3419, in _get_data
    comm = await rpc.connect(worker)
  File "/sps/lsst/users/boutigny/conda_envs/desc_2/lib/python3.8/site-packages/distributed/core.py", line 1010, in connect
    comm = await connect(
  File "/sps/lsst/users/boutigny/conda_envs/desc_2/lib/python3.8/site-packages/distributed/comm/core.py", line 323, in connect
    raise IOError(
OSError: Timed out during handshake while connecting to tcp://134.158.168.236:45221 after 10 s
distributed.comm.tcp - INFO - Connection closed before handshake completed
distributed.worker - ERROR - Worker stream died during communication: tcp://134.158.170.3:35647
Traceback (most recent call last):
  File "/sps/lsst/users/boutigny/conda_envs/desc_2/lib/python3.8/site-packages/tornado/iostream.py", line 867, in _read_to_buffer
    bytes_read = self.read_from_fd(buf)
  File "/sps/lsst/users/boutigny/conda_envs/desc_2/lib/python3.8/site-packages/tornado/iostream.py", line 1140, in read_from_fd
    return self.socket.recv_into(buf, len(buf))
ConnectionResetError: [Errno 104] Connection reset by peer

The above exception was the direct cause of the following exception:

Traceback (most recent call last):
  File "/sps/lsst/users/boutigny/conda_envs/desc_2/lib/python3.8/site-packages/distributed/comm/core.py", line 318, in connect
    handshake = await asyncio.wait_for(comm.read(), time_left())
  File "/sps/lsst/users/boutigny/conda_envs/desc_2/lib/python3.8/asyncio/tasks.py", line 494, in wait_for
    return fut.result()
  File "/sps/lsst/users/boutigny/conda_envs/desc_2/lib/python3.8/site-packages/distributed/comm/tcp.py", line 206, in read
    convert_stream_closed_error(self, e)
  File "/sps/lsst/users/boutigny/conda_envs/desc_2/lib/python3.8/site-packages/distributed/comm/tcp.py", line 124, in convert_stream_closed_error
    raise CommClosedError(
distributed.comm.core.CommClosedError: in <closed TCP>: ConnectionResetError: [Errno 104] Connection reset by peer

The above exception was the direct cause of the following exception:

Traceback (most recent call last):
  File "/sps/lsst/users/boutigny/conda_envs/desc_2/lib/python3.8/site-packages/distributed/worker.py", line 2169, in gather_dep
    response = await get_data_from_worker(
  File "/sps/lsst/users/boutigny/conda_envs/desc_2/lib/python3.8/site-packages/distributed/worker.py", line 3442, in get_data_from_worker
    return await retry_operation(_get_data, operation="get_data_from_worker")
  File "/sps/lsst/users/boutigny/conda_envs/desc_2/lib/python3.8/site-packages/distributed/utils_comm.py", line 385, in retry_operation
    return await retry(
  File "/sps/lsst/users/boutigny/conda_envs/desc_2/lib/python3.8/site-packages/distributed/utils_comm.py", line 370, in retry
    return await coro()
  File "/sps/lsst/users/boutigny/conda_envs/desc_2/lib/python3.8/site-packages/distributed/worker.py", line 3419, in _get_data
    comm = await rpc.connect(worker)
  File "/sps/lsst/users/boutigny/conda_envs/desc_2/lib/python3.8/site-packages/distributed/core.py", line 1010, in connect
    comm = await connect(
  File "/sps/lsst/users/boutigny/conda_envs/desc_2/lib/python3.8/site-packages/distributed/comm/core.py", line 323, in connect
    raise IOError(
OSError: Timed out during handshake while connecting to tcp://134.158.170.3:35647 after 10 s
distributed.worker - INFO - Can't find dependencies for key ('fix-overlap-and_-a2c92d0a7b4404ef4989bfc49cea49a2', 106)
distributed.worker - INFO - Dependent not found: ('set_index-de5055cf7981b50e2b876d80000d7d25', 105) 0 .  Asking scheduler
distributed.worker - ERROR - Worker stream died during communication: tcp://134.158.168.220:41843
Traceback (most recent call last):
  File "/sps/lsst/users/boutigny/conda_envs/desc_2/lib/python3.8/site-packages/tornado/iostream.py", line 867, in _read_to_buffer
    bytes_read = self.read_from_fd(buf)
  File "/sps/lsst/users/boutigny/conda_envs/desc_2/lib/python3.8/site-packages/tornado/iostream.py", line 1140, in read_from_fd
    return self.socket.recv_into(buf, len(buf))
ConnectionResetError: [Errno 104] Connection reset by peer

The above exception was the direct cause of the following exception:

Traceback (most recent call last):
  File "/sps/lsst/users/boutigny/conda_envs/desc_2/lib/python3.8/site-packages/distributed/comm/core.py", line 318, in connect
    handshake = await asyncio.wait_for(comm.read(), time_left())
  File "/sps/lsst/users/boutigny/conda_envs/desc_2/lib/python3.8/asyncio/tasks.py", line 494, in wait_for
    return fut.result()
  File "/sps/lsst/users/boutigny/conda_envs/desc_2/lib/python3.8/site-packages/distributed/comm/tcp.py", line 206, in read
    convert_stream_closed_error(self, e)
  File "/sps/lsst/users/boutigny/conda_envs/desc_2/lib/python3.8/site-packages/distributed/comm/tcp.py", line 124, in convert_stream_closed_error
    raise CommClosedError(
distributed.comm.core.CommClosedError: in <closed TCP>: ConnectionResetError: [Errno 104] Connection reset by peer

The above exception was the direct cause of the following exception:

Traceback (most recent call last):
  File "/sps/lsst/users/boutigny/conda_envs/desc_2/lib/python3.8/site-packages/distributed/worker.py", line 2169, in gather_dep
    response = await get_data_from_worker(
  File "/sps/lsst/users/boutigny/conda_envs/desc_2/lib/python3.8/site-packages/distributed/worker.py", line 3442, in get_data_from_worker
    return await retry_operation(_get_data, operation="get_data_from_worker")
  File "/sps/lsst/users/boutigny/conda_envs/desc_2/lib/python3.8/site-packages/distributed/utils_comm.py", line 385, in retry_operation
    return await retry(
  File "/sps/lsst/users/boutigny/conda_envs/desc_2/lib/python3.8/site-packages/distributed/utils_comm.py", line 370, in retry
    return await coro()
  File "/sps/lsst/users/boutigny/conda_envs/desc_2/lib/python3.8/site-packages/distributed/worker.py", line 3419, in _get_data
    comm = await rpc.connect(worker)
  File "/sps/lsst/users/boutigny/conda_envs/desc_2/lib/python3.8/site-packages/distributed/core.py", line 1010, in connect
    comm = await connect(
  File "/sps/lsst/users/boutigny/conda_envs/desc_2/lib/python3.8/site-packages/distributed/comm/core.py", line 323, in connect
    raise IOError(
OSError: Timed out during handshake while connecting to tcp://134.158.168.220:41843 after 10 s
distributed.worker - ERROR - Worker stream died during communication: tcp://134.158.168.214:38632
Traceback (most recent call last):
  File "/sps/lsst/users/boutigny/conda_envs/desc_2/lib/python3.8/site-packages/distributed/comm/tcp.py", line 196, in read
    frames_nbytes = await stream.read_bytes(fmt_size)
tornado.iostream.StreamClosedError: Stream is closed

The above exception was the direct cause of the following exception:

Traceback (most recent call last):
  File "/sps/lsst/users/boutigny/conda_envs/desc_2/lib/python3.8/site-packages/distributed/comm/core.py", line 318, in connect
    handshake = await asyncio.wait_for(comm.read(), time_left())
  File "/sps/lsst/users/boutigny/conda_envs/desc_2/lib/python3.8/asyncio/tasks.py", line 494, in wait_for
    return fut.result()
  File "/sps/lsst/users/boutigny/conda_envs/desc_2/lib/python3.8/site-packages/distributed/comm/tcp.py", line 206, in read
    convert_stream_closed_error(self, e)
  File "/sps/lsst/users/boutigny/conda_envs/desc_2/lib/python3.8/site-packages/distributed/comm/tcp.py", line 128, in convert_stream_closed_error
    raise CommClosedError("in %s: %s" % (obj, exc)) from exc
distributed.comm.core.CommClosedError: in <closed TCP>: Stream is closed

The above exception was the direct cause of the following exception:

Traceback (most recent call last):
  File "/sps/lsst/users/boutigny/conda_envs/desc_2/lib/python3.8/site-packages/distributed/worker.py", line 2169, in gather_dep
    response = await get_data_from_worker(
  File "/sps/lsst/users/boutigny/conda_envs/desc_2/lib/python3.8/site-packages/distributed/worker.py", line 3442, in get_data_from_worker
    return await retry_operation(_get_data, operation="get_data_from_worker")
  File "/sps/lsst/users/boutigny/conda_envs/desc_2/lib/python3.8/site-packages/distributed/utils_comm.py", line 385, in retry_operation
    return await retry(
  File "/sps/lsst/users/boutigny/conda_envs/desc_2/lib/python3.8/site-packages/distributed/utils_comm.py", line 370, in retry
    return await coro()
  File "/sps/lsst/users/boutigny/conda_envs/desc_2/lib/python3.8/site-packages/distributed/worker.py", line 3419, in _get_data
    comm = await rpc.connect(worker)
  File "/sps/lsst/users/boutigny/conda_envs/desc_2/lib/python3.8/site-packages/distributed/core.py", line 1010, in connect
    comm = await connect(
  File "/sps/lsst/users/boutigny/conda_envs/desc_2/lib/python3.8/site-packages/distributed/comm/core.py", line 323, in connect
    raise IOError(
OSError: Timed out during handshake while connecting to tcp://134.158.168.214:38632 after 10 s
distributed.worker - ERROR - Worker stream died during communication: tcp://134.158.168.237:44106
Traceback (most recent call last):
  File "/sps/lsst/users/boutigny/conda_envs/desc_2/lib/python3.8/site-packages/distributed/comm/core.py", line 318, in connect
    handshake = await asyncio.wait_for(comm.read(), time_left())
  File "/sps/lsst/users/boutigny/conda_envs/desc_2/lib/python3.8/asyncio/tasks.py", line 501, in wait_for
    raise exceptions.TimeoutError()
asyncio.exceptions.TimeoutError

The above exception was the direct cause of the following exception:

Traceback (most recent call last):
  File "/sps/lsst/users/boutigny/conda_envs/desc_2/lib/python3.8/site-packages/distributed/worker.py", line 2169, in gather_dep
    response = await get_data_from_worker(
  File "/sps/lsst/users/boutigny/conda_envs/desc_2/lib/python3.8/site-packages/distributed/worker.py", line 3442, in get_data_from_worker
    return await retry_operation(_get_data, operation="get_data_from_worker")
  File "/sps/lsst/users/boutigny/conda_envs/desc_2/lib/python3.8/site-packages/distributed/utils_comm.py", line 385, in retry_operation
    return await retry(
  File "/sps/lsst/users/boutigny/conda_envs/desc_2/lib/python3.8/site-packages/distributed/utils_comm.py", line 370, in retry
    return await coro()
  File "/sps/lsst/users/boutigny/conda_envs/desc_2/lib/python3.8/site-packages/distributed/worker.py", line 3419, in _get_data
    comm = await rpc.connect(worker)
  File "/sps/lsst/users/boutigny/conda_envs/desc_2/lib/python3.8/site-packages/distributed/core.py", line 1010, in connect
    comm = await connect(
  File "/sps/lsst/users/boutigny/conda_envs/desc_2/lib/python3.8/site-packages/distributed/comm/core.py", line 323, in connect
    raise IOError(
OSError: Timed out during handshake while connecting to tcp://134.158.168.237:44106 after 10 s
distributed.worker - ERROR - Worker stream died during communication: tcp://134.158.170.32:44838
Traceback (most recent call last):
  File "/sps/lsst/users/boutigny/conda_envs/desc_2/lib/python3.8/site-packages/distributed/comm/core.py", line 285, in connect
    comm = await asyncio.wait_for(
  File "/sps/lsst/users/boutigny/conda_envs/desc_2/lib/python3.8/asyncio/tasks.py", line 501, in wait_for
    raise exceptions.TimeoutError()
asyncio.exceptions.TimeoutError

The above exception was the direct cause of the following exception:

Traceback (most recent call last):
  File "/sps/lsst/users/boutigny/conda_envs/desc_2/lib/python3.8/site-packages/distributed/worker.py", line 2169, in gather_dep
    response = await get_data_from_worker(
  File "/sps/lsst/users/boutigny/conda_envs/desc_2/lib/python3.8/site-packages/distributed/worker.py", line 3442, in get_data_from_worker
    return await retry_operation(_get_data, operation="get_data_from_worker")
  File "/sps/lsst/users/boutigny/conda_envs/desc_2/lib/python3.8/site-packages/distributed/utils_comm.py", line 385, in retry_operation
    return await retry(
  File "/sps/lsst/users/boutigny/conda_envs/desc_2/lib/python3.8/site-packages/distributed/utils_comm.py", line 370, in retry
    return await coro()
  File "/sps/lsst/users/boutigny/conda_envs/desc_2/lib/python3.8/site-packages/distributed/worker.py", line 3419, in _get_data
    comm = await rpc.connect(worker)
  File "/sps/lsst/users/boutigny/conda_envs/desc_2/lib/python3.8/site-packages/distributed/core.py", line 1010, in connect
    comm = await connect(
  File "/sps/lsst/users/boutigny/conda_envs/desc_2/lib/python3.8/site-packages/distributed/comm/core.py", line 307, in connect
    raise IOError(
OSError: Timed out trying to connect to tcp://134.158.170.32:44838 after 10 s
distributed.worker - ERROR - Worker stream died during communication: tcp://134.158.168.195:37163
Traceback (most recent call last):
  File "/sps/lsst/users/boutigny/conda_envs/desc_2/lib/python3.8/site-packages/distributed/comm/core.py", line 285, in connect
    comm = await asyncio.wait_for(
  File "/sps/lsst/users/boutigny/conda_envs/desc_2/lib/python3.8/asyncio/tasks.py", line 501, in wait_for
    raise exceptions.TimeoutError()
asyncio.exceptions.TimeoutError

The above exception was the direct cause of the following exception:

Traceback (most recent call last):
  File "/sps/lsst/users/boutigny/conda_envs/desc_2/lib/python3.8/site-packages/distributed/worker.py", line 2169, in gather_dep
    response = await get_data_from_worker(
  File "/sps/lsst/users/boutigny/conda_envs/desc_2/lib/python3.8/site-packages/distributed/worker.py", line 3442, in get_data_from_worker
    return await retry_operation(_get_data, operation="get_data_from_worker")
  File "/sps/lsst/users/boutigny/conda_envs/desc_2/lib/python3.8/site-packages/distributed/utils_comm.py", line 385, in retry_operation
    return await retry(
  File "/sps/lsst/users/boutigny/conda_envs/desc_2/lib/python3.8/site-packages/distributed/utils_comm.py", line 370, in retry
    return await coro()
  File "/sps/lsst/users/boutigny/conda_envs/desc_2/lib/python3.8/site-packages/distributed/worker.py", line 3419, in _get_data
    comm = await rpc.connect(worker)
  File "/sps/lsst/users/boutigny/conda_envs/desc_2/lib/python3.8/site-packages/distributed/core.py", line 1010, in connect
    comm = await connect(
  File "/sps/lsst/users/boutigny/conda_envs/desc_2/lib/python3.8/site-packages/distributed/comm/core.py", line 307, in connect
    raise IOError(
OSError: Timed out trying to connect to tcp://134.158.168.195:37163 after 10 s
distributed.worker - ERROR - Worker stream died during communication: tcp://134.158.168.170:44053
Traceback (most recent call last):
  File "/sps/lsst/users/boutigny/conda_envs/desc_2/lib/python3.8/site-packages/distributed/comm/tcp.py", line 200, in read
    n = await stream.read_into(frames)
tornado.iostream.StreamClosedError: Stream is closed

The above exception was the direct cause of the following exception:

Traceback (most recent call last):
  File "/sps/lsst/users/boutigny/conda_envs/desc_2/lib/python3.8/site-packages/distributed/worker.py", line 2169, in gather_dep
    response = await get_data_from_worker(
  File "/sps/lsst/users/boutigny/conda_envs/desc_2/lib/python3.8/site-packages/distributed/worker.py", line 3442, in get_data_from_worker
    return await retry_operation(_get_data, operation="get_data_from_worker")
  File "/sps/lsst/users/boutigny/conda_envs/desc_2/lib/python3.8/site-packages/distributed/utils_comm.py", line 385, in retry_operation
    return await retry(
  File "/sps/lsst/users/boutigny/conda_envs/desc_2/lib/python3.8/site-packages/distributed/utils_comm.py", line 370, in retry
    return await coro()
  File "/sps/lsst/users/boutigny/conda_envs/desc_2/lib/python3.8/site-packages/distributed/worker.py", line 3422, in _get_data
    response = await send_recv(
  File "/sps/lsst/users/boutigny/conda_envs/desc_2/lib/python3.8/site-packages/distributed/core.py", line 645, in send_recv
    response = await comm.read(deserializers=deserializers)
  File "/sps/lsst/users/boutigny/conda_envs/desc_2/lib/python3.8/site-packages/distributed/comm/tcp.py", line 206, in read
    convert_stream_closed_error(self, e)
  File "/sps/lsst/users/boutigny/conda_envs/desc_2/lib/python3.8/site-packages/distributed/comm/tcp.py", line 128, in convert_stream_closed_error
    raise CommClosedError("in %s: %s" % (obj, exc)) from exc
distributed.comm.core.CommClosedError: in <closed TCP>: Stream is closed
distributed.core - INFO - Event loop was unresponsive in Worker for 6.87s.  This is often caused by long-running GIL-holding functions or moving large chunks of data. This can cause timeouts and instability.
distributed.core - INFO - Event loop was unresponsive in Worker for 12.60s.  This is often caused by long-running GIL-holding functions or moving large chunks of data. This can cause timeouts and instability.
distributed.comm.tcp - INFO - Connection closed before handshake completed
distributed.core - INFO - Event loop was unresponsive in Worker for 3.87s.  This is often caused by long-running GIL-holding functions or moving large chunks of data. This can cause timeouts and instability.
distributed.worker - WARNING - Memory use is high but worker has no data to store to disk.  Perhaps some other process is leaking memory?  Process memory: 3.44 GiB -- Worker memory limit: 4.66 GiB
distributed.worker - WARNING - Memory use is high but worker has no data to store to disk.  Perhaps some other process is leaking memory?  Process memory: 3.44 GiB -- Worker memory limit: 4.66 GiB
distributed.worker - WARNING - Memory use is high but worker has no data to store to disk.  Perhaps some other process is leaking memory?  Process memory: 3.44 GiB -- Worker memory limit: 4.66 GiB
distributed.worker - WARNING - Worker is at 84% memory usage. Pausing worker.  Process memory: 3.92 GiB -- Worker memory limit: 4.66 GiB
distributed.worker - WARNING - Memory use is high but worker has no data to store to disk.  Perhaps some other process is leaking memory?  Process memory: 3.92 GiB -- Worker memory limit: 4.66 GiB
distributed.worker - WARNING - Memory use is high but worker has no data to store to disk.  Perhaps some other process is leaking memory?  Process memory: 3.92 GiB -- Worker memory limit: 4.66 GiB
distributed.worker - WARNING - Memory use is high but worker has no data to store to disk.  Perhaps some other process is leaking memory?  Process memory: 3.90 GiB -- Worker memory limit: 4.66 GiB
distributed.worker - WARNING - Memory use is high but worker has no data to store to disk.  Perhaps some other process is leaking memory?  Process memory: 3.90 GiB -- Worker memory limit: 4.66 GiB
distributed.worker - WARNING - Memory use is high but worker has no data to store to disk.  Perhaps some other process is leaking memory?  Process memory: 3.90 GiB -- Worker memory limit: 4.66 GiB
distributed.worker - WARNING - Memory use is high but worker has no data to store to disk.  Perhaps some other process is leaking memory?  Process memory: 3.90 GiB -- Worker memory limit: 4.66 GiB
distributed.worker - WARNING - Memory use is high but worker has no data to store to disk.  Perhaps some other process is leaking memory?  Process memory: 3.90 GiB -- Worker memory limit: 4.66 GiB
distributed.worker - WARNING - Memory use is high but worker has no data to store to disk.  Perhaps some other process is leaking memory?  Process memory: 3.90 GiB -- Worker memory limit: 4.66 GiB
distributed.worker - WARNING - Memory use is high but worker has no data to store to disk.  Perhaps some other process is leaking memory?  Process memory: 3.90 GiB -- Worker memory limit: 4.66 GiB
distributed.worker - WARNING - Memory use is high but worker has no data to store to disk.  Perhaps some other process is leaking memory?  Process memory: 3.90 GiB -- Worker memory limit: 4.66 GiB
distributed.worker - WARNING - Memory use is high but worker has no data to store to disk.  Perhaps some other process is leaking memory?  Process memory: 3.90 GiB -- Worker memory limit: 4.66 GiB
distributed.worker - WARNING - Memory use is high but worker has no data to store to disk.  Perhaps some other process is leaking memory?  Process memory: 3.90 GiB -- Worker memory limit: 4.66 GiB
distributed.worker - WARNING - Memory use is high but worker has no data to store to disk.  Perhaps some other process is leaking memory?  Process memory: 3.95 GiB -- Worker memory limit: 4.66 GiB
distributed.worker - WARNING - Memory use is high but worker has no data to store to disk.  Perhaps some other process is leaking memory?  Process memory: 4.37 GiB -- Worker memory limit: 4.66 GiB
distributed.utils_perf - INFO - full garbage collection released 0.95 GiB from 0 reference cycles (threshold: 9.54 MiB)
distributed.core - INFO - Event loop was unresponsive in Worker for 6.08s.  This is often caused by long-running GIL-holding functions or moving large chunks of data. This can cause timeouts and instability.
distributed.worker - WARNING - Worker is at 73% memory usage. Resuming worker. Process memory: 3.42 GiB -- Worker memory limit: 4.66 GiB
distributed.worker - WARNING - Memory use is high but worker has no data to store to disk.  Perhaps some other process is leaking memory?  Process memory: 3.42 GiB -- Worker memory limit: 4.66 GiB
distributed.worker - WARNING - Memory use is high but worker has no data to store to disk.  Perhaps some other process is leaking memory?  Process memory: 3.42 GiB -- Worker memory limit: 4.66 GiB
distributed.worker - WARNING - Memory use is high but worker has no data to store to disk.  Perhaps some other process is leaking memory?  Process memory: 3.42 GiB -- Worker memory limit: 4.66 GiB
distributed.worker - WARNING - Memory use is high but worker has no data to store to disk.  Perhaps some other process is leaking memory?  Process memory: 3.42 GiB -- Worker memory limit: 4.66 GiB
distributed.worker - WARNING - Memory use is high but worker has no data to store to disk.  Perhaps some other process is leaking memory?  Process memory: 3.42 GiB -- Worker memory limit: 4.66 GiB
distributed.worker - WARNING - Memory use is high but worker has no data to store to disk.  Perhaps some other process is leaking memory?  Process memory: 3.42 GiB -- Worker memory limit: 4.66 GiB
distributed.worker - WARNING - Memory use is high but worker has no data to store to disk.  Perhaps some other process is leaking memory?  Process memory: 3.42 GiB -- Worker memory limit: 4.66 GiB
distributed.worker - WARNING - Memory use is high but worker has no data to store to disk.  Perhaps some other process is leaking memory?  Process memory: 3.42 GiB -- Worker memory limit: 4.66 GiB
distributed.worker - WARNING - Memory use is high but worker has no data to store to disk.  Perhaps some other process is leaking memory?  Process memory: 3.42 GiB -- Worker memory limit: 4.66 GiB
distributed.worker - WARNING - Memory use is high but worker has no data to store to disk.  Perhaps some other process is leaking memory?  Process memory: 3.42 GiB -- Worker memory limit: 4.66 GiB
distributed.worker - WARNING - Memory use is high but worker has no data to store to disk.  Perhaps some other process is leaking memory?  Process memory: 3.42 GiB -- Worker memory limit: 4.66 GiB
distributed.worker - WARNING - Worker is at 84% memory usage. Pausing worker.  Process memory: 3.95 GiB -- Worker memory limit: 4.66 GiB
distributed.worker - WARNING - Memory use is high but worker has no data to store to disk.  Perhaps some other process is leaking memory?  Process memory: 3.95 GiB -- Worker memory limit: 4.66 GiB
distributed.worker - ERROR - Worker stream died during communication: tcp://134.158.170.21:44434
Traceback (most recent call last):
  File "/sps/lsst/users/boutigny/conda_envs/desc_2/lib/python3.8/site-packages/distributed/comm/tcp.py", line 200, in read
    n = await stream.read_into(frames)
tornado.iostream.StreamClosedError: Stream is closed

The above exception was the direct cause of the following exception:

Traceback (most recent call last):
  File "/sps/lsst/users/boutigny/conda_envs/desc_2/lib/python3.8/site-packages/distributed/worker.py", line 2169, in gather_dep
    response = await get_data_from_worker(
  File "/sps/lsst/users/boutigny/conda_envs/desc_2/lib/python3.8/site-packages/distributed/worker.py", line 3442, in get_data_from_worker
    return await retry_operation(_get_data, operation="get_data_from_worker")
  File "/sps/lsst/users/boutigny/conda_envs/desc_2/lib/python3.8/site-packages/distributed/utils_comm.py", line 385, in retry_operation
    return await retry(
  File "/sps/lsst/users/boutigny/conda_envs/desc_2/lib/python3.8/site-packages/distributed/utils_comm.py", line 370, in retry
    return await coro()
  File "/sps/lsst/users/boutigny/conda_envs/desc_2/lib/python3.8/site-packages/distributed/worker.py", line 3422, in _get_data
    response = await send_recv(
  File "/sps/lsst/users/boutigny/conda_envs/desc_2/lib/python3.8/site-packages/distributed/core.py", line 645, in send_recv
    response = await comm.read(deserializers=deserializers)
  File "/sps/lsst/users/boutigny/conda_envs/desc_2/lib/python3.8/site-packages/distributed/comm/tcp.py", line 206, in read
    convert_stream_closed_error(self, e)
  File "/sps/lsst/users/boutigny/conda_envs/desc_2/lib/python3.8/site-packages/distributed/comm/tcp.py", line 128, in convert_stream_closed_error
    raise CommClosedError("in %s: %s" % (obj, exc)) from exc
distributed.comm.core.CommClosedError: in <closed TCP>: Stream is closed
distributed.core - INFO - Event loop was unresponsive in Worker for 5.95s.  This is often caused by long-running GIL-holding functions or moving large chunks of data. This can cause timeouts and instability.
distributed.worker - WARNING - Memory use is high but worker has no data to store to disk.  Perhaps some other process is leaking memory?  Process memory: 3.95 GiB -- Worker memory limit: 4.66 GiB
distributed.worker - WARNING - Memory use is high but worker has no data to store to disk.  Perhaps some other process is leaking memory?  Process memory: 3.95 GiB -- Worker memory limit: 4.66 GiB
distributed.worker - WARNING - Memory use is high but worker has no data to store to disk.  Perhaps some other process is leaking memory?  Process memory: 3.95 GiB -- Worker memory limit: 4.66 GiB
distributed.nanny - WARNING - Worker exceeded 95% memory budget. Restarting
distributed.nanny - INFO - Worker process 26787 was killed by signal 15
distributed.nanny - WARNING - Restarting worker
distributed.worker - INFO -       Start worker at: tcp://134.158.168.193:41888
distributed.worker - INFO -          Listening to: tcp://134.158.168.193:41888
distributed.worker - INFO -          dashboard at:      134.158.168.193:39741
distributed.worker - INFO - Waiting to connect to:  tcp://134.158.48.24:42415
distributed.worker - INFO - -------------------------------------------------
distributed.worker - INFO -               Threads:                          1
distributed.worker - INFO -                Memory:                   4.66 GiB
distributed.worker - INFO -       Local Directory: /pbs/throng/lsst/users/boutigny/LSST_notebooks/Dask/dask-worker-space/worker-u56gd9ql
distributed.worker - INFO - -------------------------------------------------
distributed.worker - INFO -         Registered to:  tcp://134.158.48.24:42415
distributed.worker - INFO - -------------------------------------------------
distributed.core - INFO - Starting established connection
distributed.worker - ERROR - Worker stream died during communication: tcp://134.158.170.27:33851
Traceback (most recent call last):
  File "/sps/lsst/users/boutigny/conda_envs/desc_2/lib/python3.8/site-packages/tornado/iostream.py", line 867, in _read_to_buffer
    bytes_read = self.read_from_fd(buf)
  File "/sps/lsst/users/boutigny/conda_envs/desc_2/lib/python3.8/site-packages/tornado/iostream.py", line 1140, in read_from_fd
    return self.socket.recv_into(buf, len(buf))
ConnectionResetError: [Errno 104] Connection reset by peer

The above exception was the direct cause of the following exception:

Traceback (most recent call last):
  File "/sps/lsst/users/boutigny/conda_envs/desc_2/lib/python3.8/site-packages/distributed/comm/core.py", line 318, in connect
    handshake = await asyncio.wait_for(comm.read(), time_left())
  File "/sps/lsst/users/boutigny/conda_envs/desc_2/lib/python3.8/asyncio/tasks.py", line 494, in wait_for
    return fut.result()
  File "/sps/lsst/users/boutigny/conda_envs/desc_2/lib/python3.8/site-packages/distributed/comm/tcp.py", line 206, in read
    convert_stream_closed_error(self, e)
  File "/sps/lsst/users/boutigny/conda_envs/desc_2/lib/python3.8/site-packages/distributed/comm/tcp.py", line 124, in convert_stream_closed_error
    raise CommClosedError(
distributed.comm.core.CommClosedError: in <closed TCP>: ConnectionResetError: [Errno 104] Connection reset by peer

The above exception was the direct cause of the following exception:

Traceback (most recent call last):
  File "/sps/lsst/users/boutigny/conda_envs/desc_2/lib/python3.8/site-packages/distributed/worker.py", line 2169, in gather_dep
    response = await get_data_from_worker(
  File "/sps/lsst/users/boutigny/conda_envs/desc_2/lib/python3.8/site-packages/distributed/worker.py", line 3442, in get_data_from_worker
    return await retry_operation(_get_data, operation="get_data_from_worker")
  File "/sps/lsst/users/boutigny/conda_envs/desc_2/lib/python3.8/site-packages/distributed/utils_comm.py", line 385, in retry_operation
    return await retry(
  File "/sps/lsst/users/boutigny/conda_envs/desc_2/lib/python3.8/site-packages/distributed/utils_comm.py", line 370, in retry
    return await coro()
  File "/sps/lsst/users/boutigny/conda_envs/desc_2/lib/python3.8/site-packages/distributed/worker.py", line 3419, in _get_data
    comm = await rpc.connect(worker)
  File "/sps/lsst/users/boutigny/conda_envs/desc_2/lib/python3.8/site-packages/distributed/core.py", line 1010, in connect
    comm = await connect(
  File "/sps/lsst/users/boutigny/conda_envs/desc_2/lib/python3.8/site-packages/distributed/comm/core.py", line 323, in connect
    raise IOError(
OSError: Timed out during handshake while connecting to tcp://134.158.170.27:33851 after 10 s
distributed.worker - INFO - Can't find dependencies for key ('fix-overlap-and_-a2c92d0a7b4404ef4989bfc49cea49a2', 38)
distributed.worker - INFO - Dependent not found: ('set_index-de5055cf7981b50e2b876d80000d7d25', 37) 0 .  Asking scheduler
distributed.worker - ERROR - Worker stream died during communication: tcp://134.158.168.190:36783
Traceback (most recent call last):
  File "/sps/lsst/users/boutigny/conda_envs/desc_2/lib/python3.8/site-packages/distributed/comm/tcp.py", line 200, in read
    n = await stream.read_into(frames)
tornado.iostream.StreamClosedError: Stream is closed

The above exception was the direct cause of the following exception:

Traceback (most recent call last):
  File "/sps/lsst/users/boutigny/conda_envs/desc_2/lib/python3.8/site-packages/distributed/worker.py", line 2169, in gather_dep
    response = await get_data_from_worker(
  File "/sps/lsst/users/boutigny/conda_envs/desc_2/lib/python3.8/site-packages/distributed/worker.py", line 3442, in get_data_from_worker
    return await retry_operation(_get_data, operation="get_data_from_worker")
  File "/sps/lsst/users/boutigny/conda_envs/desc_2/lib/python3.8/site-packages/distributed/utils_comm.py", line 385, in retry_operation
    return await retry(
  File "/sps/lsst/users/boutigny/conda_envs/desc_2/lib/python3.8/site-packages/distributed/utils_comm.py", line 370, in retry
    return await coro()
  File "/sps/lsst/users/boutigny/conda_envs/desc_2/lib/python3.8/site-packages/distributed/worker.py", line 3422, in _get_data
    response = await send_recv(
  File "/sps/lsst/users/boutigny/conda_envs/desc_2/lib/python3.8/site-packages/distributed/core.py", line 645, in send_recv
    response = await comm.read(deserializers=deserializers)
  File "/sps/lsst/users/boutigny/conda_envs/desc_2/lib/python3.8/site-packages/distributed/comm/tcp.py", line 206, in read
    convert_stream_closed_error(self, e)
  File "/sps/lsst/users/boutigny/conda_envs/desc_2/lib/python3.8/site-packages/distributed/comm/tcp.py", line 128, in convert_stream_closed_error
    raise CommClosedError("in %s: %s" % (obj, exc)) from exc
distributed.comm.core.CommClosedError: in <closed TCP>: Stream is closed
distributed.utils_perf - INFO - full garbage collection released 354.87 MiB from 0 reference cycles (threshold: 9.54 MiB)
distributed.worker - WARNING - Worker is at 90% memory usage. Pausing worker.  Process memory: 4.22 GiB -- Worker memory limit: 4.66 GiB
distributed.worker - WARNING - Worker is at 55% memory usage. Resuming worker. Process memory: 2.58 GiB -- Worker memory limit: 4.66 GiB
distributed.core - INFO - Event loop was unresponsive in Worker for 12.74s.  This is often caused by long-running GIL-holding functions or moving large chunks of data. This can cause timeouts and instability.
distributed.worker - ERROR - Worker stream died during communication: tcp://134.158.168.195:36940
Traceback (most recent call last):
  File "/sps/lsst/users/boutigny/conda_envs/desc_2/lib/python3.8/site-packages/distributed/comm/core.py", line 318, in connect
    handshake = await asyncio.wait_for(comm.read(), time_left())
  File "/sps/lsst/users/boutigny/conda_envs/desc_2/lib/python3.8/asyncio/tasks.py", line 501, in wait_for
    raise exceptions.TimeoutError()
asyncio.exceptions.TimeoutError

The above exception was the direct cause of the following exception:

Traceback (most recent call last):
  File "/sps/lsst/users/boutigny/conda_envs/desc_2/lib/python3.8/site-packages/distributed/worker.py", line 2169, in gather_dep
    response = await get_data_from_worker(
  File "/sps/lsst/users/boutigny/conda_envs/desc_2/lib/python3.8/site-packages/distributed/worker.py", line 3442, in get_data_from_worker
    return await retry_operation(_get_data, operation="get_data_from_worker")
  File "/sps/lsst/users/boutigny/conda_envs/desc_2/lib/python3.8/site-packages/distributed/utils_comm.py", line 385, in retry_operation
    return await retry(
  File "/sps/lsst/users/boutigny/conda_envs/desc_2/lib/python3.8/site-packages/distributed/utils_comm.py", line 370, in retry
    return await coro()
  File "/sps/lsst/users/boutigny/conda_envs/desc_2/lib/python3.8/site-packages/distributed/worker.py", line 3419, in _get_data
    comm = await rpc.connect(worker)
  File "/sps/lsst/users/boutigny/conda_envs/desc_2/lib/python3.8/site-packages/distributed/core.py", line 1010, in connect
    comm = await connect(
  File "/sps/lsst/users/boutigny/conda_envs/desc_2/lib/python3.8/site-packages/distributed/comm/core.py", line 323, in connect
    raise IOError(
OSError: Timed out during handshake while connecting to tcp://134.158.168.195:36940 after 10 s
distributed.comm.tcp - INFO - Connection closed before handshake completed
distributed.worker - ERROR - Worker stream died during communication: tcp://134.158.170.52:36211
Traceback (most recent call last):
  File "/sps/lsst/users/boutigny/conda_envs/desc_2/lib/python3.8/site-packages/distributed/comm/tcp.py", line 200, in read
    n = await stream.read_into(frames)
tornado.iostream.StreamClosedError: Stream is closed

The above exception was the direct cause of the following exception:

Traceback (most recent call last):
  File "/sps/lsst/users/boutigny/conda_envs/desc_2/lib/python3.8/site-packages/distributed/worker.py", line 2169, in gather_dep
    response = await get_data_from_worker(
  File "/sps/lsst/users/boutigny/conda_envs/desc_2/lib/python3.8/site-packages/distributed/worker.py", line 3442, in get_data_from_worker
    return await retry_operation(_get_data, operation="get_data_from_worker")
  File "/sps/lsst/users/boutigny/conda_envs/desc_2/lib/python3.8/site-packages/distributed/utils_comm.py", line 385, in retry_operation
    return await retry(
  File "/sps/lsst/users/boutigny/conda_envs/desc_2/lib/python3.8/site-packages/distributed/utils_comm.py", line 370, in retry
    return await coro()
  File "/sps/lsst/users/boutigny/conda_envs/desc_2/lib/python3.8/site-packages/distributed/worker.py", line 3422, in _get_data
    response = await send_recv(
  File "/sps/lsst/users/boutigny/conda_envs/desc_2/lib/python3.8/site-packages/distributed/core.py", line 645, in send_recv
    response = await comm.read(deserializers=deserializers)
  File "/sps/lsst/users/boutigny/conda_envs/desc_2/lib/python3.8/site-packages/distributed/comm/tcp.py", line 206, in read
    convert_stream_closed_error(self, e)
  File "/sps/lsst/users/boutigny/conda_envs/desc_2/lib/python3.8/site-packages/distributed/comm/tcp.py", line 128, in convert_stream_closed_error
    raise CommClosedError("in %s: %s" % (obj, exc)) from exc
distributed.comm.core.CommClosedError: in <closed TCP>: Stream is closed
distributed.core - INFO - Event loop was unresponsive in Worker for 7.95s.  This is often caused by long-running GIL-holding functions or moving large chunks of data. This can cause timeouts and instability.
distributed.utils_perf - INFO - full garbage collection released 10.41 MiB from 75 reference cycles (threshold: 9.54 MiB)
distributed.worker - ERROR - Worker stream died during communication: tcp://134.158.168.225:35269
Traceback (most recent call last):
  File "/sps/lsst/users/boutigny/conda_envs/desc_2/lib/python3.8/site-packages/distributed/comm/tcp.py", line 200, in read
    n = await stream.read_into(frames)
tornado.iostream.StreamClosedError: Stream is closed

The above exception was the direct cause of the following exception:

Traceback (most recent call last):
  File "/sps/lsst/users/boutigny/conda_envs/desc_2/lib/python3.8/site-packages/distributed/worker.py", line 2169, in gather_dep
    response = await get_data_from_worker(
  File "/sps/lsst/users/boutigny/conda_envs/desc_2/lib/python3.8/site-packages/distributed/worker.py", line 3442, in get_data_from_worker
    return await retry_operation(_get_data, operation="get_data_from_worker")
  File "/sps/lsst/users/boutigny/conda_envs/desc_2/lib/python3.8/site-packages/distributed/utils_comm.py", line 385, in retry_operation
    return await retry(
  File "/sps/lsst/users/boutigny/conda_envs/desc_2/lib/python3.8/site-packages/distributed/utils_comm.py", line 370, in retry
    return await coro()
  File "/sps/lsst/users/boutigny/conda_envs/desc_2/lib/python3.8/site-packages/distributed/worker.py", line 3422, in _get_data
    response = await send_recv(
  File "/sps/lsst/users/boutigny/conda_envs/desc_2/lib/python3.8/site-packages/distributed/core.py", line 645, in send_recv
    response = await comm.read(deserializers=deserializers)
  File "/sps/lsst/users/boutigny/conda_envs/desc_2/lib/python3.8/site-packages/distributed/comm/tcp.py", line 206, in read
    convert_stream_closed_error(self, e)
  File "/sps/lsst/users/boutigny/conda_envs/desc_2/lib/python3.8/site-packages/distributed/comm/tcp.py", line 128, in convert_stream_closed_error
    raise CommClosedError("in %s: %s" % (obj, exc)) from exc
distributed.comm.core.CommClosedError: in <closed TCP>: Stream is closed
distributed.worker - INFO - Can't find dependencies for key ('fix-overlap-and_-a2c92d0a7b4404ef4989bfc49cea49a2', 69)
distributed.worker - ERROR - Worker stream died during communication: tcp://134.158.171.73:34616
Traceback (most recent call last):
  File "/sps/lsst/users/boutigny/conda_envs/desc_2/lib/python3.8/site-packages/distributed/comm/tcp.py", line 200, in read
    n = await stream.read_into(frames)
tornado.iostream.StreamClosedError: Stream is closed

The above exception was the direct cause of the following exception:

Traceback (most recent call last):
  File "/sps/lsst/users/boutigny/conda_envs/desc_2/lib/python3.8/site-packages/distributed/worker.py", line 2169, in gather_dep
    response = await get_data_from_worker(
  File "/sps/lsst/users/boutigny/conda_envs/desc_2/lib/python3.8/site-packages/distributed/worker.py", line 3442, in get_data_from_worker
    return await retry_operation(_get_data, operation="get_data_from_worker")
  File "/sps/lsst/users/boutigny/conda_envs/desc_2/lib/python3.8/site-packages/distributed/utils_comm.py", line 385, in retry_operation
    return await retry(
  File "/sps/lsst/users/boutigny/conda_envs/desc_2/lib/python3.8/site-packages/distributed/utils_comm.py", line 370, in retry
    return await coro()
  File "/sps/lsst/users/boutigny/conda_envs/desc_2/lib/python3.8/site-packages/distributed/worker.py", line 3422, in _get_data
    response = await send_recv(
  File "/sps/lsst/users/boutigny/conda_envs/desc_2/lib/python3.8/site-packages/distributed/core.py", line 645, in send_recv
    response = await comm.read(deserializers=deserializers)
  File "/sps/lsst/users/boutigny/conda_envs/desc_2/lib/python3.8/site-packages/distributed/comm/tcp.py", line 206, in read
    convert_stream_closed_error(self, e)
  File "/sps/lsst/users/boutigny/conda_envs/desc_2/lib/python3.8/site-packages/distributed/comm/tcp.py", line 128, in convert_stream_closed_error
    raise CommClosedError("in %s: %s" % (obj, exc)) from exc
distributed.comm.core.CommClosedError: in <closed TCP>: Stream is closed
distributed.worker - INFO - Can't find dependencies for key ('fix-overlap-and_-a2c92d0a7b4404ef4989bfc49cea49a2', 84)
distributed.core - INFO - Event loop was unresponsive in Worker for 4.43s.  This is often caused by long-running GIL-holding functions or moving large chunks of data. This can cause timeouts and instability.
distributed.worker - WARNING - Memory use is high but worker has no data to store to disk.  Perhaps some other process is leaking memory?  Process memory: 2.82 GiB -- Worker memory limit: 4.66 GiB
distributed.comm.tcp - INFO - Connection closed before handshake completed
distributed.comm.tcp - INFO - Connection closed before handshake completed
distributed.comm.tcp - INFO - Connection closed before handshake completed
distributed.core - INFO - Event loop was unresponsive in Worker for 3.47s.  This is often caused by long-running GIL-holding functions or moving large chunks of data. This can cause timeouts and instability.
distributed.nanny - WARNING - Worker exceeded 95% memory budget. Restarting
distributed.nanny - WARNING - Worker exceeded 95% memory budget. Restarting
distributed.nanny - WARNING - Worker exceeded 95% memory budget. Restarting
distributed.nanny - INFO - Worker process 28727 was killed by signal 15
distributed.nanny - WARNING - Restarting worker
distributed.worker - INFO -       Start worker at: tcp://134.158.168.193:41986
distributed.worker - INFO -          Listening to: tcp://134.158.168.193:41986
distributed.worker - INFO -          dashboard at:      134.158.168.193:33165
distributed.worker - INFO - Waiting to connect to:  tcp://134.158.48.24:42415
distributed.worker - INFO - -------------------------------------------------
distributed.worker - INFO -               Threads:                          1
distributed.worker - INFO -                Memory:                   4.66 GiB
distributed.worker - INFO -       Local Directory: /pbs/throng/lsst/users/boutigny/LSST_notebooks/Dask/dask-worker-space/worker-vxjwd6be
distributed.worker - INFO - -------------------------------------------------
distributed.worker - INFO -         Registered to:  tcp://134.158.48.24:42415
distributed.worker - INFO - -------------------------------------------------
distributed.core - INFO - Starting established connection
distributed.worker - WARNING - Worker is at 81% memory usage. Pausing worker.  Process memory: 3.81 GiB -- Worker memory limit: 4.66 GiB
distributed.core - INFO - Event loop was unresponsive in Worker for 3.94s.  This is often caused by long-running GIL-holding functions or moving large chunks of data. This can cause timeouts and instability.
distributed.worker - WARNING - Worker is at 46% memory usage. Resuming worker. Process memory: 2.19 GiB -- Worker memory limit: 4.66 GiB
distributed.comm.tcp - INFO - Connection closed before handshake completed
