**********************************************************************
*                     Grid Engine Batch System                       *
*              IN2P3 Computing Centre, Villeurbanne FR               *
**********************************************************************
* User:                           boutigny                           *
* Group:                          lsst                               *
* Jobname:                        dask-worker                        *
* JobID:                          15658731                           *
* Queue:                          mc_debug                           *
* Worker:                         ccwcge0002.in2p3.fr                *
* Operating system:               Linux 3.10.0-1160.25.1.el7.x86_64  *
* Project:                        P_lsst                             *
**********************************************************************
* Submitted on:                   Tue Jul 20 17:50:45 CEST 2021      *
* Started on:                     Tue Jul 20 17:50:57 CEST 2021      *
**********************************************************************
distributed.nanny - INFO -         Start Nanny at: 'tcp://134.158.170.3:35618'
distributed.worker - INFO -       Start worker at:  tcp://134.158.170.3:33388
distributed.worker - INFO -          Listening to:  tcp://134.158.170.3:33388
distributed.worker - INFO -          dashboard at:        134.158.170.3:38016
distributed.worker - INFO - Waiting to connect to:  tcp://134.158.48.24:37486
distributed.worker - INFO - -------------------------------------------------
distributed.worker - INFO -               Threads:                          1
distributed.worker - INFO -                Memory:                   4.60 GiB
distributed.worker - INFO -       Local Directory: /pbs/throng/lsst/users/boutigny/LSST_notebooks/Dask/dask-worker-space/worker-foybq_xl
distributed.worker - INFO - -------------------------------------------------
distributed.worker - INFO -         Registered to:  tcp://134.158.48.24:37486
distributed.worker - INFO - -------------------------------------------------
distributed.core - INFO - Starting established connection
distributed.core - INFO - Event loop was unresponsive in Worker for 46.38s.  This is often caused by long-running GIL-holding functions or moving large chunks of data. This can cause timeouts and instability.
distributed.utils_perf - INFO - full garbage collection released 43.18 MiB from 28394 reference cycles (threshold: 9.54 MiB)
distributed.worker - ERROR - Worker stream died during communication: tcp://134.158.170.3:33852
Traceback (most recent call last):
  File "/sps/lsst/users/boutigny/conda_envs/desc_2/lib/python3.8/site-packages/distributed/comm/tcp.py", line 200, in read
    n = await stream.read_into(frames)
tornado.iostream.StreamClosedError: Stream is closed

The above exception was the direct cause of the following exception:

Traceback (most recent call last):
  File "/sps/lsst/users/boutigny/conda_envs/desc_2/lib/python3.8/site-packages/distributed/worker.py", line 2169, in gather_dep
    response = await get_data_from_worker(
  File "/sps/lsst/users/boutigny/conda_envs/desc_2/lib/python3.8/site-packages/distributed/worker.py", line 3442, in get_data_from_worker
    return await retry_operation(_get_data, operation="get_data_from_worker")
  File "/sps/lsst/users/boutigny/conda_envs/desc_2/lib/python3.8/site-packages/distributed/utils_comm.py", line 385, in retry_operation
    return await retry(
  File "/sps/lsst/users/boutigny/conda_envs/desc_2/lib/python3.8/site-packages/distributed/utils_comm.py", line 370, in retry
    return await coro()
  File "/sps/lsst/users/boutigny/conda_envs/desc_2/lib/python3.8/site-packages/distributed/worker.py", line 3422, in _get_data
    response = await send_recv(
  File "/sps/lsst/users/boutigny/conda_envs/desc_2/lib/python3.8/site-packages/distributed/core.py", line 645, in send_recv
    response = await comm.read(deserializers=deserializers)
  File "/sps/lsst/users/boutigny/conda_envs/desc_2/lib/python3.8/site-packages/distributed/comm/tcp.py", line 206, in read
    convert_stream_closed_error(self, e)
  File "/sps/lsst/users/boutigny/conda_envs/desc_2/lib/python3.8/site-packages/distributed/comm/tcp.py", line 128, in convert_stream_closed_error
    raise CommClosedError("in %s: %s" % (obj, exc)) from exc
distributed.comm.core.CommClosedError: in <closed TCP>: Stream is closed
distributed.worker - INFO - Can't find dependencies for key ('fix-overlap-getitem-79064f937c983bb927ec234f3e5f7ab1', 118)
distributed.worker - INFO - Dependent not found: ('set_index-de5055cf7981b50e2b876d80000d7d25', 118) 0 .  Asking scheduler
distributed.worker - INFO - Can't find dependencies for key ('fix-overlap-and_-a2c92d0a7b4404ef4989bfc49cea49a2', 118)
distributed.nanny - WARNING - Worker exceeded 95% memory budget. Restarting
distributed.nanny - INFO - Worker process 182859 was killed by signal 15
distributed.nanny - WARNING - Restarting worker
distributed.diskutils - INFO - Found stale lock file and directory '/pbs/throng/lsst/users/boutigny/LSST_notebooks/Dask/dask-worker-space/worker-rbptc_a7', purging
distributed.worker - INFO -       Start worker at:  tcp://134.158.170.3:36690
distributed.worker - INFO -          Listening to:  tcp://134.158.170.3:36690
distributed.worker - INFO -          dashboard at:        134.158.170.3:45047
distributed.worker - INFO - Waiting to connect to:  tcp://134.158.48.24:37486
distributed.worker - INFO - -------------------------------------------------
distributed.worker - INFO -               Threads:                          1
distributed.worker - INFO -                Memory:                   4.60 GiB
distributed.worker - INFO -       Local Directory: /pbs/throng/lsst/users/boutigny/LSST_notebooks/Dask/dask-worker-space/worker-7dgyqxgk
distributed.worker - INFO - -------------------------------------------------
distributed.worker - INFO -         Registered to:  tcp://134.158.48.24:37486
distributed.worker - INFO - -------------------------------------------------
distributed.core - INFO - Starting established connection
distributed.core - INFO - Event loop was unresponsive in Worker for 8.27s.  This is often caused by long-running GIL-holding functions or moving large chunks of data. This can cause timeouts and instability.
distributed.utils_perf - INFO - full garbage collection released 446.72 MiB from 80 reference cycles (threshold: 9.54 MiB)
distributed.worker - WARNING - Worker is at 90% memory usage. Pausing worker.  Process memory: 4.17 GiB -- Worker memory limit: 4.60 GiB
distributed.worker - WARNING - Worker is at 53% memory usage. Resuming worker. Process memory: 2.46 GiB -- Worker memory limit: 4.60 GiB
distributed.worker - WARNING - Worker is at 80% memory usage. Pausing worker.  Process memory: 3.71 GiB -- Worker memory limit: 4.60 GiB
distributed.worker - WARNING - Worker is at 58% memory usage. Resuming worker. Process memory: 2.71 GiB -- Worker memory limit: 4.60 GiB
distributed.worker - ERROR - failed during get data with tcp://134.158.170.3:36690 -> tcp://134.158.168.224:35940
Traceback (most recent call last):
  File "/sps/lsst/users/boutigny/conda_envs/desc_2/lib/python3.8/site-packages/tornado/iostream.py", line 867, in _read_to_buffer
    bytes_read = self.read_from_fd(buf)
  File "/sps/lsst/users/boutigny/conda_envs/desc_2/lib/python3.8/site-packages/tornado/iostream.py", line 1140, in read_from_fd
    return self.socket.recv_into(buf, len(buf))
ConnectionResetError: [Errno 104] Connection reset by peer

The above exception was the direct cause of the following exception:

Traceback (most recent call last):
  File "/sps/lsst/users/boutigny/conda_envs/desc_2/lib/python3.8/site-packages/distributed/worker.py", line 1366, in get_data
    response = await comm.read(deserializers=serializers)
  File "/sps/lsst/users/boutigny/conda_envs/desc_2/lib/python3.8/site-packages/distributed/comm/tcp.py", line 206, in read
    convert_stream_closed_error(self, e)
  File "/sps/lsst/users/boutigny/conda_envs/desc_2/lib/python3.8/site-packages/distributed/comm/tcp.py", line 124, in convert_stream_closed_error
    raise CommClosedError(
distributed.comm.core.CommClosedError: in <closed TCP>: ConnectionResetError: [Errno 104] Connection reset by peer
distributed.worker - WARNING - Worker is at 85% memory usage. Pausing worker.  Process memory: 3.91 GiB -- Worker memory limit: 4.60 GiB
distributed.core - INFO - Lost connection to 'tcp://134.158.168.224:36842': in <closed TCP>: ConnectionResetError: [Errno 104] Connection reset by peer
distributed.nanny - WARNING - Worker exceeded 95% memory budget. Restarting
distributed.nanny - WARNING - Worker exceeded 95% memory budget. Restarting
distributed.nanny - WARNING - Worker exceeded 95% memory budget. Restarting
distributed.nanny - WARNING - Worker exceeded 95% memory budget. Restarting
distributed.nanny - WARNING - Worker exceeded 95% memory budget. Restarting
distributed.nanny - WARNING - Worker exceeded 95% memory budget. Restarting
distributed.nanny - WARNING - Worker exceeded 95% memory budget. Restarting
distributed.nanny - WARNING - Worker exceeded 95% memory budget. Restarting
distributed.nanny - WARNING - Worker exceeded 95% memory budget. Restarting
distributed.nanny - WARNING - Worker exceeded 95% memory budget. Restarting
distributed.nanny - INFO - Worker process 188642 was killed by signal 15
distributed.nanny - WARNING - Restarting worker
distributed.worker - INFO -       Start worker at:  tcp://134.158.170.3:42919
distributed.worker - INFO -          Listening to:  tcp://134.158.170.3:42919
distributed.worker - INFO -          dashboard at:        134.158.170.3:36536
distributed.worker - INFO - Waiting to connect to:  tcp://134.158.48.24:37486
distributed.worker - INFO - -------------------------------------------------
distributed.worker - INFO -               Threads:                          1
distributed.worker - INFO -                Memory:                   4.60 GiB
distributed.worker - INFO -       Local Directory: /pbs/throng/lsst/users/boutigny/LSST_notebooks/Dask/dask-worker-space/worker-yzktfqjj
distributed.worker - INFO - -------------------------------------------------
distributed.worker - INFO -         Registered to:  tcp://134.158.48.24:37486
distributed.worker - INFO - -------------------------------------------------
distributed.core - INFO - Starting established connection
distributed.worker - ERROR - Worker stream died during communication: tcp://134.158.171.86:33752
Traceback (most recent call last):
  File "/sps/lsst/users/boutigny/conda_envs/desc_2/lib/python3.8/site-packages/distributed/comm/tcp.py", line 200, in read
    n = await stream.read_into(frames)
tornado.iostream.StreamClosedError: Stream is closed

The above exception was the direct cause of the following exception:

Traceback (most recent call last):
  File "/sps/lsst/users/boutigny/conda_envs/desc_2/lib/python3.8/site-packages/distributed/worker.py", line 2169, in gather_dep
    response = await get_data_from_worker(
  File "/sps/lsst/users/boutigny/conda_envs/desc_2/lib/python3.8/site-packages/distributed/worker.py", line 3442, in get_data_from_worker
    return await retry_operation(_get_data, operation="get_data_from_worker")
  File "/sps/lsst/users/boutigny/conda_envs/desc_2/lib/python3.8/site-packages/distributed/utils_comm.py", line 385, in retry_operation
    return await retry(
  File "/sps/lsst/users/boutigny/conda_envs/desc_2/lib/python3.8/site-packages/distributed/utils_comm.py", line 370, in retry
    return await coro()
  File "/sps/lsst/users/boutigny/conda_envs/desc_2/lib/python3.8/site-packages/distributed/worker.py", line 3422, in _get_data
    response = await send_recv(
  File "/sps/lsst/users/boutigny/conda_envs/desc_2/lib/python3.8/site-packages/distributed/core.py", line 645, in send_recv
    response = await comm.read(deserializers=deserializers)
  File "/sps/lsst/users/boutigny/conda_envs/desc_2/lib/python3.8/site-packages/distributed/comm/tcp.py", line 206, in read
    convert_stream_closed_error(self, e)
  File "/sps/lsst/users/boutigny/conda_envs/desc_2/lib/python3.8/site-packages/distributed/comm/tcp.py", line 128, in convert_stream_closed_error
    raise CommClosedError("in %s: %s" % (obj, exc)) from exc
distributed.comm.core.CommClosedError: in <closed TCP>: Stream is closed
distributed.worker - INFO - Can't find dependencies for key ('fix-overlap-and_-a2c92d0a7b4404ef4989bfc49cea49a2', 165)
distributed.nanny - WARNING - Worker exceeded 95% memory budget. Restarting
distributed.nanny - INFO - Worker process 189215 was killed by signal 15
distributed.nanny - WARNING - Restarting worker
distributed.diskutils - INFO - Found stale lock file and directory '/pbs/throng/lsst/users/boutigny/LSST_notebooks/Dask/dask-worker-space/worker-a4d8_eai', purging
distributed.diskutils - INFO - Found stale lock file and directory '/pbs/throng/lsst/users/boutigny/LSST_notebooks/Dask/dask-worker-space/worker-fgwc2r0g', purging
distributed.worker - INFO -       Start worker at:  tcp://134.158.170.3:40401
distributed.worker - INFO -          Listening to:  tcp://134.158.170.3:40401
distributed.worker - INFO -          dashboard at:        134.158.170.3:41193
distributed.worker - INFO - Waiting to connect to:  tcp://134.158.48.24:37486
distributed.worker - INFO - -------------------------------------------------
distributed.worker - INFO -               Threads:                          1
distributed.worker - INFO -                Memory:                   4.60 GiB
distributed.worker - INFO -       Local Directory: /pbs/throng/lsst/users/boutigny/LSST_notebooks/Dask/dask-worker-space/worker-n37l_fm8
distributed.worker - INFO - -------------------------------------------------
distributed.worker - INFO -         Registered to:  tcp://134.158.48.24:37486
distributed.worker - INFO - -------------------------------------------------
distributed.core - INFO - Starting established connection
distributed.utils_perf - INFO - full garbage collection released 566.86 MiB from 97 reference cycles (threshold: 9.54 MiB)
distributed.core - INFO - Event loop was unresponsive in Worker for 4.64s.  This is often caused by long-running GIL-holding functions or moving large chunks of data. This can cause timeouts and instability.
distributed.worker - WARNING - Worker is at 81% memory usage. Pausing worker.  Process memory: 3.74 GiB -- Worker memory limit: 4.60 GiB
distributed.core - INFO - Event loop was unresponsive in Worker for 3.72s.  This is often caused by long-running GIL-holding functions or moving large chunks of data. This can cause timeouts and instability.
distributed.utils_perf - INFO - full garbage collection released 20.78 MiB from 21 reference cycles (threshold: 9.54 MiB)
distributed.worker - WARNING - Worker is at 56% memory usage. Resuming worker. Process memory: 2.61 GiB -- Worker memory limit: 4.60 GiB
distributed.worker - WARNING - Memory use is high but worker has no data to store to disk.  Perhaps some other process is leaking memory?  Process memory: 3.63 GiB -- Worker memory limit: 4.60 GiB
distributed.worker - WARNING - Memory use is high but worker has no data to store to disk.  Perhaps some other process is leaking memory?  Process memory: 3.63 GiB -- Worker memory limit: 4.60 GiB
distributed.worker - WARNING - Memory use is high but worker has no data to store to disk.  Perhaps some other process is leaking memory?  Process memory: 3.44 GiB -- Worker memory limit: 4.60 GiB
distributed.nanny - WARNING - Worker exceeded 95% memory budget. Restarting
distributed.nanny - INFO - Worker process 189312 was killed by signal 15
distributed.nanny - WARNING - Restarting worker
distributed.worker - INFO -       Start worker at:  tcp://134.158.170.3:43775
distributed.worker - INFO -          Listening to:  tcp://134.158.170.3:43775
distributed.worker - INFO -          dashboard at:        134.158.170.3:41189
distributed.worker - INFO - Waiting to connect to:  tcp://134.158.48.24:37486
distributed.worker - INFO - -------------------------------------------------
distributed.worker - INFO -               Threads:                          1
distributed.worker - INFO -                Memory:                   4.60 GiB
distributed.worker - INFO -       Local Directory: /pbs/throng/lsst/users/boutigny/LSST_notebooks/Dask/dask-worker-space/worker-inaof_4g
distributed.worker - INFO - -------------------------------------------------
distributed.worker - INFO -         Registered to:  tcp://134.158.48.24:37486
distributed.worker - INFO - -------------------------------------------------
distributed.core - INFO - Starting established connection
distributed.worker - ERROR - failed during get data with tcp://134.158.170.3:43775 -> tcp://134.158.168.237:41198
Traceback (most recent call last):
  File "/sps/lsst/users/boutigny/conda_envs/desc_2/lib/python3.8/site-packages/tornado/iostream.py", line 867, in _read_to_buffer
    bytes_read = self.read_from_fd(buf)
  File "/sps/lsst/users/boutigny/conda_envs/desc_2/lib/python3.8/site-packages/tornado/iostream.py", line 1140, in read_from_fd
    return self.socket.recv_into(buf, len(buf))
ConnectionResetError: [Errno 104] Connection reset by peer

The above exception was the direct cause of the following exception:

Traceback (most recent call last):
  File "/sps/lsst/users/boutigny/conda_envs/desc_2/lib/python3.8/site-packages/distributed/worker.py", line 1366, in get_data
    response = await comm.read(deserializers=serializers)
  File "/sps/lsst/users/boutigny/conda_envs/desc_2/lib/python3.8/site-packages/distributed/comm/tcp.py", line 206, in read
    convert_stream_closed_error(self, e)
  File "/sps/lsst/users/boutigny/conda_envs/desc_2/lib/python3.8/site-packages/distributed/comm/tcp.py", line 124, in convert_stream_closed_error
    raise CommClosedError(
distributed.comm.core.CommClosedError: in <closed TCP>: ConnectionResetError: [Errno 104] Connection reset by peer
distributed.core - INFO - Lost connection to 'tcp://134.158.168.237:54630': in <closed TCP>: ConnectionResetError: [Errno 104] Connection reset by peer
distributed.worker - ERROR - Worker stream died during communication: tcp://134.158.168.222:43945
Traceback (most recent call last):
  File "/sps/lsst/users/boutigny/conda_envs/desc_2/lib/python3.8/site-packages/distributed/comm/core.py", line 318, in connect
    handshake = await asyncio.wait_for(comm.read(), time_left())
  File "/sps/lsst/users/boutigny/conda_envs/desc_2/lib/python3.8/asyncio/tasks.py", line 501, in wait_for
    raise exceptions.TimeoutError()
asyncio.exceptions.TimeoutError

The above exception was the direct cause of the following exception:

Traceback (most recent call last):
  File "/sps/lsst/users/boutigny/conda_envs/desc_2/lib/python3.8/site-packages/distributed/worker.py", line 2169, in gather_dep
    response = await get_data_from_worker(
  File "/sps/lsst/users/boutigny/conda_envs/desc_2/lib/python3.8/site-packages/distributed/worker.py", line 3442, in get_data_from_worker
    return await retry_operation(_get_data, operation="get_data_from_worker")
  File "/sps/lsst/users/boutigny/conda_envs/desc_2/lib/python3.8/site-packages/distributed/utils_comm.py", line 385, in retry_operation
    return await retry(
  File "/sps/lsst/users/boutigny/conda_envs/desc_2/lib/python3.8/site-packages/distributed/utils_comm.py", line 370, in retry
    return await coro()
  File "/sps/lsst/users/boutigny/conda_envs/desc_2/lib/python3.8/site-packages/distributed/worker.py", line 3419, in _get_data
    comm = await rpc.connect(worker)
  File "/sps/lsst/users/boutigny/conda_envs/desc_2/lib/python3.8/site-packages/distributed/core.py", line 1010, in connect
    comm = await connect(
  File "/sps/lsst/users/boutigny/conda_envs/desc_2/lib/python3.8/site-packages/distributed/comm/core.py", line 323, in connect
    raise IOError(
OSError: Timed out during handshake while connecting to tcp://134.158.168.222:43945 after 10 s
distributed.nanny - WARNING - Worker exceeded 95% memory budget. Restarting
distributed.nanny - INFO - Worker process 189646 was killed by signal 15
distributed.nanny - WARNING - Restarting worker
distributed.worker - INFO -       Start worker at:  tcp://134.158.170.3:38362
distributed.worker - INFO -          Listening to:  tcp://134.158.170.3:38362
distributed.worker - INFO -          dashboard at:        134.158.170.3:34257
distributed.worker - INFO - Waiting to connect to:  tcp://134.158.48.24:37486
distributed.worker - INFO - -------------------------------------------------
distributed.worker - INFO -               Threads:                          1
distributed.worker - INFO -                Memory:                   4.60 GiB
distributed.worker - INFO -       Local Directory: /pbs/throng/lsst/users/boutigny/LSST_notebooks/Dask/dask-worker-space/worker-b3fcre_d
distributed.worker - INFO - -------------------------------------------------
distributed.worker - INFO -         Registered to:  tcp://134.158.48.24:37486
distributed.worker - INFO - -------------------------------------------------
distributed.core - INFO - Starting established connection
distributed.utils_perf - INFO - full garbage collection released 569.62 MiB from 88 reference cycles (threshold: 9.54 MiB)
distributed.worker - ERROR - failed during get data with tcp://134.158.170.3:38362 -> tcp://134.158.171.43:37059
Traceback (most recent call last):
  File "/sps/lsst/users/boutigny/conda_envs/desc_2/lib/python3.8/site-packages/tornado/iostream.py", line 867, in _read_to_buffer
    bytes_read = self.read_from_fd(buf)
  File "/sps/lsst/users/boutigny/conda_envs/desc_2/lib/python3.8/site-packages/tornado/iostream.py", line 1140, in read_from_fd
    return self.socket.recv_into(buf, len(buf))
ConnectionResetError: [Errno 104] Connection reset by peer

The above exception was the direct cause of the following exception:

Traceback (most recent call last):
  File "/sps/lsst/users/boutigny/conda_envs/desc_2/lib/python3.8/site-packages/distributed/worker.py", line 1366, in get_data
    response = await comm.read(deserializers=serializers)
  File "/sps/lsst/users/boutigny/conda_envs/desc_2/lib/python3.8/site-packages/distributed/comm/tcp.py", line 206, in read
    convert_stream_closed_error(self, e)
  File "/sps/lsst/users/boutigny/conda_envs/desc_2/lib/python3.8/site-packages/distributed/comm/tcp.py", line 124, in convert_stream_closed_error
    raise CommClosedError(
distributed.comm.core.CommClosedError: in <closed TCP>: ConnectionResetError: [Errno 104] Connection reset by peer
distributed.core - INFO - Lost connection to 'tcp://134.158.171.43:33370': in <closed TCP>: ConnectionResetError: [Errno 104] Connection reset by peer
distributed.utils_perf - INFO - full garbage collection released 570.27 MiB from 27 reference cycles (threshold: 9.54 MiB)
distributed.core - INFO - Event loop was unresponsive in Worker for 3.00s.  This is often caused by long-running GIL-holding functions or moving large chunks of data. This can cause timeouts and instability.
distributed.worker - ERROR - failed during get data with tcp://134.158.170.3:38362 -> tcp://134.158.170.37:35624
Traceback (most recent call last):
  File "/sps/lsst/users/boutigny/conda_envs/desc_2/lib/python3.8/site-packages/distributed/comm/tcp.py", line 196, in read
    frames_nbytes = await stream.read_bytes(fmt_size)
tornado.iostream.StreamClosedError: Stream is closed

The above exception was the direct cause of the following exception:

Traceback (most recent call last):
  File "/sps/lsst/users/boutigny/conda_envs/desc_2/lib/python3.8/site-packages/distributed/worker.py", line 1366, in get_data
    response = await comm.read(deserializers=serializers)
  File "/sps/lsst/users/boutigny/conda_envs/desc_2/lib/python3.8/site-packages/distributed/comm/tcp.py", line 206, in read
    convert_stream_closed_error(self, e)
  File "/sps/lsst/users/boutigny/conda_envs/desc_2/lib/python3.8/site-packages/distributed/comm/tcp.py", line 128, in convert_stream_closed_error
    raise CommClosedError("in %s: %s" % (obj, exc)) from exc
distributed.comm.core.CommClosedError: in <closed TCP>: Stream is closed
distributed.core - INFO - Event loop was unresponsive in Worker for 3.87s.  This is often caused by long-running GIL-holding functions or moving large chunks of data. This can cause timeouts and instability.
distributed.utils_perf - INFO - full garbage collection released 21.13 MiB from 21 reference cycles (threshold: 9.54 MiB)
distributed.worker - WARNING - Memory use is high but worker has no data to store to disk.  Perhaps some other process is leaking memory?  Process memory: 3.61 GiB -- Worker memory limit: 4.60 GiB
distributed.core - INFO - Lost connection to 'tcp://134.158.170.37:35070': in <closed TCP>: Stream is closed
distributed.worker - WARNING - Memory use is high but worker has no data to store to disk.  Perhaps some other process is leaking memory?  Process memory: 3.61 GiB -- Worker memory limit: 4.60 GiB
distributed.nanny - WARNING - Worker exceeded 95% memory budget. Restarting
distributed.nanny - INFO - Worker process 189887 was killed by signal 15
distributed.nanny - WARNING - Restarting worker
distributed.worker - INFO -       Start worker at:  tcp://134.158.170.3:33907
distributed.worker - INFO -          Listening to:  tcp://134.158.170.3:33907
distributed.worker - INFO -          dashboard at:        134.158.170.3:38773
distributed.worker - INFO - Waiting to connect to:  tcp://134.158.48.24:37486
distributed.worker - INFO - -------------------------------------------------
distributed.worker - INFO -               Threads:                          1
distributed.worker - INFO -                Memory:                   4.60 GiB
distributed.worker - INFO -       Local Directory: /pbs/throng/lsst/users/boutigny/LSST_notebooks/Dask/dask-worker-space/worker-int8kr6x
distributed.worker - INFO - -------------------------------------------------
distributed.worker - INFO -         Registered to:  tcp://134.158.48.24:37486
distributed.worker - INFO - -------------------------------------------------
distributed.core - INFO - Starting established connection
distributed.worker - ERROR - Worker stream died during communication: tcp://134.158.168.226:33661
Traceback (most recent call last):
  File "/sps/lsst/users/boutigny/conda_envs/desc_2/lib/python3.8/site-packages/tornado/iostream.py", line 867, in _read_to_buffer
    bytes_read = self.read_from_fd(buf)
  File "/sps/lsst/users/boutigny/conda_envs/desc_2/lib/python3.8/site-packages/tornado/iostream.py", line 1140, in read_from_fd
    return self.socket.recv_into(buf, len(buf))
ConnectionResetError: [Errno 104] Connection reset by peer

The above exception was the direct cause of the following exception:

Traceback (most recent call last):
  File "/sps/lsst/users/boutigny/conda_envs/desc_2/lib/python3.8/site-packages/distributed/worker.py", line 2169, in gather_dep
    response = await get_data_from_worker(
  File "/sps/lsst/users/boutigny/conda_envs/desc_2/lib/python3.8/site-packages/distributed/worker.py", line 3442, in get_data_from_worker
    return await retry_operation(_get_data, operation="get_data_from_worker")
  File "/sps/lsst/users/boutigny/conda_envs/desc_2/lib/python3.8/site-packages/distributed/utils_comm.py", line 385, in retry_operation
    return await retry(
  File "/sps/lsst/users/boutigny/conda_envs/desc_2/lib/python3.8/site-packages/distributed/utils_comm.py", line 370, in retry
    return await coro()
  File "/sps/lsst/users/boutigny/conda_envs/desc_2/lib/python3.8/site-packages/distributed/worker.py", line 3422, in _get_data
    response = await send_recv(
  File "/sps/lsst/users/boutigny/conda_envs/desc_2/lib/python3.8/site-packages/distributed/core.py", line 645, in send_recv
    response = await comm.read(deserializers=deserializers)
  File "/sps/lsst/users/boutigny/conda_envs/desc_2/lib/python3.8/site-packages/distributed/comm/tcp.py", line 206, in read
    convert_stream_closed_error(self, e)
  File "/sps/lsst/users/boutigny/conda_envs/desc_2/lib/python3.8/site-packages/distributed/comm/tcp.py", line 124, in convert_stream_closed_error
    raise CommClosedError(
distributed.comm.core.CommClosedError: in <closed TCP>: ConnectionResetError: [Errno 104] Connection reset by peer
distributed.worker - INFO - Can't find dependencies for key ('fix-overlap-and_-a2c92d0a7b4404ef4989bfc49cea49a2', 92)
distributed.worker - INFO - Dependent not found: ('set_index-de5055cf7981b50e2b876d80000d7d25', 91) 0 .  Asking scheduler
distributed.worker - ERROR - Worker stream died during communication: tcp://134.158.172.229:45325
Traceback (most recent call last):
  File "/sps/lsst/users/boutigny/conda_envs/desc_2/lib/python3.8/site-packages/distributed/comm/tcp.py", line 200, in read
    n = await stream.read_into(frames)
tornado.iostream.StreamClosedError: Stream is closed

The above exception was the direct cause of the following exception:

Traceback (most recent call last):
  File "/sps/lsst/users/boutigny/conda_envs/desc_2/lib/python3.8/site-packages/distributed/worker.py", line 2169, in gather_dep
    response = await get_data_from_worker(
  File "/sps/lsst/users/boutigny/conda_envs/desc_2/lib/python3.8/site-packages/distributed/worker.py", line 3442, in get_data_from_worker
    return await retry_operation(_get_data, operation="get_data_from_worker")
  File "/sps/lsst/users/boutigny/conda_envs/desc_2/lib/python3.8/site-packages/distributed/utils_comm.py", line 385, in retry_operation
    return await retry(
  File "/sps/lsst/users/boutigny/conda_envs/desc_2/lib/python3.8/site-packages/distributed/utils_comm.py", line 370, in retry
    return await coro()
  File "/sps/lsst/users/boutigny/conda_envs/desc_2/lib/python3.8/site-packages/distributed/worker.py", line 3422, in _get_data
    response = await send_recv(
  File "/sps/lsst/users/boutigny/conda_envs/desc_2/lib/python3.8/site-packages/distributed/core.py", line 645, in send_recv
    response = await comm.read(deserializers=deserializers)
  File "/sps/lsst/users/boutigny/conda_envs/desc_2/lib/python3.8/site-packages/distributed/comm/tcp.py", line 206, in read
    convert_stream_closed_error(self, e)
  File "/sps/lsst/users/boutigny/conda_envs/desc_2/lib/python3.8/site-packages/distributed/comm/tcp.py", line 128, in convert_stream_closed_error
    raise CommClosedError("in %s: %s" % (obj, exc)) from exc
distributed.comm.core.CommClosedError: in <closed TCP>: Stream is closed
