**********************************************************************
*                     Grid Engine Batch System                       *
*              IN2P3 Computing Centre, Villeurbanne FR               *
**********************************************************************
* User:                           boutigny                           *
* Group:                          lsst                               *
* Jobname:                        dask-worker                        *
* JobID:                          15661166                           *
* Queue:                          long                               *
* Worker:                         ccwsge0363.in2p3.fr                *
* Operating system:               Linux 3.10.0-1160.25.1.el7.x86_64  *
* Project:                        P_lsst                             *
**********************************************************************
* Submitted on:                   Tue Jul 20 19:31:22 CEST 2021      *
* Started on:                     Tue Jul 20 19:31:33 CEST 2021      *
**********************************************************************
/var/spool/sge/ccwsge0363/job_scripts/15661166: line 9: e: command not found
/var/spool/sge/ccwsge0363/job_scripts/15661166: line 10: x: command not found
/var/spool/sge/ccwsge0363/job_scripts/15661166: line 11: p: command not found
/var/spool/sge/ccwsge0363/job_scripts/15661166: line 12: o: command not found
/var/spool/sge/ccwsge0363/job_scripts/15661166: line 13: r: command not found
/var/spool/sge/ccwsge0363/job_scripts/15661166: line 14: t: command not found
/var/spool/sge/ccwsge0363/job_scripts/15661166: line 16: M: command not found
/var/spool/sge/ccwsge0363/job_scripts/15661166: line 17: A: command not found
/var/spool/sge/ccwsge0363/job_scripts/15661166: line 18: L: command not found
/var/spool/sge/ccwsge0363/job_scripts/15661166: line 19: L: command not found
/var/spool/sge/ccwsge0363/job_scripts/15661166: line 20: O: command not found
/var/spool/sge/ccwsge0363/job_scripts/15661166: line 21: C: command not found
/var/spool/sge/ccwsge0363/job_scripts/15661166: line 22: _: command not found
/var/spool/sge/ccwsge0363/job_scripts/15661166: line 23: T: command not found
/var/spool/sge/ccwsge0363/job_scripts/15661166: line 24: R: command not found
/var/spool/sge/ccwsge0363/job_scripts/15661166: line 25: I: command not found
/var/spool/sge/ccwsge0363/job_scripts/15661166: line 26: M: command not found
/var/spool/sge/ccwsge0363/job_scripts/15661166: line 27: _: command not found
/var/spool/sge/ccwsge0363/job_scripts/15661166: line 28: T: command not found
/var/spool/sge/ccwsge0363/job_scripts/15661166: line 29: H: command not found
/var/spool/sge/ccwsge0363/job_scripts/15661166: line 30: R: command not found
/var/spool/sge/ccwsge0363/job_scripts/15661166: line 31: E: command not found
/var/spool/sge/ccwsge0363/job_scripts/15661166: line 32: S: command not found
/var/spool/sge/ccwsge0363/job_scripts/15661166: line 33: H: command not found
/var/spool/sge/ccwsge0363/job_scripts/15661166: line 34: O: command not found
/var/spool/sge/ccwsge0363/job_scripts/15661166: line 35: L: command not found
/var/spool/sge/ccwsge0363/job_scripts/15661166: line 36: D: command not found
/var/spool/sge/ccwsge0363/job_scripts/15661166: line 37: _: command not found
/var/spool/sge/ccwsge0363/job_scripts/15661166: line 38: =: command not found
/var/spool/sge/ccwsge0363/job_scripts/15661166: line 39: 5: command not found
/var/spool/sge/ccwsge0363/job_scripts/15661166: line 40: 1: command not found
/var/spool/sge/ccwsge0363/job_scripts/15661166: line 41: 2: command not found
/var/spool/sge/ccwsge0363/job_scripts/15661166: line 42: 0: command not found
distributed.nanny - INFO -         Start Nanny at: 'tcp://134.158.168.221:33128'
distributed.worker - INFO -       Start worker at: tcp://134.158.168.221:33601
distributed.worker - INFO -          Listening to: tcp://134.158.168.221:33601
distributed.worker - INFO -          dashboard at:      134.158.168.221:45599
distributed.worker - INFO - Waiting to connect to:  tcp://134.158.48.24:35668
distributed.worker - INFO - -------------------------------------------------
distributed.worker - INFO -               Threads:                          1
distributed.worker - INFO -                Memory:                   4.60 GiB
distributed.worker - INFO -       Local Directory: /pbs/throng/lsst/users/boutigny/LSST_notebooks/Dask/dask-worker-space/worker-hx9fofm0
distributed.worker - INFO - -------------------------------------------------
distributed.worker - INFO -         Registered to:  tcp://134.158.48.24:35668
distributed.worker - INFO - -------------------------------------------------
distributed.core - INFO - Starting established connection
distributed.core - INFO - Event loop was unresponsive in Worker for 8.13s.  This is often caused by long-running GIL-holding functions or moving large chunks of data. This can cause timeouts and instability.
distributed.worker - ERROR - Worker stream died during communication: tcp://134.158.168.224:39242
Traceback (most recent call last):
  File "/sps/lsst/users/boutigny/conda_envs/desc_2/lib/python3.8/site-packages/tornado/iostream.py", line 867, in _read_to_buffer
    bytes_read = self.read_from_fd(buf)
  File "/sps/lsst/users/boutigny/conda_envs/desc_2/lib/python3.8/site-packages/tornado/iostream.py", line 1140, in read_from_fd
    return self.socket.recv_into(buf, len(buf))
ConnectionResetError: [Errno 104] Connection reset by peer

The above exception was the direct cause of the following exception:

Traceback (most recent call last):
  File "/sps/lsst/users/boutigny/conda_envs/desc_2/lib/python3.8/site-packages/distributed/comm/core.py", line 318, in connect
    handshake = await asyncio.wait_for(comm.read(), time_left())
  File "/sps/lsst/users/boutigny/conda_envs/desc_2/lib/python3.8/asyncio/tasks.py", line 494, in wait_for
    return fut.result()
  File "/sps/lsst/users/boutigny/conda_envs/desc_2/lib/python3.8/site-packages/distributed/comm/tcp.py", line 206, in read
    convert_stream_closed_error(self, e)
  File "/sps/lsst/users/boutigny/conda_envs/desc_2/lib/python3.8/site-packages/distributed/comm/tcp.py", line 124, in convert_stream_closed_error
    raise CommClosedError(
distributed.comm.core.CommClosedError: in <closed TCP>: ConnectionResetError: [Errno 104] Connection reset by peer

The above exception was the direct cause of the following exception:

Traceback (most recent call last):
  File "/sps/lsst/users/boutigny/conda_envs/desc_2/lib/python3.8/site-packages/distributed/worker.py", line 2169, in gather_dep
    response = await get_data_from_worker(
  File "/sps/lsst/users/boutigny/conda_envs/desc_2/lib/python3.8/site-packages/distributed/worker.py", line 3442, in get_data_from_worker
    return await retry_operation(_get_data, operation="get_data_from_worker")
  File "/sps/lsst/users/boutigny/conda_envs/desc_2/lib/python3.8/site-packages/distributed/utils_comm.py", line 385, in retry_operation
    return await retry(
  File "/sps/lsst/users/boutigny/conda_envs/desc_2/lib/python3.8/site-packages/distributed/utils_comm.py", line 370, in retry
    return await coro()
  File "/sps/lsst/users/boutigny/conda_envs/desc_2/lib/python3.8/site-packages/distributed/worker.py", line 3419, in _get_data
    comm = await rpc.connect(worker)
  File "/sps/lsst/users/boutigny/conda_envs/desc_2/lib/python3.8/site-packages/distributed/core.py", line 1010, in connect
    comm = await connect(
  File "/sps/lsst/users/boutigny/conda_envs/desc_2/lib/python3.8/site-packages/distributed/comm/core.py", line 323, in connect
    raise IOError(
OSError: Timed out during handshake while connecting to tcp://134.158.168.224:39242 after 10 s
distributed.worker - ERROR - Worker stream died during communication: tcp://134.158.170.57:35502
Traceback (most recent call last):
  File "/sps/lsst/users/boutigny/conda_envs/desc_2/lib/python3.8/site-packages/tornado/iostream.py", line 867, in _read_to_buffer
    bytes_read = self.read_from_fd(buf)
  File "/sps/lsst/users/boutigny/conda_envs/desc_2/lib/python3.8/site-packages/tornado/iostream.py", line 1140, in read_from_fd
    return self.socket.recv_into(buf, len(buf))
ConnectionResetError: [Errno 104] Connection reset by peer

The above exception was the direct cause of the following exception:

Traceback (most recent call last):
  File "/sps/lsst/users/boutigny/conda_envs/desc_2/lib/python3.8/site-packages/distributed/comm/core.py", line 318, in connect
    handshake = await asyncio.wait_for(comm.read(), time_left())
  File "/sps/lsst/users/boutigny/conda_envs/desc_2/lib/python3.8/asyncio/tasks.py", line 494, in wait_for
    return fut.result()
  File "/sps/lsst/users/boutigny/conda_envs/desc_2/lib/python3.8/site-packages/distributed/comm/tcp.py", line 206, in read
    convert_stream_closed_error(self, e)
  File "/sps/lsst/users/boutigny/conda_envs/desc_2/lib/python3.8/site-packages/distributed/comm/tcp.py", line 124, in convert_stream_closed_error
    raise CommClosedError(
distributed.comm.core.CommClosedError: in <closed TCP>: ConnectionResetError: [Errno 104] Connection reset by peer

The above exception was the direct cause of the following exception:

Traceback (most recent call last):
  File "/sps/lsst/users/boutigny/conda_envs/desc_2/lib/python3.8/site-packages/distributed/worker.py", line 2169, in gather_dep
    response = await get_data_from_worker(
  File "/sps/lsst/users/boutigny/conda_envs/desc_2/lib/python3.8/site-packages/distributed/worker.py", line 3442, in get_data_from_worker
    return await retry_operation(_get_data, operation="get_data_from_worker")
  File "/sps/lsst/users/boutigny/conda_envs/desc_2/lib/python3.8/site-packages/distributed/utils_comm.py", line 385, in retry_operation
    return await retry(
  File "/sps/lsst/users/boutigny/conda_envs/desc_2/lib/python3.8/site-packages/distributed/utils_comm.py", line 370, in retry
    return await coro()
  File "/sps/lsst/users/boutigny/conda_envs/desc_2/lib/python3.8/site-packages/distributed/worker.py", line 3419, in _get_data
    comm = await rpc.connect(worker)
  File "/sps/lsst/users/boutigny/conda_envs/desc_2/lib/python3.8/site-packages/distributed/core.py", line 1010, in connect
    comm = await connect(
  File "/sps/lsst/users/boutigny/conda_envs/desc_2/lib/python3.8/site-packages/distributed/comm/core.py", line 323, in connect
    raise IOError(
OSError: Timed out during handshake while connecting to tcp://134.158.170.57:35502 after 10 s
distributed.worker - ERROR - Worker stream died during communication: tcp://134.158.168.114:42303
Traceback (most recent call last):
  File "/sps/lsst/users/boutigny/conda_envs/desc_2/lib/python3.8/site-packages/distributed/comm/core.py", line 318, in connect
    handshake = await asyncio.wait_for(comm.read(), time_left())
  File "/sps/lsst/users/boutigny/conda_envs/desc_2/lib/python3.8/asyncio/tasks.py", line 501, in wait_for
    raise exceptions.TimeoutError()
asyncio.exceptions.TimeoutError

The above exception was the direct cause of the following exception:

Traceback (most recent call last):
  File "/sps/lsst/users/boutigny/conda_envs/desc_2/lib/python3.8/site-packages/distributed/worker.py", line 2169, in gather_dep
    response = await get_data_from_worker(
  File "/sps/lsst/users/boutigny/conda_envs/desc_2/lib/python3.8/site-packages/distributed/worker.py", line 3442, in get_data_from_worker
    return await retry_operation(_get_data, operation="get_data_from_worker")
  File "/sps/lsst/users/boutigny/conda_envs/desc_2/lib/python3.8/site-packages/distributed/utils_comm.py", line 385, in retry_operation
    return await retry(
  File "/sps/lsst/users/boutigny/conda_envs/desc_2/lib/python3.8/site-packages/distributed/utils_comm.py", line 370, in retry
    return await coro()
  File "/sps/lsst/users/boutigny/conda_envs/desc_2/lib/python3.8/site-packages/distributed/worker.py", line 3419, in _get_data
    comm = await rpc.connect(worker)
  File "/sps/lsst/users/boutigny/conda_envs/desc_2/lib/python3.8/site-packages/distributed/core.py", line 1010, in connect
    comm = await connect(
  File "/sps/lsst/users/boutigny/conda_envs/desc_2/lib/python3.8/site-packages/distributed/comm/core.py", line 323, in connect
    raise IOError(
OSError: Timed out during handshake while connecting to tcp://134.158.168.114:42303 after 10 s
distributed.worker - ERROR - Worker stream died during communication: tcp://134.158.168.195:41928
Traceback (most recent call last):
  File "/sps/lsst/users/boutigny/conda_envs/desc_2/lib/python3.8/site-packages/distributed/comm/core.py", line 318, in connect
    handshake = await asyncio.wait_for(comm.read(), time_left())
  File "/sps/lsst/users/boutigny/conda_envs/desc_2/lib/python3.8/asyncio/tasks.py", line 501, in wait_for
    raise exceptions.TimeoutError()
asyncio.exceptions.TimeoutError

The above exception was the direct cause of the following exception:

Traceback (most recent call last):
  File "/sps/lsst/users/boutigny/conda_envs/desc_2/lib/python3.8/site-packages/distributed/worker.py", line 2169, in gather_dep
    response = await get_data_from_worker(
  File "/sps/lsst/users/boutigny/conda_envs/desc_2/lib/python3.8/site-packages/distributed/worker.py", line 3442, in get_data_from_worker
    return await retry_operation(_get_data, operation="get_data_from_worker")
  File "/sps/lsst/users/boutigny/conda_envs/desc_2/lib/python3.8/site-packages/distributed/utils_comm.py", line 385, in retry_operation
    return await retry(
  File "/sps/lsst/users/boutigny/conda_envs/desc_2/lib/python3.8/site-packages/distributed/utils_comm.py", line 370, in retry
    return await coro()
  File "/sps/lsst/users/boutigny/conda_envs/desc_2/lib/python3.8/site-packages/distributed/worker.py", line 3419, in _get_data
    comm = await rpc.connect(worker)
  File "/sps/lsst/users/boutigny/conda_envs/desc_2/lib/python3.8/site-packages/distributed/core.py", line 1010, in connect
    comm = await connect(
  File "/sps/lsst/users/boutigny/conda_envs/desc_2/lib/python3.8/site-packages/distributed/comm/core.py", line 323, in connect
    raise IOError(
OSError: Timed out during handshake while connecting to tcp://134.158.168.195:41928 after 10 s
distributed.worker - ERROR - Worker stream died during communication: tcp://134.158.168.69:35839
Traceback (most recent call last):
  File "/sps/lsst/users/boutigny/conda_envs/desc_2/lib/python3.8/site-packages/tornado/iostream.py", line 867, in _read_to_buffer
    bytes_read = self.read_from_fd(buf)
  File "/sps/lsst/users/boutigny/conda_envs/desc_2/lib/python3.8/site-packages/tornado/iostream.py", line 1140, in read_from_fd
    return self.socket.recv_into(buf, len(buf))
ConnectionResetError: [Errno 104] Connection reset by peer

The above exception was the direct cause of the following exception:

Traceback (most recent call last):
  File "/sps/lsst/users/boutigny/conda_envs/desc_2/lib/python3.8/site-packages/distributed/comm/core.py", line 318, in connect
    handshake = await asyncio.wait_for(comm.read(), time_left())
  File "/sps/lsst/users/boutigny/conda_envs/desc_2/lib/python3.8/asyncio/tasks.py", line 494, in wait_for
    return fut.result()
  File "/sps/lsst/users/boutigny/conda_envs/desc_2/lib/python3.8/site-packages/distributed/comm/tcp.py", line 206, in read
    convert_stream_closed_error(self, e)
  File "/sps/lsst/users/boutigny/conda_envs/desc_2/lib/python3.8/site-packages/distributed/comm/tcp.py", line 124, in convert_stream_closed_error
    raise CommClosedError(
distributed.comm.core.CommClosedError: in <closed TCP>: ConnectionResetError: [Errno 104] Connection reset by peer

The above exception was the direct cause of the following exception:

Traceback (most recent call last):
  File "/sps/lsst/users/boutigny/conda_envs/desc_2/lib/python3.8/site-packages/distributed/worker.py", line 2169, in gather_dep
    response = await get_data_from_worker(
  File "/sps/lsst/users/boutigny/conda_envs/desc_2/lib/python3.8/site-packages/distributed/worker.py", line 3442, in get_data_from_worker
    return await retry_operation(_get_data, operation="get_data_from_worker")
  File "/sps/lsst/users/boutigny/conda_envs/desc_2/lib/python3.8/site-packages/distributed/utils_comm.py", line 385, in retry_operation
    return await retry(
  File "/sps/lsst/users/boutigny/conda_envs/desc_2/lib/python3.8/site-packages/distributed/utils_comm.py", line 370, in retry
    return await coro()
  File "/sps/lsst/users/boutigny/conda_envs/desc_2/lib/python3.8/site-packages/distributed/worker.py", line 3419, in _get_data
    comm = await rpc.connect(worker)
  File "/sps/lsst/users/boutigny/conda_envs/desc_2/lib/python3.8/site-packages/distributed/core.py", line 1010, in connect
    comm = await connect(
  File "/sps/lsst/users/boutigny/conda_envs/desc_2/lib/python3.8/site-packages/distributed/comm/core.py", line 323, in connect
    raise IOError(
OSError: Timed out during handshake while connecting to tcp://134.158.168.69:35839 after 10 s
distributed.worker - INFO - Can't find dependencies for key ('fix-overlap-and_-a2c92d0a7b4404ef4989bfc49cea49a2', 163)
distributed.worker - INFO - Dependent not found: ('set_index-de5055cf7981b50e2b876d80000d7d25', 162) 0 .  Asking scheduler
distributed.nanny - WARNING - Worker exceeded 95% memory budget. Restarting
distributed.nanny - WARNING - Worker exceeded 95% memory budget. Restarting
distributed.nanny - WARNING - Worker exceeded 95% memory budget. Restarting
distributed.nanny - WARNING - Worker exceeded 95% memory budget. Restarting
distributed.nanny - INFO - Worker process 46337 was killed by signal 15
distributed.nanny - WARNING - Restarting worker
distributed.worker - INFO -       Start worker at: tcp://134.158.168.221:46175
distributed.worker - INFO -          Listening to: tcp://134.158.168.221:46175
distributed.worker - INFO -          dashboard at:      134.158.168.221:44732
distributed.worker - INFO - Waiting to connect to:  tcp://134.158.48.24:35668
distributed.worker - INFO - -------------------------------------------------
distributed.worker - INFO -               Threads:                          1
distributed.worker - INFO -                Memory:                   4.60 GiB
distributed.worker - INFO -       Local Directory: /pbs/throng/lsst/users/boutigny/LSST_notebooks/Dask/dask-worker-space/worker-9u6fm7ie
distributed.worker - INFO - -------------------------------------------------
distributed.worker - INFO -         Registered to:  tcp://134.158.48.24:35668
distributed.worker - INFO - -------------------------------------------------
distributed.core - INFO - Starting established connection
distributed.worker - ERROR - Worker stream died during communication: tcp://134.158.168.180:36187
Traceback (most recent call last):
  File "/sps/lsst/users/boutigny/conda_envs/desc_2/lib/python3.8/site-packages/distributed/comm/tcp.py", line 196, in read
    frames_nbytes = await stream.read_bytes(fmt_size)
tornado.iostream.StreamClosedError: Stream is closed

The above exception was the direct cause of the following exception:

Traceback (most recent call last):
  File "/sps/lsst/users/boutigny/conda_envs/desc_2/lib/python3.8/site-packages/distributed/worker.py", line 2169, in gather_dep
    response = await get_data_from_worker(
  File "/sps/lsst/users/boutigny/conda_envs/desc_2/lib/python3.8/site-packages/distributed/worker.py", line 3442, in get_data_from_worker
    return await retry_operation(_get_data, operation="get_data_from_worker")
  File "/sps/lsst/users/boutigny/conda_envs/desc_2/lib/python3.8/site-packages/distributed/utils_comm.py", line 385, in retry_operation
    return await retry(
  File "/sps/lsst/users/boutigny/conda_envs/desc_2/lib/python3.8/site-packages/distributed/utils_comm.py", line 370, in retry
    return await coro()
  File "/sps/lsst/users/boutigny/conda_envs/desc_2/lib/python3.8/site-packages/distributed/worker.py", line 3422, in _get_data
    response = await send_recv(
  File "/sps/lsst/users/boutigny/conda_envs/desc_2/lib/python3.8/site-packages/distributed/core.py", line 645, in send_recv
    response = await comm.read(deserializers=deserializers)
  File "/sps/lsst/users/boutigny/conda_envs/desc_2/lib/python3.8/site-packages/distributed/comm/tcp.py", line 206, in read
    convert_stream_closed_error(self, e)
  File "/sps/lsst/users/boutigny/conda_envs/desc_2/lib/python3.8/site-packages/distributed/comm/tcp.py", line 128, in convert_stream_closed_error
    raise CommClosedError("in %s: %s" % (obj, exc)) from exc
distributed.comm.core.CommClosedError: in <closed TCP>: Stream is closed
distributed.worker - INFO - Can't find dependencies for key ('fix-overlap-and_-a2c92d0a7b4404ef4989bfc49cea49a2', 54)
distributed.worker - INFO - Dependent not found: ('set_index-de5055cf7981b50e2b876d80000d7d25', 54) 0 .  Asking scheduler
distributed.worker - WARNING - Worker is at 82% memory usage. Pausing worker.  Process memory: 3.81 GiB -- Worker memory limit: 4.60 GiB
distributed.nanny - WARNING - Worker exceeded 95% memory budget. Restarting
distributed.nanny - INFO - Worker process 47384 was killed by signal 15
distributed.nanny - WARNING - Restarting worker
distributed.worker - INFO -       Start worker at: tcp://134.158.168.221:37107
distributed.worker - INFO -          Listening to: tcp://134.158.168.221:37107
distributed.worker - INFO -          dashboard at:      134.158.168.221:34399
distributed.worker - INFO - Waiting to connect to:  tcp://134.158.48.24:35668
distributed.worker - INFO - -------------------------------------------------
distributed.worker - INFO -               Threads:                          1
distributed.worker - INFO -                Memory:                   4.60 GiB
distributed.worker - INFO -       Local Directory: /pbs/throng/lsst/users/boutigny/LSST_notebooks/Dask/dask-worker-space/worker-1s3wip7n
distributed.worker - INFO - -------------------------------------------------
distributed.worker - INFO -         Registered to:  tcp://134.158.48.24:35668
distributed.worker - INFO - -------------------------------------------------
distributed.core - INFO - Starting established connection
distributed.utils_perf - INFO - full garbage collection released 506.82 MiB from 27 reference cycles (threshold: 9.54 MiB)
distributed.worker - WARNING - Worker is at 86% memory usage. Pausing worker.  Process memory: 3.98 GiB -- Worker memory limit: 4.60 GiB
distributed.worker - WARNING - Worker is at 51% memory usage. Resuming worker. Process memory: 2.39 GiB -- Worker memory limit: 4.60 GiB
distributed.worker - ERROR - failed during get data with tcp://134.158.168.221:37107 -> tcp://134.158.170.48:33384
Traceback (most recent call last):
  File "/sps/lsst/users/boutigny/conda_envs/desc_2/lib/python3.8/site-packages/tornado/iostream.py", line 867, in _read_to_buffer
    bytes_read = self.read_from_fd(buf)
  File "/sps/lsst/users/boutigny/conda_envs/desc_2/lib/python3.8/site-packages/tornado/iostream.py", line 1140, in read_from_fd
    return self.socket.recv_into(buf, len(buf))
ConnectionResetError: [Errno 104] Connection reset by peer

The above exception was the direct cause of the following exception:

Traceback (most recent call last):
  File "/sps/lsst/users/boutigny/conda_envs/desc_2/lib/python3.8/site-packages/distributed/worker.py", line 1366, in get_data
    response = await comm.read(deserializers=serializers)
  File "/sps/lsst/users/boutigny/conda_envs/desc_2/lib/python3.8/site-packages/distributed/comm/tcp.py", line 206, in read
    convert_stream_closed_error(self, e)
  File "/sps/lsst/users/boutigny/conda_envs/desc_2/lib/python3.8/site-packages/distributed/comm/tcp.py", line 124, in convert_stream_closed_error
    raise CommClosedError(
distributed.comm.core.CommClosedError: in <closed TCP>: ConnectionResetError: [Errno 104] Connection reset by peer
distributed.core - INFO - Lost connection to 'tcp://134.158.170.48:37106': in <closed TCP>: ConnectionResetError: [Errno 104] Connection reset by peer
distributed.worker - ERROR - failed during get data with tcp://134.158.168.221:37107 -> tcp://134.158.168.180:35841
Traceback (most recent call last):
  File "/sps/lsst/users/boutigny/conda_envs/desc_2/lib/python3.8/site-packages/tornado/iostream.py", line 867, in _read_to_buffer
    bytes_read = self.read_from_fd(buf)
  File "/sps/lsst/users/boutigny/conda_envs/desc_2/lib/python3.8/site-packages/tornado/iostream.py", line 1140, in read_from_fd
    return self.socket.recv_into(buf, len(buf))
ConnectionResetError: [Errno 104] Connection reset by peer

The above exception was the direct cause of the following exception:

Traceback (most recent call last):
  File "/sps/lsst/users/boutigny/conda_envs/desc_2/lib/python3.8/site-packages/distributed/worker.py", line 1366, in get_data
    response = await comm.read(deserializers=serializers)
  File "/sps/lsst/users/boutigny/conda_envs/desc_2/lib/python3.8/site-packages/distributed/comm/tcp.py", line 206, in read
    convert_stream_closed_error(self, e)
  File "/sps/lsst/users/boutigny/conda_envs/desc_2/lib/python3.8/site-packages/distributed/comm/tcp.py", line 124, in convert_stream_closed_error
    raise CommClosedError(
distributed.comm.core.CommClosedError: in <closed TCP>: ConnectionResetError: [Errno 104] Connection reset by peer
distributed.core - INFO - Lost connection to 'tcp://134.158.168.180:39126': in <closed TCP>: ConnectionResetError: [Errno 104] Connection reset by peer
distributed.worker - ERROR - failed during get data with tcp://134.158.168.221:37107 -> tcp://134.158.168.188:45032
Traceback (most recent call last):
  File "/sps/lsst/users/boutigny/conda_envs/desc_2/lib/python3.8/site-packages/tornado/iostream.py", line 867, in _read_to_buffer
    bytes_read = self.read_from_fd(buf)
  File "/sps/lsst/users/boutigny/conda_envs/desc_2/lib/python3.8/site-packages/tornado/iostream.py", line 1140, in read_from_fd
    return self.socket.recv_into(buf, len(buf))
ConnectionResetError: [Errno 104] Connection reset by peer

The above exception was the direct cause of the following exception:

Traceback (most recent call last):
  File "/sps/lsst/users/boutigny/conda_envs/desc_2/lib/python3.8/site-packages/distributed/worker.py", line 1366, in get_data
    response = await comm.read(deserializers=serializers)
  File "/sps/lsst/users/boutigny/conda_envs/desc_2/lib/python3.8/site-packages/distributed/comm/tcp.py", line 206, in read
    convert_stream_closed_error(self, e)
  File "/sps/lsst/users/boutigny/conda_envs/desc_2/lib/python3.8/site-packages/distributed/comm/tcp.py", line 124, in convert_stream_closed_error
    raise CommClosedError(
distributed.comm.core.CommClosedError: in <closed TCP>: ConnectionResetError: [Errno 104] Connection reset by peer
distributed.core - INFO - Lost connection to 'tcp://134.158.168.188:55096': in <closed TCP>: ConnectionResetError: [Errno 104] Connection reset by peer
distributed.utils_perf - INFO - full garbage collection released 564.72 MiB from 48 reference cycles (threshold: 9.54 MiB)
distributed.worker - WARNING - Memory use is high but worker has no data to store to disk.  Perhaps some other process is leaking memory?  Process memory: 2.82 GiB -- Worker memory limit: 4.60 GiB
distributed.comm.tcp - INFO - Connection closed before handshake completed
distributed.utils_perf - INFO - full garbage collection released 20.53 MiB from 23 reference cycles (threshold: 9.54 MiB)
distributed.worker - WARNING - Memory use is high but worker has no data to store to disk.  Perhaps some other process is leaking memory?  Process memory: 3.07 GiB -- Worker memory limit: 4.60 GiB
distributed.worker - WARNING - Memory use is high but worker has no data to store to disk.  Perhaps some other process is leaking memory?  Process memory: 3.45 GiB -- Worker memory limit: 4.60 GiB
distributed.worker - WARNING - Memory use is high but worker has no data to store to disk.  Perhaps some other process is leaking memory?  Process memory: 3.45 GiB -- Worker memory limit: 4.60 GiB
distributed.worker - WARNING - Worker is at 80% memory usage. Pausing worker.  Process memory: 3.69 GiB -- Worker memory limit: 4.60 GiB
distributed.worker - WARNING - Memory use is high but worker has no data to store to disk.  Perhaps some other process is leaking memory?  Process memory: 3.73 GiB -- Worker memory limit: 4.60 GiB
distributed.worker - WARNING - Memory use is high but worker has no data to store to disk.  Perhaps some other process is leaking memory?  Process memory: 3.74 GiB -- Worker memory limit: 4.60 GiB
distributed.worker - WARNING - Memory use is high but worker has no data to store to disk.  Perhaps some other process is leaking memory?  Process memory: 3.74 GiB -- Worker memory limit: 4.60 GiB
distributed.worker - WARNING - Memory use is high but worker has no data to store to disk.  Perhaps some other process is leaking memory?  Process memory: 3.74 GiB -- Worker memory limit: 4.60 GiB
distributed.worker - WARNING - Worker is at 77% memory usage. Resuming worker. Process memory: 3.56 GiB -- Worker memory limit: 4.60 GiB
distributed.worker - WARNING - Memory use is high but worker has no data to store to disk.  Perhaps some other process is leaking memory?  Process memory: 3.56 GiB -- Worker memory limit: 4.60 GiB
distributed.worker - WARNING - Memory use is high but worker has no data to store to disk.  Perhaps some other process is leaking memory?  Process memory: 3.56 GiB -- Worker memory limit: 4.60 GiB
distributed.worker - ERROR - Worker stream died during communication: tcp://134.158.168.225:34582
Traceback (most recent call last):
  File "/sps/lsst/users/boutigny/conda_envs/desc_2/lib/python3.8/site-packages/distributed/comm/tcp.py", line 200, in read
    n = await stream.read_into(frames)
tornado.iostream.StreamClosedError: Stream is closed

The above exception was the direct cause of the following exception:

Traceback (most recent call last):
  File "/sps/lsst/users/boutigny/conda_envs/desc_2/lib/python3.8/site-packages/distributed/worker.py", line 2169, in gather_dep
    response = await get_data_from_worker(
  File "/sps/lsst/users/boutigny/conda_envs/desc_2/lib/python3.8/site-packages/distributed/worker.py", line 3442, in get_data_from_worker
    return await retry_operation(_get_data, operation="get_data_from_worker")
  File "/sps/lsst/users/boutigny/conda_envs/desc_2/lib/python3.8/site-packages/distributed/utils_comm.py", line 385, in retry_operation
    return await retry(
  File "/sps/lsst/users/boutigny/conda_envs/desc_2/lib/python3.8/site-packages/distributed/utils_comm.py", line 370, in retry
    return await coro()
  File "/sps/lsst/users/boutigny/conda_envs/desc_2/lib/python3.8/site-packages/distributed/worker.py", line 3422, in _get_data
    response = await send_recv(
  File "/sps/lsst/users/boutigny/conda_envs/desc_2/lib/python3.8/site-packages/distributed/core.py", line 645, in send_recv
    response = await comm.read(deserializers=deserializers)
  File "/sps/lsst/users/boutigny/conda_envs/desc_2/lib/python3.8/site-packages/distributed/comm/tcp.py", line 206, in read
    convert_stream_closed_error(self, e)
  File "/sps/lsst/users/boutigny/conda_envs/desc_2/lib/python3.8/site-packages/distributed/comm/tcp.py", line 128, in convert_stream_closed_error
    raise CommClosedError("in %s: %s" % (obj, exc)) from exc
distributed.comm.core.CommClosedError: in <closed TCP>: Stream is closed
distributed.worker - WARNING - Memory use is high but worker has no data to store to disk.  Perhaps some other process is leaking memory?  Process memory: 3.57 GiB -- Worker memory limit: 4.60 GiB
distributed.worker - WARNING - Memory use is high but worker has no data to store to disk.  Perhaps some other process is leaking memory?  Process memory: 3.55 GiB -- Worker memory limit: 4.60 GiB
distributed.worker - WARNING - Memory use is high but worker has no data to store to disk.  Perhaps some other process is leaking memory?  Process memory: 3.58 GiB -- Worker memory limit: 4.60 GiB
distributed.worker - WARNING - Memory use is high but worker has no data to store to disk.  Perhaps some other process is leaking memory?  Process memory: 3.58 GiB -- Worker memory limit: 4.60 GiB
distributed.worker - WARNING - Memory use is high but worker has no data to store to disk.  Perhaps some other process is leaking memory?  Process memory: 3.58 GiB -- Worker memory limit: 4.60 GiB
distributed.worker - WARNING - Memory use is high but worker has no data to store to disk.  Perhaps some other process is leaking memory?  Process memory: 3.58 GiB -- Worker memory limit: 4.60 GiB
distributed.worker - WARNING - Memory use is high but worker has no data to store to disk.  Perhaps some other process is leaking memory?  Process memory: 3.58 GiB -- Worker memory limit: 4.60 GiB
distributed.worker - WARNING - Memory use is high but worker has no data to store to disk.  Perhaps some other process is leaking memory?  Process memory: 3.58 GiB -- Worker memory limit: 4.60 GiB
distributed.worker - WARNING - Memory use is high but worker has no data to store to disk.  Perhaps some other process is leaking memory?  Process memory: 3.25 GiB -- Worker memory limit: 4.60 GiB
distributed.worker - WARNING - Memory use is high but worker has no data to store to disk.  Perhaps some other process is leaking memory?  Process memory: 3.27 GiB -- Worker memory limit: 4.60 GiB
distributed.worker - WARNING - Memory use is high but worker has no data to store to disk.  Perhaps some other process is leaking memory?  Process memory: 3.27 GiB -- Worker memory limit: 4.60 GiB
distributed.worker - WARNING - Memory use is high but worker has no data to store to disk.  Perhaps some other process is leaking memory?  Process memory: 3.33 GiB -- Worker memory limit: 4.60 GiB
distributed.worker - WARNING - Memory use is high but worker has no data to store to disk.  Perhaps some other process is leaking memory?  Process memory: 3.35 GiB -- Worker memory limit: 4.60 GiB
distributed.worker - WARNING - Memory use is high but worker has no data to store to disk.  Perhaps some other process is leaking memory?  Process memory: 3.36 GiB -- Worker memory limit: 4.60 GiB
distributed.worker - ERROR - Worker stream died during communication: tcp://134.158.170.39:33102
Traceback (most recent call last):
  File "/sps/lsst/users/boutigny/conda_envs/desc_2/lib/python3.8/site-packages/distributed/comm/tcp.py", line 200, in read
    n = await stream.read_into(frames)
tornado.iostream.StreamClosedError: Stream is closed

The above exception was the direct cause of the following exception:

Traceback (most recent call last):
  File "/sps/lsst/users/boutigny/conda_envs/desc_2/lib/python3.8/site-packages/distributed/worker.py", line 2169, in gather_dep
    response = await get_data_from_worker(
  File "/sps/lsst/users/boutigny/conda_envs/desc_2/lib/python3.8/site-packages/distributed/worker.py", line 3442, in get_data_from_worker
    return await retry_operation(_get_data, operation="get_data_from_worker")
  File "/sps/lsst/users/boutigny/conda_envs/desc_2/lib/python3.8/site-packages/distributed/utils_comm.py", line 385, in retry_operation
    return await retry(
  File "/sps/lsst/users/boutigny/conda_envs/desc_2/lib/python3.8/site-packages/distributed/utils_comm.py", line 370, in retry
    return await coro()
  File "/sps/lsst/users/boutigny/conda_envs/desc_2/lib/python3.8/site-packages/distributed/worker.py", line 3422, in _get_data
    response = await send_recv(
  File "/sps/lsst/users/boutigny/conda_envs/desc_2/lib/python3.8/site-packages/distributed/core.py", line 645, in send_recv
    response = await comm.read(deserializers=deserializers)
  File "/sps/lsst/users/boutigny/conda_envs/desc_2/lib/python3.8/site-packages/distributed/comm/tcp.py", line 206, in read
    convert_stream_closed_error(self, e)
  File "/sps/lsst/users/boutigny/conda_envs/desc_2/lib/python3.8/site-packages/distributed/comm/tcp.py", line 128, in convert_stream_closed_error
    raise CommClosedError("in %s: %s" % (obj, exc)) from exc
distributed.comm.core.CommClosedError: in <closed TCP>: Stream is closed
distributed.worker - INFO - Can't find dependencies for key ('fix-overlap-and_-a2c92d0a7b4404ef4989bfc49cea49a2', 130)
distributed.worker - INFO - Dependent not found: ('set_index-de5055cf7981b50e2b876d80000d7d25', 130) 0 .  Asking scheduler
distributed.worker - WARNING - Memory use is high but worker has no data to store to disk.  Perhaps some other process is leaking memory?  Process memory: 3.39 GiB -- Worker memory limit: 4.60 GiB
distributed.worker - WARNING - Memory use is high but worker has no data to store to disk.  Perhaps some other process is leaking memory?  Process memory: 3.40 GiB -- Worker memory limit: 4.60 GiB
distributed.worker - WARNING - Memory use is high but worker has no data to store to disk.  Perhaps some other process is leaking memory?  Process memory: 3.42 GiB -- Worker memory limit: 4.60 GiB
distributed.worker - WARNING - Memory use is high but worker has no data to store to disk.  Perhaps some other process is leaking memory?  Process memory: 3.42 GiB -- Worker memory limit: 4.60 GiB
distributed.worker - WARNING - Memory use is high but worker has no data to store to disk.  Perhaps some other process is leaking memory?  Process memory: 3.42 GiB -- Worker memory limit: 4.60 GiB
distributed.worker - WARNING - Memory use is high but worker has no data to store to disk.  Perhaps some other process is leaking memory?  Process memory: 3.42 GiB -- Worker memory limit: 4.60 GiB
distributed.worker - WARNING - Memory use is high but worker has no data to store to disk.  Perhaps some other process is leaking memory?  Process memory: 3.42 GiB -- Worker memory limit: 4.60 GiB
distributed.worker - WARNING - Memory use is high but worker has no data to store to disk.  Perhaps some other process is leaking memory?  Process memory: 3.42 GiB -- Worker memory limit: 4.60 GiB
distributed.worker - WARNING - Memory use is high but worker has no data to store to disk.  Perhaps some other process is leaking memory?  Process memory: 3.42 GiB -- Worker memory limit: 4.60 GiB
distributed.worker - WARNING - Memory use is high but worker has no data to store to disk.  Perhaps some other process is leaking memory?  Process memory: 3.42 GiB -- Worker memory limit: 4.60 GiB
distributed.worker - WARNING - Memory use is high but worker has no data to store to disk.  Perhaps some other process is leaking memory?  Process memory: 3.47 GiB -- Worker memory limit: 4.60 GiB
distributed.worker - WARNING - Memory use is high but worker has no data to store to disk.  Perhaps some other process is leaking memory?  Process memory: 3.50 GiB -- Worker memory limit: 4.60 GiB
distributed.worker - WARNING - Memory use is high but worker has no data to store to disk.  Perhaps some other process is leaking memory?  Process memory: 3.51 GiB -- Worker memory limit: 4.60 GiB
distributed.worker - WARNING - Memory use is high but worker has no data to store to disk.  Perhaps some other process is leaking memory?  Process memory: 3.52 GiB -- Worker memory limit: 4.60 GiB
distributed.worker - WARNING - Memory use is high but worker has no data to store to disk.  Perhaps some other process is leaking memory?  Process memory: 3.54 GiB -- Worker memory limit: 4.60 GiB
distributed.worker - WARNING - Memory use is high but worker has no data to store to disk.  Perhaps some other process is leaking memory?  Process memory: 3.54 GiB -- Worker memory limit: 4.60 GiB
distributed.worker - WARNING - Memory use is high but worker has no data to store to disk.  Perhaps some other process is leaking memory?  Process memory: 3.57 GiB -- Worker memory limit: 4.60 GiB
distributed.worker - WARNING - Memory use is high but worker has no data to store to disk.  Perhaps some other process is leaking memory?  Process memory: 3.57 GiB -- Worker memory limit: 4.60 GiB
distributed.worker - WARNING - Memory use is high but worker has no data to store to disk.  Perhaps some other process is leaking memory?  Process memory: 3.57 GiB -- Worker memory limit: 4.60 GiB
distributed.worker - WARNING - Memory use is high but worker has no data to store to disk.  Perhaps some other process is leaking memory?  Process memory: 3.58 GiB -- Worker memory limit: 4.60 GiB
distributed.worker - WARNING - Memory use is high but worker has no data to store to disk.  Perhaps some other process is leaking memory?  Process memory: 3.59 GiB -- Worker memory limit: 4.60 GiB
distributed.worker - WARNING - Worker is at 82% memory usage. Pausing worker.  Process memory: 3.79 GiB -- Worker memory limit: 4.60 GiB
distributed.worker - WARNING - Memory use is high but worker has no data to store to disk.  Perhaps some other process is leaking memory?  Process memory: 3.79 GiB -- Worker memory limit: 4.60 GiB
distributed.nanny - WARNING - Worker exceeded 95% memory budget. Restarting
distributed.nanny - INFO - Worker process 47414 was killed by signal 15
distributed.nanny - WARNING - Restarting worker
/sps/lsst/users/boutigny/conda_envs/desc_2/lib/python3.8/contextlib.py:120: UserWarning: Creating scratch directories is taking a surprisingly long time. This is often due to running workers on a network file system. Consider specifying a local-directory to point workers to write scratch data to a local disk.
  next(self.gen)
distributed.worker - INFO -       Start worker at: tcp://134.158.168.221:37796
distributed.worker - INFO -          Listening to: tcp://134.158.168.221:37796
distributed.worker - INFO -          dashboard at:      134.158.168.221:33323
distributed.worker - INFO - Waiting to connect to:  tcp://134.158.48.24:35668
distributed.worker - INFO - -------------------------------------------------
distributed.worker - INFO -               Threads:                          1
distributed.worker - INFO -                Memory:                   4.60 GiB
distributed.worker - INFO -       Local Directory: /pbs/throng/lsst/users/boutigny/LSST_notebooks/Dask/dask-worker-space/worker-gf3008ki
distributed.worker - INFO - -------------------------------------------------
distributed.worker - INFO -         Registered to:  tcp://134.158.48.24:35668
distributed.worker - INFO - -------------------------------------------------
distributed.core - INFO - Starting established connection
distributed.nanny - WARNING - Worker exceeded 95% memory budget. Restarting
distributed.nanny - INFO - Worker process 48202 was killed by signal 15
distributed.nanny - WARNING - Restarting worker
distributed.worker - INFO -       Start worker at: tcp://134.158.168.221:45158
distributed.worker - INFO -          Listening to: tcp://134.158.168.221:45158
distributed.worker - INFO -          dashboard at:      134.158.168.221:44119
distributed.worker - INFO - Waiting to connect to:  tcp://134.158.48.24:35668
distributed.worker - INFO - -------------------------------------------------
distributed.worker - INFO -               Threads:                          1
distributed.worker - INFO -                Memory:                   4.60 GiB
distributed.worker - INFO -       Local Directory: /pbs/throng/lsst/users/boutigny/LSST_notebooks/Dask/dask-worker-space/worker-_fujmzxk
distributed.worker - INFO - -------------------------------------------------
distributed.worker - INFO -         Registered to:  tcp://134.158.48.24:35668
distributed.worker - INFO - -------------------------------------------------
distributed.core - INFO - Starting established connection
distributed.utils_perf - INFO - full garbage collection released 489.50 MiB from 56 reference cycles (threshold: 9.54 MiB)
distributed.core - INFO - Event loop was unresponsive in Worker for 4.58s.  This is often caused by long-running GIL-holding functions or moving large chunks of data. This can cause timeouts and instability.
distributed.worker - ERROR - Worker stream died during communication: tcp://134.158.171.73:33081
Traceback (most recent call last):
  File "/sps/lsst/users/boutigny/conda_envs/desc_2/lib/python3.8/site-packages/distributed/comm/tcp.py", line 200, in read
    n = await stream.read_into(frames)
tornado.iostream.StreamClosedError: Stream is closed

The above exception was the direct cause of the following exception:

Traceback (most recent call last):
  File "/sps/lsst/users/boutigny/conda_envs/desc_2/lib/python3.8/site-packages/distributed/worker.py", line 2169, in gather_dep
    response = await get_data_from_worker(
  File "/sps/lsst/users/boutigny/conda_envs/desc_2/lib/python3.8/site-packages/distributed/worker.py", line 3442, in get_data_from_worker
    return await retry_operation(_get_data, operation="get_data_from_worker")
  File "/sps/lsst/users/boutigny/conda_envs/desc_2/lib/python3.8/site-packages/distributed/utils_comm.py", line 385, in retry_operation
    return await retry(
  File "/sps/lsst/users/boutigny/conda_envs/desc_2/lib/python3.8/site-packages/distributed/utils_comm.py", line 370, in retry
    return await coro()
  File "/sps/lsst/users/boutigny/conda_envs/desc_2/lib/python3.8/site-packages/distributed/worker.py", line 3422, in _get_data
    response = await send_recv(
  File "/sps/lsst/users/boutigny/conda_envs/desc_2/lib/python3.8/site-packages/distributed/core.py", line 645, in send_recv
    response = await comm.read(deserializers=deserializers)
  File "/sps/lsst/users/boutigny/conda_envs/desc_2/lib/python3.8/site-packages/distributed/comm/tcp.py", line 206, in read
    convert_stream_closed_error(self, e)
  File "/sps/lsst/users/boutigny/conda_envs/desc_2/lib/python3.8/site-packages/distributed/comm/tcp.py", line 128, in convert_stream_closed_error
    raise CommClosedError("in %s: %s" % (obj, exc)) from exc
distributed.comm.core.CommClosedError: in <closed TCP>: Stream is closed
distributed.utils_perf - INFO - full garbage collection released 528.97 MiB from 81 reference cycles (threshold: 9.54 MiB)
distributed.comm.tcp - INFO - Connection closed before handshake completed
distributed.worker - ERROR - failed during get data with tcp://134.158.168.221:45158 -> tcp://134.158.168.65:34312
Traceback (most recent call last):
  File "/sps/lsst/users/boutigny/conda_envs/desc_2/lib/python3.8/site-packages/tornado/iostream.py", line 867, in _read_to_buffer
    bytes_read = self.read_from_fd(buf)
  File "/sps/lsst/users/boutigny/conda_envs/desc_2/lib/python3.8/site-packages/tornado/iostream.py", line 1140, in read_from_fd
    return self.socket.recv_into(buf, len(buf))
ConnectionResetError: [Errno 104] Connection reset by peer

The above exception was the direct cause of the following exception:

Traceback (most recent call last):
  File "/sps/lsst/users/boutigny/conda_envs/desc_2/lib/python3.8/site-packages/distributed/worker.py", line 1366, in get_data
    response = await comm.read(deserializers=serializers)
  File "/sps/lsst/users/boutigny/conda_envs/desc_2/lib/python3.8/site-packages/distributed/comm/tcp.py", line 206, in read
    convert_stream_closed_error(self, e)
  File "/sps/lsst/users/boutigny/conda_envs/desc_2/lib/python3.8/site-packages/distributed/comm/tcp.py", line 124, in convert_stream_closed_error
    raise CommClosedError(
distributed.comm.core.CommClosedError: in <closed TCP>: ConnectionResetError: [Errno 104] Connection reset by peer
distributed.core - INFO - Lost connection to 'tcp://134.158.168.65:57512': in <closed TCP>: ConnectionResetError: [Errno 104] Connection reset by peer
distributed.worker - ERROR - failed during get data with tcp://134.158.168.221:45158 -> tcp://134.158.170.49:35177
Traceback (most recent call last):
  File "/sps/lsst/users/boutigny/conda_envs/desc_2/lib/python3.8/site-packages/tornado/iostream.py", line 867, in _read_to_buffer
    bytes_read = self.read_from_fd(buf)
  File "/sps/lsst/users/boutigny/conda_envs/desc_2/lib/python3.8/site-packages/tornado/iostream.py", line 1140, in read_from_fd
    return self.socket.recv_into(buf, len(buf))
ConnectionResetError: [Errno 104] Connection reset by peer

The above exception was the direct cause of the following exception:

Traceback (most recent call last):
  File "/sps/lsst/users/boutigny/conda_envs/desc_2/lib/python3.8/site-packages/distributed/worker.py", line 1366, in get_data
    response = await comm.read(deserializers=serializers)
  File "/sps/lsst/users/boutigny/conda_envs/desc_2/lib/python3.8/site-packages/distributed/comm/tcp.py", line 206, in read
    convert_stream_closed_error(self, e)
  File "/sps/lsst/users/boutigny/conda_envs/desc_2/lib/python3.8/site-packages/distributed/comm/tcp.py", line 124, in convert_stream_closed_error
    raise CommClosedError(
distributed.comm.core.CommClosedError: in <closed TCP>: ConnectionResetError: [Errno 104] Connection reset by peer
distributed.core - INFO - Lost connection to 'tcp://134.158.170.49:59344': in <closed TCP>: ConnectionResetError: [Errno 104] Connection reset by peer
distributed.worker - ERROR - Worker stream died during communication: tcp://134.158.170.59:43828
Traceback (most recent call last):
  File "/sps/lsst/users/boutigny/conda_envs/desc_2/lib/python3.8/site-packages/distributed/comm/tcp.py", line 266, in write
    raise StreamClosedError()
tornado.iostream.StreamClosedError: Stream is closed

The above exception was the direct cause of the following exception:

Traceback (most recent call last):
  File "/sps/lsst/users/boutigny/conda_envs/desc_2/lib/python3.8/site-packages/distributed/comm/core.py", line 319, in connect
    await asyncio.wait_for(comm.write(local_info), time_left())
  File "/sps/lsst/users/boutigny/conda_envs/desc_2/lib/python3.8/asyncio/tasks.py", line 494, in wait_for
    return fut.result()
  File "/sps/lsst/users/boutigny/conda_envs/desc_2/lib/python3.8/site-packages/distributed/comm/tcp.py", line 282, in write
    convert_stream_closed_error(self, e)
  File "/sps/lsst/users/boutigny/conda_envs/desc_2/lib/python3.8/site-packages/distributed/comm/tcp.py", line 128, in convert_stream_closed_error
    raise CommClosedError("in %s: %s" % (obj, exc)) from exc
distributed.comm.core.CommClosedError: in <closed TCP>: Stream is closed

The above exception was the direct cause of the following exception:

Traceback (most recent call last):
  File "/sps/lsst/users/boutigny/conda_envs/desc_2/lib/python3.8/site-packages/distributed/worker.py", line 2169, in gather_dep
    response = await get_data_from_worker(
  File "/sps/lsst/users/boutigny/conda_envs/desc_2/lib/python3.8/site-packages/distributed/worker.py", line 3442, in get_data_from_worker
    return await retry_operation(_get_data, operation="get_data_from_worker")
  File "/sps/lsst/users/boutigny/conda_envs/desc_2/lib/python3.8/site-packages/distributed/utils_comm.py", line 385, in retry_operation
    return await retry(
  File "/sps/lsst/users/boutigny/conda_envs/desc_2/lib/python3.8/site-packages/distributed/utils_comm.py", line 370, in retry
    return await coro()
  File "/sps/lsst/users/boutigny/conda_envs/desc_2/lib/python3.8/site-packages/distributed/worker.py", line 3419, in _get_data
    comm = await rpc.connect(worker)
  File "/sps/lsst/users/boutigny/conda_envs/desc_2/lib/python3.8/site-packages/distributed/core.py", line 1010, in connect
    comm = await connect(
  File "/sps/lsst/users/boutigny/conda_envs/desc_2/lib/python3.8/site-packages/distributed/comm/core.py", line 323, in connect
    raise IOError(
OSError: Timed out during handshake while connecting to tcp://134.158.170.59:43828 after 10 s
distributed.worker - WARNING - Worker is at 81% memory usage. Pausing worker.  Process memory: 3.74 GiB -- Worker memory limit: 4.60 GiB
distributed.worker - WARNING - Memory use is high but worker has no data to store to disk.  Perhaps some other process is leaking memory?  Process memory: 3.74 GiB -- Worker memory limit: 4.60 GiB
distributed.worker - WARNING - Memory use is high but worker has no data to store to disk.  Perhaps some other process is leaking memory?  Process memory: 3.93 GiB -- Worker memory limit: 4.60 GiB
distributed.worker - WARNING - Worker is at 79% memory usage. Resuming worker. Process memory: 3.65 GiB -- Worker memory limit: 4.60 GiB
distributed.worker - WARNING - Memory use is high but worker has no data to store to disk.  Perhaps some other process is leaking memory?  Process memory: 3.65 GiB -- Worker memory limit: 4.60 GiB
distributed.utils_perf - INFO - full garbage collection released 506.80 MiB from 48 reference cycles (threshold: 9.54 MiB)
distributed.utils_perf - INFO - full garbage collection released 17.05 MiB from 0 reference cycles (threshold: 9.54 MiB)
distributed.worker - WARNING - Memory use is high but worker has no data to store to disk.  Perhaps some other process is leaking memory?  Process memory: 3.30 GiB -- Worker memory limit: 4.60 GiB
distributed.worker - WARNING - Memory use is high but worker has no data to store to disk.  Perhaps some other process is leaking memory?  Process memory: 3.30 GiB -- Worker memory limit: 4.60 GiB
distributed.worker - WARNING - Memory use is high but worker has no data to store to disk.  Perhaps some other process is leaking memory?  Process memory: 3.69 GiB -- Worker memory limit: 4.60 GiB
distributed.utils_perf - INFO - full garbage collection released 10.59 MiB from 0 reference cycles (threshold: 9.54 MiB)
distributed.worker - WARNING - Worker is at 80% memory usage. Pausing worker.  Process memory: 3.69 GiB -- Worker memory limit: 4.60 GiB
distributed.worker - WARNING - Worker is at 79% memory usage. Resuming worker. Process memory: 3.68 GiB -- Worker memory limit: 4.60 GiB
distributed.worker - WARNING - Memory use is high but worker has no data to store to disk.  Perhaps some other process is leaking memory?  Process memory: 3.68 GiB -- Worker memory limit: 4.60 GiB
distributed.worker - WARNING - Worker is at 80% memory usage. Pausing worker.  Process memory: 3.70 GiB -- Worker memory limit: 4.60 GiB
distributed.worker - WARNING - Memory use is high but worker has no data to store to disk.  Perhaps some other process is leaking memory?  Process memory: 3.70 GiB -- Worker memory limit: 4.60 GiB
distributed.worker - WARNING - Memory use is high but worker has no data to store to disk.  Perhaps some other process is leaking memory?  Process memory: 3.70 GiB -- Worker memory limit: 4.60 GiB
distributed.worker - WARNING - Memory use is high but worker has no data to store to disk.  Perhaps some other process is leaking memory?  Process memory: 3.72 GiB -- Worker memory limit: 4.60 GiB
distributed.worker - WARNING - Memory use is high but worker has no data to store to disk.  Perhaps some other process is leaking memory?  Process memory: 3.69 GiB -- Worker memory limit: 4.60 GiB
distributed.worker - WARNING - Memory use is high but worker has no data to store to disk.  Perhaps some other process is leaking memory?  Process memory: 4.01 GiB -- Worker memory limit: 4.60 GiB
distributed.nanny - WARNING - Worker exceeded 95% memory budget. Restarting
distributed.nanny - INFO - Worker process 48234 was killed by signal 15
distributed.nanny - WARNING - Restarting worker
distributed.worker - INFO -       Start worker at: tcp://134.158.168.221:38042
distributed.worker - INFO -          Listening to: tcp://134.158.168.221:38042
distributed.worker - INFO -          dashboard at:      134.158.168.221:36560
distributed.worker - INFO - Waiting to connect to:  tcp://134.158.48.24:35668
distributed.worker - INFO - -------------------------------------------------
distributed.worker - INFO -               Threads:                          1
distributed.worker - INFO -                Memory:                   4.60 GiB
distributed.worker - INFO -       Local Directory: /pbs/throng/lsst/users/boutigny/LSST_notebooks/Dask/dask-worker-space/worker-j1upn3ne
distributed.worker - INFO - -------------------------------------------------
distributed.worker - INFO -         Registered to:  tcp://134.158.48.24:35668
distributed.worker - INFO - -------------------------------------------------
distributed.core - INFO - Starting established connection
distributed.utils_perf - INFO - full garbage collection released 364.45 MiB from 0 reference cycles (threshold: 9.54 MiB)
distributed.worker - WARNING - Worker is at 84% memory usage. Pausing worker.  Process memory: 3.86 GiB -- Worker memory limit: 4.60 GiB
distributed.worker - WARNING - Worker is at 47% memory usage. Resuming worker. Process memory: 2.20 GiB -- Worker memory limit: 4.60 GiB
distributed.worker - ERROR - Worker stream died during communication: tcp://134.158.170.37:45889
Traceback (most recent call last):
  File "/sps/lsst/users/boutigny/conda_envs/desc_2/lib/python3.8/site-packages/distributed/comm/tcp.py", line 200, in read
    n = await stream.read_into(frames)
tornado.iostream.StreamClosedError: Stream is closed

The above exception was the direct cause of the following exception:

Traceback (most recent call last):
  File "/sps/lsst/users/boutigny/conda_envs/desc_2/lib/python3.8/site-packages/distributed/worker.py", line 2169, in gather_dep
    response = await get_data_from_worker(
  File "/sps/lsst/users/boutigny/conda_envs/desc_2/lib/python3.8/site-packages/distributed/worker.py", line 3442, in get_data_from_worker
    return await retry_operation(_get_data, operation="get_data_from_worker")
  File "/sps/lsst/users/boutigny/conda_envs/desc_2/lib/python3.8/site-packages/distributed/utils_comm.py", line 385, in retry_operation
    return await retry(
  File "/sps/lsst/users/boutigny/conda_envs/desc_2/lib/python3.8/site-packages/distributed/utils_comm.py", line 370, in retry
    return await coro()
  File "/sps/lsst/users/boutigny/conda_envs/desc_2/lib/python3.8/site-packages/distributed/worker.py", line 3422, in _get_data
    response = await send_recv(
  File "/sps/lsst/users/boutigny/conda_envs/desc_2/lib/python3.8/site-packages/distributed/core.py", line 645, in send_recv
    response = await comm.read(deserializers=deserializers)
  File "/sps/lsst/users/boutigny/conda_envs/desc_2/lib/python3.8/site-packages/distributed/comm/tcp.py", line 206, in read
    convert_stream_closed_error(self, e)
  File "/sps/lsst/users/boutigny/conda_envs/desc_2/lib/python3.8/site-packages/distributed/comm/tcp.py", line 128, in convert_stream_closed_error
    raise CommClosedError("in %s: %s" % (obj, exc)) from exc
distributed.comm.core.CommClosedError: in <closed TCP>: Stream is closed
distributed.worker - INFO - Can't find dependencies for key ('fix-overlap-and_-a2c92d0a7b4404ef4989bfc49cea49a2', 17)
distributed.worker - INFO - Dependent not found: ('set_index-de5055cf7981b50e2b876d80000d7d25', 16) 0 .  Asking scheduler
distributed.utils_perf - INFO - full garbage collection released 568.52 MiB from 81 reference cycles (threshold: 9.54 MiB)
distributed.utils_perf - INFO - full garbage collection released 492.39 MiB from 0 reference cycles (threshold: 9.54 MiB)
distributed.nanny - WARNING - Worker exceeded 95% memory budget. Restarting
distributed.nanny - WARNING - Worker exceeded 95% memory budget. Restarting
distributed.nanny - WARNING - Worker exceeded 95% memory budget. Restarting
distributed.nanny - WARNING - Worker exceeded 95% memory budget. Restarting
distributed.nanny - WARNING - Worker exceeded 95% memory budget. Restarting
distributed.nanny - WARNING - Worker exceeded 95% memory budget. Restarting
distributed.nanny - WARNING - Worker exceeded 95% memory budget. Restarting
distributed.nanny - WARNING - Worker exceeded 95% memory budget. Restarting
distributed.nanny - WARNING - Worker exceeded 95% memory budget. Restarting
distributed.nanny - WARNING - Worker exceeded 95% memory budget. Restarting
distributed.nanny - WARNING - Worker exceeded 95% memory budget. Restarting
distributed.nanny - WARNING - Worker exceeded 95% memory budget. Restarting
distributed.nanny - WARNING - Worker exceeded 95% memory budget. Restarting
distributed.nanny - WARNING - Worker exceeded 95% memory budget. Restarting
distributed.nanny - WARNING - Worker exceeded 95% memory budget. Restarting
distributed.nanny - INFO - Worker process 48648 was killed by signal 15
distributed.nanny - WARNING - Restarting worker
distributed.diskutils - INFO - Found stale lock file and directory '/pbs/throng/lsst/users/boutigny/LSST_notebooks/Dask/dask-worker-space/worker-1aitj2yj', purging
/sps/lsst/users/boutigny/conda_envs/desc_2/lib/python3.8/contextlib.py:120: UserWarning: Creating scratch directories is taking a surprisingly long time. This is often due to running workers on a network file system. Consider specifying a local-directory to point workers to write scratch data to a local disk.
  next(self.gen)
distributed.worker - INFO -       Start worker at: tcp://134.158.168.221:45447
distributed.worker - INFO -          Listening to: tcp://134.158.168.221:45447
distributed.worker - INFO -          dashboard at:      134.158.168.221:40540
distributed.worker - INFO - Waiting to connect to:  tcp://134.158.48.24:35668
distributed.worker - INFO - -------------------------------------------------
distributed.worker - INFO -               Threads:                          1
distributed.worker - INFO -                Memory:                   4.60 GiB
distributed.worker - INFO -       Local Directory: /pbs/throng/lsst/users/boutigny/LSST_notebooks/Dask/dask-worker-space/worker-wpvb_bgv
distributed.worker - INFO - -------------------------------------------------
distributed.worker - INFO -         Registered to:  tcp://134.158.48.24:35668
distributed.worker - INFO - -------------------------------------------------
distributed.core - INFO - Starting established connection
distributed.worker - ERROR - Worker stream died during communication: tcp://134.158.170.39:39583
Traceback (most recent call last):
  File "/sps/lsst/users/boutigny/conda_envs/desc_2/lib/python3.8/site-packages/distributed/comm/tcp.py", line 196, in read
    frames_nbytes = await stream.read_bytes(fmt_size)
tornado.iostream.StreamClosedError: Stream is closed

The above exception was the direct cause of the following exception:

Traceback (most recent call last):
  File "/sps/lsst/users/boutigny/conda_envs/desc_2/lib/python3.8/site-packages/distributed/comm/core.py", line 318, in connect
    handshake = await asyncio.wait_for(comm.read(), time_left())
  File "/sps/lsst/users/boutigny/conda_envs/desc_2/lib/python3.8/asyncio/tasks.py", line 494, in wait_for
    return fut.result()
  File "/sps/lsst/users/boutigny/conda_envs/desc_2/lib/python3.8/site-packages/distributed/comm/tcp.py", line 206, in read
    convert_stream_closed_error(self, e)
  File "/sps/lsst/users/boutigny/conda_envs/desc_2/lib/python3.8/site-packages/distributed/comm/tcp.py", line 128, in convert_stream_closed_error
    raise CommClosedError("in %s: %s" % (obj, exc)) from exc
distributed.comm.core.CommClosedError: in <closed TCP>: Stream is closed

The above exception was the direct cause of the following exception:

Traceback (most recent call last):
  File "/sps/lsst/users/boutigny/conda_envs/desc_2/lib/python3.8/site-packages/distributed/worker.py", line 2169, in gather_dep
    response = await get_data_from_worker(
  File "/sps/lsst/users/boutigny/conda_envs/desc_2/lib/python3.8/site-packages/distributed/worker.py", line 3442, in get_data_from_worker
    return await retry_operation(_get_data, operation="get_data_from_worker")
  File "/sps/lsst/users/boutigny/conda_envs/desc_2/lib/python3.8/site-packages/distributed/utils_comm.py", line 385, in retry_operation
    return await retry(
  File "/sps/lsst/users/boutigny/conda_envs/desc_2/lib/python3.8/site-packages/distributed/utils_comm.py", line 370, in retry
    return await coro()
  File "/sps/lsst/users/boutigny/conda_envs/desc_2/lib/python3.8/site-packages/distributed/worker.py", line 3419, in _get_data
    comm = await rpc.connect(worker)
  File "/sps/lsst/users/boutigny/conda_envs/desc_2/lib/python3.8/site-packages/distributed/core.py", line 1010, in connect
    comm = await connect(
  File "/sps/lsst/users/boutigny/conda_envs/desc_2/lib/python3.8/site-packages/distributed/comm/core.py", line 323, in connect
    raise IOError(
OSError: Timed out during handshake while connecting to tcp://134.158.170.39:39583 after 10 s
distributed.worker - ERROR - failed during get data with tcp://134.158.168.221:45447 -> tcp://134.158.170.49:40071
Traceback (most recent call last):
  File "/sps/lsst/users/boutigny/conda_envs/desc_2/lib/python3.8/site-packages/tornado/iostream.py", line 867, in _read_to_buffer
    bytes_read = self.read_from_fd(buf)
  File "/sps/lsst/users/boutigny/conda_envs/desc_2/lib/python3.8/site-packages/tornado/iostream.py", line 1140, in read_from_fd
    return self.socket.recv_into(buf, len(buf))
ConnectionResetError: [Errno 104] Connection reset by peer

The above exception was the direct cause of the following exception:

Traceback (most recent call last):
  File "/sps/lsst/users/boutigny/conda_envs/desc_2/lib/python3.8/site-packages/distributed/worker.py", line 1366, in get_data
    response = await comm.read(deserializers=serializers)
  File "/sps/lsst/users/boutigny/conda_envs/desc_2/lib/python3.8/site-packages/distributed/comm/tcp.py", line 206, in read
    convert_stream_closed_error(self, e)
  File "/sps/lsst/users/boutigny/conda_envs/desc_2/lib/python3.8/site-packages/distributed/comm/tcp.py", line 124, in convert_stream_closed_error
    raise CommClosedError(
distributed.comm.core.CommClosedError: in <closed TCP>: ConnectionResetError: [Errno 104] Connection reset by peer
distributed.core - INFO - Lost connection to 'tcp://134.158.170.49:46302': in <closed TCP>: ConnectionResetError: [Errno 104] Connection reset by peer
